Workbook

Sheet Trường hợp kiểm thử
A1: ĐẠI HỌC DUY TÂN
A2: KHOA CÔNG NGHỆ THÔNG TIN
A3: NGÀNH: CÔNG NGHỆ PHẦN MỀM
C6: TEST CASE SYSTEM SPRINT 3
C8: Tên dự án | D8: XÂY DỰNG HỆ THỐNG DISHNET - NỀN TẢNG MẠNG XÃ HỘI KINH DOANH ẨM THỰC
C9: STT | D9: Chức năng | E9: Sheet Name | F9: Số Testcase
C10: 1 | D10: Tương tác người dùng | E10: =HYPERLINK("#'" & D10 & "'!A1", "Tương tác người dùng") -> Tương tác người dùng | F10: ='Tương tác người dùng'!F5 -> 34
C11: 2 | D11: Bảng xếp hạng | E11: =HYPERLINK("#'" & D11 & "'!A1", "Bảng xếp hạng") -> Bảng xếp hạng | F11: ='Bảng xếp hạng'!F6 -> 54
C12: 3 | D12: Trò chuyện | E12: =HYPERLINK("#'" & D12 & "'!A1", "Trò chuyện") -> Trò chuyện | F12: ='Trò chuyện'!F5 -> 39
C13: 4 | D13: Gửi yêu cầu hỗ trợ | E13: =HYPERLINK("#'" & D13 & "'!A1", "Gửi yêu cầu hỗ trợ") -> Gửi yêu cầu hỗ trợ | F13: ='Gửi yêu cầu hỗ trợ'!F5 -> 44
C14: 5 | D14: Kiếm tiền từ nội dung | E14: =HYPERLINK("#'" & D14 & "'!A1", "Kiếm tiền từ nội dung") -> Kiếm tiền từ nội dung | F14: ='Kiếm tiền từ nội dung'!F5 -> 41
C15: 6 | D15: Đăng ký mở cửa hàng | E15: =HYPERLINK("#'" & D15 & "'!A1", "Đăng ký mở cửa hàng") -> Đăng ký mở cửa hàng | F15: ='Đăng ký mở cửa hàng'!F5 -> 65
C16: 7 | D16: Giỏ hàng | E16: =HYPERLINK("#'" & D16 & "'!A1", "Giỏ hàng") -> Giỏ hàng | F16: ='Giỏ hàng'!F6 -> 59
C17: 8 | D17: Thanh toán | E17: =HYPERLINK("#'" & D17 & "'!A1", "Thanh toán") -> Thanh toán | F17: ='Thanh toán'!F6 -> 69
C18: 9 | D18: Đơn hàng của tôi | E18: =HYPERLINK("#'" & D18 & "'!A1", "Đơn hàng của tôi") -> Đơn hàng của tôi | F18: ='Đơn hàng của tôi'!F6 -> 55
C19: 10 | D19: Đánh giá đơn hàng | E19: =HYPERLINK("#'" & D19 & "'!A1", "Đánh giá đơn hàng") -> Đánh giá đơn hàng | F19: ='Đánh giá đơn hàng'!F6 -> 48
C20: Tổng số testcase của sprint 3 | F20: =SUM(F10:F19) -> 508

Sheet Tương tác người dùng
A1: Project Name | B1: XÂY DỰNG HỆ THỐNG DISHNET - NỀN TẢNG MẠNG XÃ HỘI KINH DOANH ẨM THỰC
A2: Module Code | B2: Tương tác người dùng
A3: Người kiểm tra | B3: Phạm Đình Vân Ly
B4: Hoàn thành | C4: Lỗi | D4: Chưa kiểm tra | E4: Bị chăn | F4: Tổng số trường hợp thử nghiệm
A5: Round 1 | B5: =COUNTIF(G22:G991,"passed") -> 32 | C5: =COUNTIF(G22:G991,"failed") -> 2 | D5: =COUNTIF(G22:G991,"untest") -> 0 | E5: =COUNTIF(G22:G991,"blocked") -> 0 | F5: =COUNTIF(A18:A987, "*TT*") -> 34
A6: Round 2 | B6: =COUNTIF(I22:I992,"passed") -> 2 | C6: =COUNTIF(I22:I991,"failed") -> 0 | D6: =COUNTIF(G22:G991,"untest") -> 0 | E6: =COUNTIF(G22:G991,"blocked") -> 0 | F6: =COUNTIF(A19:A988, "*TT*") -> 34
A18: Test Case ID | B18: Mô tả | C18: Hành động | D18: Điều kiện tiên quyết | E18: Kết quả mong đợi | F18: Kết quả thực tế | G18: Kết quả | I18: Kết quả | K18: Chú thích
G19: Vòng 1 | I19: Vòng 2
G20: Trạng thái | H20: Ngày kiểm tra | I20: Trạng thái | J20: Ngày kiểm tra
A21: GUI
A22: GUI_TT_01 | B22: Xác nhận hiển thị nút “Theo dõi” | C22: 1. Truy cập trang cá nhân user khác | D22: Chưa follow user | E22: Hiển thị nút “Theo dõi” rõ ràng, đúng vị trí | F22: Nút “Theo dõi” hiển thị đúng vị trí, rõ ràng khi truy cập trang cá nhân user khác | G22: passed | H22: 46143
A23: GUI_TT_02 | B23: Xác nhận hiển thị nút “Nhắn tin” | C23: 1. Truy cập trang cá nhân | D23: User tồn tại | E23: Hiển thị nút “Nhắn tin” đúng UI | F23: Nút “Nhắn tin” hiển thị đúng UI khi user tồn tại | G23: passed | H23: 46143
A24: GUI_TT_03 | B24: Xác nhận hiển thị menu “…” | C24: 1. Quan sát icon | D24: Trang load | E24: Hiển thị icon menu ba chấm | F24: Icon menu ba chấm hiển thị đúng sau khi trang load | G24: passed | H24: 46143
A25: GUI_TT_04 | B25: Xác nhận layout các nút tương tác | C25: 1. Quan sát toàn bộ khu vực | D25: Trang load | E25: Các nút hiển thị đúng vị trí, không lệch | F25: Các nút tương tác hiển thị đúng layout, không bị lệch | G25: passed | H25: 46143
A26: GUI_TT_05 | B26: Xác nhận responsive UI | C26: 1. Resize màn hình | D26: Trang đang mở | E26: Các nút không bị vỡ layout | F26: UI responsive tốt, không bị vỡ layout khi resize màn hình | G26: passed | H26: 46143
A27: FUNCTION
A28: TC_TT_06 | B28: Xác nhận người dùng có thể truy cập và hiển thị đầy đủ thông tin trang cá nhân của người dùng khác | C28: 1. Click vào avatar / username | D28: Tài khoản cần truy cập tồn tại | E28: Điều hướng đúng đến trang cá nhân của người dùng khác | F28: Click vào avatar/username điều hướng đúng đến trang cá nhân của user khác, hiển thị đầy đủ thông tin | G28: passed | H28: 46143
A29: TC_TT_07 | B29: Xác nhận hiển thị đúng username khi truy cập trang cá nhân | C29: 1. Truy cập trang cá nhân user | D29: User tồn tại trong hệ thống | E29: Hiển thị username đúng với dữ liệu DB | F29: Username hiển thị đúng và khớp với dữ liệu trong DB | G29: passed | H29: 46143
A30: TC_TT_08 | B30: Xác nhận hiển thị ID tài khoản dưới username | C30: 1. Truy cập trang cá nhân | D30: Có dữ liệu ID | E30: Hiển thị ID/handle đúng định dạng | F30: ID/handle hiển thị đúng định dạng dưới username | G30: passed | H30: 46143
A31: TC_TT_09 | B31: Xác nhận hiển thị đúng số bài viết trên trang cá nhân | C31: 1. Truy cập trang cá nhân | D31: User có bài viết | E31: Hiển thị đúng số lượng bài viết | F31: Số lượng bài viết hiển thị đúng theo dữ liệu hiện có | G31: passed | H31: 46143
A32: TC_TT_10 | B32: Xác nhận hiển thị đúng số người theo dõi trên trang cá nhân | C32: 1. Truy cập trang cá nhân | D32: Có dữ liệu followers | E32: Hiển thị đúng số lượng người theo dõi | F32: Số lượng followers hiển thị chính xác | G32: passed | H32: 46143
A33: TC_TT_11 | B33: Xác nhận hiển thị số người đang theo dõi | C33: 1. Truy cập trang cá nhân | D33: Có dữ liệu following | E33: Hiển thị đúng số lượng đang theo dõi | F33: Số lượng following hiển thị chính xác | G33: passed | H33: 46143
A34: TC_TT_12 | B34: Xác nhận format hiển thị số bài viết, người theo dõi, đang theo dõi lớn (k, M) | C34: 1. Truy cập user có nhiều followers | D34: Followers > 1000 | E34: Hiển thị dạng rút gọn (1.2k, 1M), không hiển thị số thô | F34: Số lượng followers >1000 không được format rút gọn (hiển thị dạng số đầy đủ thay vì 1.2k, 1M) | G34: failed | H34: 46143 | I34: passed | J34: 46147
A35: TC_TT_13 | B35: Xác nhận hiển thị đúng khi giá trị =0 | C35: 1. Truy cập user mới | D35: Không có dữ liệu | E35: Hiển thị “0 bài viết”, “0 người theo dõi”, “0 đang theo dõi” | F35: Với user không có dữ liệu, hiển thị “0 bài viết”, “0 người theo dõi”, “0 đang theo dõi” đúng | G35: passed | H35: 46143
A36: TC_TT_14 | B36: Xác nhận cập nhật dữ liệu khi có thay đổi | C36: 1. Theo dõi/ hủy theo dõi 2. Reload trang | D36: Có thay đổi dữ liệu | E36: Số followers/following được cập nhật đúng | F36: Sau khi follow/unfollow và reload trang, số followers/following được cập nhật đúng | G36: passed | H36: 46143
A37: TC_TT_15 | B37: Xác nhận điều hướng đúng khi người dùng chưa đăng nhập mà nhấn nút "Theo dõi" | C37: 1. Truy cập vào trang cá nhân của đối phương 2. Click "Đang theo dõi" | D37: Tài khoản chưa đăng nhập | E37: Điều hướng về trang đăng nhập khi người dùng nhấn "Theo dõi" mà chưa đăng nhập | F37: Khi chưa đăng nhập và nhấn “Theo dõi”, hệ thống điều hướng đến trang đăng nhập | G37: passed | H37: 46143
A38: TC_TT_16 | B38: Xác nhận hệ thống hiển thị trạng thái đã theo dõi sau khi nhấn nút Theo dõi thành công | C38: 1. Truy cập vào trang cá nhân của đối phương 2. Click nút "Theo dõi" | D38: Tài khoản đang ở trạng thái "Chưa theo dõi" | E38: Nút chuyển thành "Đang theo dõi", số theo dõi +1 | F38: Sau khi nhấn “Theo dõi”, nút chuyển thành “Đang theo dõi”, số followers tăng +1 | G38: passed | H38: 46143
A39: TC_TT_17 | B39: Xác nhận hệ thống cập nhật trạng thái hủy theo dõi sau khi nhấn nút Hủy theo dõi | C39: 1. Truy cập vào trang cá nhân của đối phương 2. Click "Đang theo dõi" 3. Nhấn "Hủy theo dõi" | D39: Tài khoản đang ở trạng thái "Đã theo dõi" | E39: Nút chuyển về "Theo dõi", số người theo dõi -1 | F39: Sau khi nhấn “Hủy theo dõi”, nút chuyển về “Theo dõi”, số followers giảm -1 | G39: passed | H39: 46143
A40: TC_TT_18 | B40: Xác nhận hệ thống xử lý phản hồi chính xác khi nhấn nút Theo dõi liên tục nhiều lần | C40: 1. Spam click "Theo dõi" | D40: User chưa follow | E40: Không gửi request trùng, trạng thái đúng | F40: Spam click “Theo dõi” không gửi request trùng, trạng thái hiển thị đúng | G40: passed | H40: 46143
A41: TC_TT_19 | B41: Xác nhận hệ thống tự động cập nhật trạng thái "Bạn bè" khi Follow lại | C41: 1. Truy cập vào trang cá nhân của đối phương 2. Nhấn nút "Follow lại" | D41: Tài khoản B đã theo dõi tài khoản A | E41: Sau khi người dùng thực hiện Follow lại, hệ thống tự động cập nhật trạng thái từ “Đã theo dõi” sang “Bạn bè" | F41: Sau khi follow lại, trạng thái chuyển từ “Đã theo dõi” sang “Bạn bè” | G41: passed | H41: 46143
A42: TC_TT_20 | B42: Xác nhận hệ thống mở màn hình chat khi nhấn vào Nhắn tin | C42: 1. Click "Nhắn tin" | D42: Tài khoản đã đăng nhập | E42: Điều hướng tới màn hình chat đúng user | F42: Nhấn “Nhắn tin” điều hướng đúng đến màn hình chat của user | G42: passed | H42: 46143
A43: TC_TT_21 | B43: Xác nhận hiển thị menu khi nhấn nút (...) | C43: 1. Nhấn vào nút "..." trên trang cá nhân | D43: Đang ở trang cá nhân người dùng khác | E43: Hiển thị dropdown menu gồm "Báo cáo tài khoản" và "Chặn tài khoản" | F43: Nhấn menu “...” hiển thị dropdown gồm “Báo cáo tài khoản” và “Chặn tài khoản” | G43: passed | H43: 46143
A44: TC_TT_22 | B44: Xác nhận hệ thống mở form báo cáo tài khoản khi chọn "Báo cáo" | C44: 1. Nhấn menu (...) 2. Chọn "Báo cáo" từ menu | D44: Menu "..." đang hiển thị | E44: Hiển thị form báo cáo gồm ô nhập lý do và nút "Gửi" | F44: Chọn “Báo cáo” hiển thị form báo cáo gồm ô nhập lý do và nút “Gửi” | G44: passed | H44: 46143
A45: TC_TT_23 | B45: Xác nhận hệ thống gửi báo cáo thành công khi người dùng đã chọn lý do | C45: 1. Nhấn menu (...) 2. Chọn "Báo cáo" từ menu" 3. Chọn lý do 4. Nhấn "Gửi" | D45: Form báo cáo đang mở | E45: Báo cáo được gửi thành công đến hệ thống | F45: Sau khi chọn lý do và nhấn “Gửi”, báo cáo được gửi thành công | G45: passed | H45: 46143
A46: TC_TT_24 | B46: Xác nhận hệ thống mở form chặn tài khoản khi chọn "Chặn" | C46: 1. Nhấn menu (...) 2. Chọn "Chặn" từ menu" | D46: Menu "..." đang hiển thị | E46: Hiển thị popup xác nhận gồm "Xác nhận" và "Hủy" | F46: Chọn “Chặn” hiển thị popup xác nhận gồm “Xác nhận” và “Hủy” | G46: passed | H46: 46143
... A53: TC_TT_31 | B53: Xác nhận hiển thị độ uy tín khi truy cập trang cá nhân của người dùng đã đăng ký chế độ kiếm tiền | C53: 1. Truy cập trang cá nhân | D53: User đã bật chế độ kiếm tiền | E53: Hiển thị “Độ uy tín” + điểm, hiển thị đúng vị trí UI | F53: Khi user bật kiếm tiền, hiển thị “Độ uy tín” + điểm đúng vị trí | G53: passed | H53: 46143
A54: TC_TT_32 | B54: Xác nhận không hiển thị độ uy tín khi truy cập trang cá nhân của người dùng chưa đăng ký kiếm tiền | C54: 1. Truy cập trang cá nhân | D54: User chưa bật kiếm tiền | E54: Không hiển thị phần “Độ uy tín” | F54: Vẫn hiển thị phần “Độ uy tín” dù user chưa bật kiếm tiền | G54: failed | H54: 46143 | I54: passed | J54: 46147
A55: TC_TT_33 | B55: Xác nhận hiển thị đúng độ uy tín | C55: 1. Truy cập trang cá nhân | D55: Có dữ liệu hợp lệ | E55: Giá trị hiển thị dạng số thập phân, không hiển thị quá nhiều số lẻ | F55: Giá trị độ uy tín hiển thị dạng số thập phân hợp lý, không quá nhiều số lẻ | G55: passed | H55: 46143
A56: TC_TT_34 | B56: Xác nhận cập nhật độ uy tín khi có thay đổi dữ liệu | C56: 1. Thay đổi rating backend 2. Reload trang | D56: API cập nhật thành công | E56: Giá trị độ uy tín được cập nhật đúng theo dữ liệu mới | F56: Sau khi thay đổi dữ liệu backend và reload, độ uy tín được cập nhật đúng | G56: passed | H56: 46143

Sheet Bảng xếp hạng
A1: Project Name | B1: XÂY DỰNG HỆ THỐNG DISHNET - NỀN TẢNG MẠNG XÃ HỘI KINH DOANH ẨM THỰC
A2: Module Code | B2: Bảng xếp hạng
A3: Người kiểm tra | B3: Phan Thị Lệ Thi
B4: Hoàn thành | C4: Lỗi | D4: Chưa kiểm tra | E4: Bị chăn | F4: Tổng số trường hợp thử nghiệm
A5: Round 1 | B5: =COUNTIF(G27:G973,"passed") -> 54 | C5: =COUNTIF(G27:G973,"failed") -> 0 | D5: =COUNTIF(G27:G973,"untest") -> 0 | E5: =COUNTIF(G27:G973,"blocked") -> 0 | F5: =COUNTIF(A23:A969, "*RANK*") -> 54
A6: Round 2 | B6: =COUNTIF(I27:I974,"passed") -> 0 | C6: =COUNTIF(I27:I973,"failed") -> 0 | D6: =COUNTIF(G27:G973,"untest") -> 0 | E6: =COUNTIF(G27:G973,"blocked") -> 0 | F6: =COUNTIF(A24:A970, "*RANK*") -> 54
A23: Test Case ID | B23: Mô tả | C23: Hành động | D23: Điều kiện tiên quyết | E23: Kết quả mong đợi | F23: Kết quả thực tế | G23: Kết quả | I23: Kết quả | K23: Chú thích
G24: Vòng 1 | I24: Vòng 2
G25: Trạng thái | H25: Ngày kiểm tra | I25: Trạng thái | J25: Ngày kiểm tra
A26: GUI
A27: GUI_RANK_01 | B27: Kiểm tra tiêu đề "BẢNG XẾP HẠNG" | C27: 1. Truy cập trang Bảng xếp hạng 2. Quan sát tiêu đề trang | D27: N/A | E27: Tiêu đề hiển thị đúng chữ in hoa, in đậm và căn lề trái như thiết kế. | F27: Hiển thị đúng tiêu đề. | G27: passed | H27: 46143
A28: GUI_RANK_02 | B28: Kiểm tra thanh Tab điều hướng (Cửa hàng, Reviewer, Món ăn) | C28: 1. Quan sát khu vực thanh tab 2. Kiểm tra màu sắc tab đang chọn | D28: N/A | E28: Hiển thị đủ 3 tab; tab "Cửa hàng" có màu nền xanh lá (Active) khác với các tab còn lại. | F28: Hiển thị đúng thanh tab. | G28: passed | H28: 46143
A29: GUI_RANK_03 | B29: Kiểm tra ô tìm kiếm trên bảng xếp hạng | C29: 1. Quan sát ô input bên phải 2. Kiểm tra placeholder | D29: N/A | E29: Ô tìm kiếm hiển thị placeholder: "Tìm kiếm trên bảng xếp hạng". | F29: Hiển thị đúng ô tìm kiếm. | G29: passed | H29: 46143
A30: GUI_RANK_04 | B30: Kiểm tra nhóm các bộ lọc (Khu vực, Số đơn hàng, Đánh giá,...) | C30: 1. Quan sát dòng "Lọc theo" 2. Kiểm tra các dropdown list | D30: N/A | E30: Hiển thị đầy đủ 5 bộ lọc: Khu vực, Số đơn hàng, Đánh giá, Trạng thái, Tỷ lệ hủy. | F30: Hiển thị đúng bộ lọc. | G30: passed | H30: 46143
A31: GUI_RANK_05 | B31: Kiểm tra Header của bảng danh sách | C31: 1. Quan sát hàng tiêu đề bảng 2. Kiểm tra các cột | D31: N/A | E31: Hiển thị đúng các cột: Cửa hàng, Đánh giá, Số đơn hàng, Tỷ lệ hủy. | F31: Hiển thị đúng header bảng. | G31: passed | H31: 46143
A32: GUI_RANK_06 | B32: Kiểm tra hiển thị icon thứ hạng (Top 1, 2, 3) | C32: 1. Quan sát cột số thứ tự 2. Kiểm tra màu sắc các vòng tròn | D32: N/A | E32: Các hạng 1, 2, 3 được highlight màu cam/vàng để nổi bật hơn các hạng sau. | F32: Hiển thị đúng icon thứ hạng. | G32: passed | H32: 46143
A33: GUI_RANK_07 | B33: Kiểm tra hiển thị thông tin Cửa hàng (Logo, Tên) | C33: 1. Quan sát cột Cửa hàng 2. Kiểm tra hình ảnh và chữ | D33: N/A | E33: Logo cửa hàng hiển thị trong khung bo góc, tên cửa hàng hiển thị ngay bên cạnh. | F33: Hiển thị đúng thông tin shop. | G33: passed | H33: 46143
A34: GUI_RANK_08 | B34: Kiểm tra hiển thị số sao và điểm đánh giá | C34: 1. Quan sát cột Đánh giá 2. Kiểm tra icon ngôi sao | D34: N/A | E34: Hiển thị số điểm (ví dụ 4.9) kèm theo các icon ngôi sao màu vàng. | F34: Hiển thị đúng đánh giá. | G34: passed | H34: 46143
A35: GUI_RANK_09 | B35: Kiểm tra hiển thị chỉ số Tỷ lệ hủy | C35: 1. Quan sát cột Tỷ lệ hủy 2. Kiểm tra màu sắc chữ | D35: N/A | E35: Tỷ lệ % hiển thị đúng định dạng (0.00%) và có màu đỏ để gây chú ý. | F35: Hiển thị đúng tỷ lệ hủy. | G35: passed | H35: 46143
A36: GUI_RANK_10 | B36: Kiểm tra hiển thị nút "Xem" | C36: 1. Quan sát cột cuối cùng của bảng 2. Kiểm tra hình dáng nút | D36: N/A | E36: Mỗi hàng có một nút "Xem" thiết kế dạng outline, bo góc mềm mại. | F36: Hiển thị đúng nút Xem. | G36: passed | H36: 46143
A37: GUI_RANK_11 | B37: Kiểm tra font chữ và màu sắc tổng thể giao diện | C37: 1. Quan sát toàn bộ trang 2. Đối chiếu với màu thương hiệu | D37: N/A | E37: Font chữ đồng nhất, dễ đọc; màu chủ đạo xanh lá và cam được sử dụng hợp lý. | F37: GUI đồng nhất. | G37: passed | H37: 46143
A38: GUI_RANK_12 | B38: Kiểm tra hiển thị thanh Header chung của DishNet | C38: 1. Quan sát phần đầu trang 2. Kiểm tra Logo và các menu | D38: N/A | E38: Logo DishNet, ô tìm kiếm chính, menu Bảng Tin, Khám Phá,... hiển thị đúng vị trí. | F38: Header hiển thị đúng. | G38: passed | H38: 46143
A39: GUI_RANK_13 | B39: Kiểm tra hiển thị thông tin User ở góc phải | C39: 1. Quan sát khu vực tài khoản 2. Kiểm tra tên và avatar | D39: Đã đăng nhập. | E39: Hiển thị đúng tên "Người Dùng Demo" và avatar thu nhỏ. | F39: Thông tin user đúng. | G39: passed | H39: 46143
A40: FUNCTION
A41: TC_RANK_14 | B41: Xác nhận chuyển trang thành công từ Bảng xếp hạng mini tại trang chủ | C41: 1. Truy cập Trang chủ 2. Nhấn nút "Xem thêm" tại Leaderboard mini | D41: N/A | E41: Hệ thống điều hướng người dùng đến trang Bảng xếp hạng chính thức. | F41: Người dùng được chuyển hướng chính xác đến trang Bảng xếp hạng tổng thể sau khi nhấn xem thêm. | G41: passed | H41: 46143
A42: TC_RANK_15 | B42: Xác nhận truy cập trang Bảng xếp hạng từ thanh Header | C42: 1. Nhấn vào mục "Bảng xếp hạng" trên thanh Header | D42: N/A | E42: Hệ thống chuyển hướng người dùng đến trang Bảng xếp hạng thành công. | F42: Chức năng điều hướng trên thanh Header hoạt động ổn định, dẫn người dùng đến đúng trang đích. | G42: passed | H42: 46143
A43: TC_RANK_16 | B43: Xác nhận tính chính xác của vị trí Top 1 Cửa hàng | C43: 1. Kiểm tra cửa hàng đứng đầu 2. Đối chiếu công thức tính điểm tích lũy | D43: Điểm = Số sao * Số lượng bán. | E43: Cửa hàng có tổng điểm tích lũy cao nhất hệ thống phải hiển thị ở vị trí số 1. | F43: Vị trí Top 1 phản ánh đúng dữ liệu thực tế dựa trên công thức tính điểm tích lũy của hệ thống. | G43: passed | H43: 46143
A44: TC_RANK_17 | B44: Xác nhận Reviewer có độ tin cậy cao nhất đứng vị trí số 1 | C44: 1. Chuyển sang tab Reviewer 2. Kiểm tra người đứng đầu | D44: N/A | E44: Reviewer có điểm tin cậy (Trust score) cao nhất phải đứng ở vị trí đầu bảng. | F44: Hệ thống phân loại và sắp xếp đúng thứ tự Reviewer dựa trên thang điểm tin cậy của cộng đồng. | G44: passed | H44: 46143
A45: TC_RANK_18 | B45: Xác nhận tổng lượt Thích/Xem của Reviewer là tổng từ tất cả bài Post | C45: 1. Kiểm tra chỉ số Thích/Xem trên Leaderboard 2. Cộng tổng các chỉ số từ tất cả bài đăng của Reviewer đó | D45: N/A | E45: Tổng lượt Thích/Xem trên bảng xếp hạng phải bằng tổng các chỉ số cộng dồn từ toàn bộ bài viết. | F45: Chỉ số tương tác tổng hợp của Reviewer được thống kê đầy đủ và chính xác từ mọi bài đăng. | G45: passed | H45: 46143
A46: TC_RANK_19 | B46: Xác nhận tổng lượt Bình luận của Reviewer khớp với dữ liệu thực tế | C46: 1. Kiểm tra cột Bình luận 2. Đối chiếu với tổng comment thực tế trên các bài review | D46: N/A | E46: Số lượng bình luận hiển thị phải khớp với tổng số comment hiện có trên các bài của Reviewer. | F46: Hệ thống truy xuất và hiển thị đúng số lượng phản hồi từ cộng đồng cho từng Reviewer. | G46: passed | H46: 46143
A47: TC_RANK_20 | B47: Xác nhận món ăn Top Trending đứng vị trí số 1 | C47: 1. Chuyển sang tab Món ăn 2. Kiểm tra vị trí đầu tiên | D47: Chu kỳ thiết lập (Tuần/Tháng). | E47: Món ăn có tổng lượng đơn đặt thành công cao nhất trong chu kỳ phải đứng vị trí số 1. | F47: Bảng xếp hạng xu hướng (Trending) cập nhật đúng món ăn có sức mua lớn nhất trong khoảng thời gian quy định. | G47: passed | H47: 46143
A48: TC_RANK_21 | B48: Xác nhận hiển thị đúng chủ sở hữu "Food Reviewer" cho món ăn tốt nhất | C48: 1. Kiểm tra cột chủ sở hữu món ăn 2. Đối chiếu với người review món đó tốt nhất | D48: N/A | E48: Hiển thị đúng thông tin định danh của người đã có bài review xuất sắc nhất cho món ăn đó. | F48: Hệ thống xác định và hiển thị chính xác gương mặt Reviewer tiêu biểu gắn liền với món ăn đạt giải. | G48: passed | H48: 46143
A49: TC_RANK_22 | B49: Xác nhận nút "Xem" chuyển hướng đúng đến chi tiết đối tượng | C49: 1. Click nút "Xem" tại Cửa hàng/Reviewer/Món ăn | D49: N/A | E49: Hệ thống điều hướng chính xác đến trang thông tin chi tiết của đối tượng tương ứng. | F49: Chức năng chuyển hướng hoạt động mượt mà, dẫn người dùng đến đúng trang đích để xem thêm chi tiết. | G49: passed | H49: 46143
A50: TC_RANK_23 | B50: Kiểm tra tính ổn định khi click liên tục để chuyển đổi Tab | C50: 1. Click chuột liên tục giữa các Tab "Reviewer" và "Món ăn" | D50: N/A | E50: Dữ liệu hiển thị đúng tab, không bị chồng chéo hoặc load sai Schema. | F50: Giao diện và dữ liệu được làm mới chính xác, không xảy ra hiện tượng xung đột dữ liệu khi thao tác nhanh. | G50: passed | H50: 46143
A51: TC_RANK_24 | B51: Kiểm tra hiển thị khi mất kết nối mạng trong quá trình chuyển Tab | C51: 1. Ngắt kết nối mạng khi đang chuyển Tab 2. Quan sát UI | D51: Đang thực hiện load dữ liệu. | E51: Hệ thống phải hiển thị icon Loading hoặc thông báo mất kết nối tới người dùng. | F51: Người dùng nhận được phản hồi rõ ràng về tình trạng mạng, tránh việc đứng màn hình không rõ nguyên nhân. | G51: passed | H51: 46143
A52: TC_RANK_25 | B52: Xác nhận kết quả tìm kiếm hiển thị đúng với từ khóa (Search Happy Case) | C52: 1. Nhập từ khóa hợp lệ vào ô Search 2. Nhấn tìm kiếm | D52: Có dữ liệu khớp từ khóa. | E52: Hiển thị danh sách các mục có thông tin khớp hoàn toàn với từ khóa đã nhập. | F52: Chức năng tìm kiếm hoạt động chính xác, trả về kết quả liên quan mật thiết đến yêu cầu của người dùng. | G52: passed | H52: 46143
... A81: TC_RANK_54 | B81: Xác nhận số lượng "Đã bán" món ăn không tăng khi phát hiện đơn hàng ảo (Spam) | C81: 1. Thực hiện các đơn hàng ảo cho 1 món ăn 2. Kiểm tra chỉ số bán trên BXH | D81: Hệ thống phát hiện đơn hàng spam cho món ăn này. | E81: Số lượng "Đã bán" trên BXH không được phép tăng. | F81: Thuật toán bảo vệ dữ liệu hoạt động chính xác, loại bỏ các giao dịch không hợp lệ khỏi thành tích tiêu thụ của món ăn. | G81: passed | H81: 46143

Sheet Trò chuyện
A1: Project Name | B1: XÂY DỰNG HỆ THỐNG DISHNET - NỀN TẢNG MẠNG XÃ HỘI KINH DOANH ẨM THỰC
A2: Module Code | B2: Trò chuyện
A3: Người kiểm tra | B3: Phan Thị Lệ Thi
B4: Hoàn thành | C4: Lỗi | D4: Chưa kiểm tra | E4: Bị chăn | F4: Tổng số trường hợp thử nghiệm
A5: Round 1 | B5: =COUNTIF(G27:G1013,"passed") -> 38 | C5: =COUNTIF(G27:G1013,"failed") -> 1 | D5: =COUNTIF(G27:G1013,"untest") -> 0 | E5: =COUNTIF(G27:G1013,"blocked") -> 0 | F5: =COUNTIF(A23:A971, "*MSG*") -> 39
A6: Round 2 | B6: =COUNTIF(I27:I1014,"passed") -> 1 | C6: =COUNTIF(I27:I1013,"failed") -> 0 | D6: =COUNTIF(G27:G1013,"untest") -> 0 | E6: =COUNTIF(G27:G1013,"blocked") -> 0 | F6: =COUNTIF(A24:A972, "*MSG*") -> 39
A23: Test Case ID | B23: Mô tả | C23: Hành động | D23: Điều kiện tiên quyết | E23: Kết quả mong đợi | F23: Kết quả thực tế | G23: Kết quả | I23: Kết quả | K23: Chú thích
G24: Vòng 1 | I24: Vòng 2
G25: Trạng thái | H25: Ngày kiểm tra | I25: Trạng thái | J25: Ngày kiểm tra
A26: GUI
A27: GUI_MSG_01 | B27: Xác nhận hiển thị tin nhắn bên gửi và bên nhận đúng vị trí | C27: 1. Quan sát đoạn chat | D27: Có dữ liệu tin nhắn | E27: Tin nhắn người gửi hiển thị bên phải (màu khác), người nhận bên trái | F27: Hiển thị tin nhắn đúng vị trí giữa người gửi và người nhận | G27: passed | H27: 46143
A28: GUI_MSG_02 | B28: Xác nhận hiển thị nội dung tin nhắn | C28: 1. Quan sát nội dung chat | D28: Có tin nhắn | E28: Nội dung hiển thị đầy đủ, không bị cắt | F28: Nội dung tin nhắn hiển thị đầy đủ, không bị cắt | G28: passed | H28: 46143
A29: GUI_MSG_03 | B29: Xác nhận hiển thị thời gian gửi tin nhắn | C29: 1. Quan sát timestamp | D29: Có tin nhắn | E29: Thời gian hiển thị đúng định dạng | F29: Thời gian hiển thị đúng định dạng | G29: passed | H29: 46143
A30: GUI_MSG_04 | B30: Xác nhận hiển thị avatar user trong chat | C30: 1. Quan sát UI | D30: Có dữ liệu user | E30: Avatar hiển thị đúng, không bị vỡ | F30: Avatar người dùng hiển thị đúng, không bị lỗi | G30: passed | H30: 46144
A31: GUI_MSG_05 | B31: Xác nhận hiển thị ô nhập tin nhắn | C31: 1. Quan sát thanh nhập dưới cùng | D31: Mở khung chat | E31: Hiển thị input với placeholder "Gửi tin nhắn..." | F31: Ô nhập tin nhắn hiển thị đúng placeholder | G31: passed | H31: 46143
A32: GUI_MSG_06 | B32: Xác nhận hiển thị nút gửi tin nhắn | C32: 1. Quan sát icon gửi | D32: Mở khung chat | E32: Hiển thị nút gửi (icon mũi tên) rõ ràng | F32: Nút gửi tin nhắn hiển thị rõ ràng, hoạt động bình thường | G32: passed | H32: 46143
A33: GUI_MSG_07 | B33: Xác nhận giao diện rỗng khi chưa có tin nhắn | C33: 1. Chọn user chưa có tin nhắn | D33: Có user chưa chat | E33: Hiển thị trạng thái "Chưa có tin nhắn" | F33: Hiển thị trạng thái "Chưa có tin nhắn" khi chưa có chat | G33: passed | H33: 46143
A34: GUI_MSG_08 | B34: Xác nhận hiển thị preview tin nhắn ở sidebar | C34: 1. Quan sát danh sách bên trái | D34: Có dữ liệu | E34: Hiển thị nội dung tin nhắn gần nhất dạng rút gọn | F34: Preview tin nhắn hiển thị đúng ở sidebar | G34: passed | H34: 46143
A35: GUI_MSG_09 | B35: Xác nhận layout tổng thể | C35: 1. Quan sát toàn trang | D35: Trang load thành công | E35: Giao diện chia 2 cột rõ ràng, không lệch | F35: Layout giao diện rõ ràng, không bị lệch | G35: passed | H35: 46143
A36: GUI_MSG_10 | B36: Xác nhận responsive | C36: 1. Resize trình duyệt | D36: Trang đang mở | E36: UI không vỡ layout, vẫn hiển thị đầy đủ | F36: Giao diện responsive tốt trên các kích thước màn hình | G36: passed | H36: 46143
A37: GUI_MSG_11 | B37: Xác nhận scroll trong khung chat | C37: 1. Scroll khung chat | D37: Có nhiều tin nhắn | E37: Có thanh scroll, cuộn mượt, không lỗi | F37: Scroll trong khung chat hoạt động mượt | G37: passed | H37: 46143
A38: GUI_MSG_12 | B38: Xác nhận hiển thị icon chức năng sidebar | C38: 1. Quan sát thanh icon trái | D38: Trang mở | E38: Hiển thị icon (home, chat, thông báo...) đúng vị trí | F38: Các icon chức năng hiển thị đúng vị trí | G38: passed | H38: 46143
A39: GUI_MSG_13 | B39: Xác nhận hiển thị thông tin người dùng góc phải | C39: 1. Quan sát góc phải | D39: Đã đăng nhập | E39: Hiển thị avatar + tên người dùng | F39: Thông tin người dùng (avatar + tên) hiển thị đúng | G39: passed | H39: 46143
A40: FUNCTION
A41: TC_MSG_14 | B41: Xác nhận hiển thị đúng danh sách cuộc trò chuyện khi truy cập trang tin nhắn | C41: 1. Đăng nhập hệ thống 2. Truy cập trang “Tin nhắn” | D41: User đã có danh sách chat | E41: Hiển thị danh sách chat bên trái gồm avatar, tên, tin nhắn gần nhất, thời gian | F41: Danh sách cuộc trò chuyện hiển thị đầy đủ avatar, tên, tin nhắn gần nhất, thời gian | G41: passed | H41: 46143
A42: TC_MSG_15 | B42: Xác nhận hiển thị đúng cuộc trò chuyện khi click vào 1 user | C42: 1. Click vào 1 cuộc trò chuyện | D42: Có dữ liệu chat | E42: Nội dung chat hiển thị bên phải đúng user được chọn | F42: Click vào cuộc trò chuyện hiển thị đúng nội dung | G42: passed | H42: 46143
A43: TC_MSG_16 | B43: Xác nhận highlight cuộc trò chuyện đang được chọn | C43: 1. Click vào 1 user bất kỳ | D43: Có danh sách chat | E43: Item được chọn có background khác biệt | F43: Cuộc trò chuyện được chọn có highlight rõ ràng | G43: passed | H43: 46143
A44: TC_MSG_17 | B44: Xác nhận hiển thị thời gian gửi tin nhắn | C44: 1. Quan sát tin nhắn | D44: Có tin nhắn | E44: Hiển thị timestamp đúng định dạng (hh:mm) | F44: Timestamp hiển thị đúng định dạng (hh:mm) | G44: passed | H44: 46143
A45: TC_MSG_18 | B45: Xác nhận hiển thị trạng thái “đang hoạt động” của user | C45: 1. Mở cuộc trò chuyện | D45: User đang online | E45: Hiển thị text “Đang hoạt động gần đây” | F45: Hiển thị trạng thái “Đang hoạt động gần đây” đúng | G45: passed | H45: 46143
A46: TC_MSG_19 | B46: Xác nhận hệ thống hiển thị đúng nội dung đã nhập nội dung vào ô chat | C46: 1. Click vào input 2. Nhập text | D46: Input active | E46: Nội dung hiển thị đúng trong ô nhập | F46: Nội dung tin nhắn hiển thị đúng trong ô input | G46: passed | H46: 46143
A47: TC_MSG_20 | B47: Xác nhận hệ thống gửi tin nhắn khi click icon gửi | C47: 1. Nhập nội dung 2. Click nút gửi | D47: Có nội dung | E47: Tin nhắn được gửi và hiển thị ngay | F47: Tin nhắn được gửi và hiển thị ngay sau khi click nút gửi | G47: passed | H47: 46143
A48: TC_MSG_21 | B48: Xác nhận hệ thống gửi tin nhắn khi nhấn Enter | C48: 1. Nhập nội dung 2. Nhấn Enter | D48: Có nội dung | E48: Tin nhắn được gửi và hiển thị ngay | F48: Nhấn Enter không gửi được tin nhắn, nút gửi bị ẩn sau khi Enter | G48: failed | H48: 46143 | I48: passed | J48: 46147
A49: TC_MSG_22 | B49: Xác nhận hệ thống không gửi tin nhắn khi ô input rỗng | C49: 1. Không nhập nội dung 2. Click gửi | D49: Input rỗng | E49: Không gửi tin nhắn, có thể disable button hoặc không phản hồi | F49: Không gửi tin nhắn khi input rỗng | G49: passed | H49: 46143
A50: TC_MSG_23 | B50: Xác nhận hiển thị lỗi khi gửi tin nhắn thất bại | C50: 1. Ngắt mạng 2. Gửi tin nhắn | D50: Mất kết nối | E50: Hiển thị thông báo lỗi, tin nhắn không được gửi | F50: Hiển thị thông báo lỗi khi gửi tin nhắn thất bại | G50: passed | H50: 46143
A51: TC_MSG_24 | B51: Xác nhận tự động cuộn xuống tin nhắn mới | C51: 1. Gửi/nhận tin nhắn mới | D51: Có tin nhắn mới | E51: Màn hình tự cuộn xuống cuối | F51: Màn hình tự động cuộn xuống khi có tin nhắn mới | G51: passed | H51: 46143
A52: TC_MSG_25 | B52: Xác nhận hiển thị danh sách chat khi không có tin nhắn | C52: 1. Truy cập user chưa có chat | D52: Không có dữ liệu | E52: Hiển thị “Chưa có tin nhắn” hoặc danh sách rỗng | F52: Khi không có dữ liệu danh sách rỗng | G52: passed | H52: 46143
A53: TC_MSG_26 | B53: Xác nhận hiển thị đúng tin nhắn trước trong danh sách | C53: 1. Quan sát sidebar | D53: Có tin nhắn | E53: Hiển thị nội dung rút gọn tin nhắn gần nhất | F53: Hiển thị đúng nội dung tin nhắn gần nhất trong danh sách | G53: passed | H53: 46143
A54: TC_MSG_27 | B54: Xác nhận hiển thị thời gian trong danh sách chat | C54: 1. Quan sát sidebar | D54: Có dữ liệu | E54: Hiển thị đúng thời gian tin nhắn cuối | F54: Hiển thị đúng thời gian tin nhắn trong danh sách chat | G54: passed | H54: 46143
A55: TC_MSG_28 | B55: Xác nhận nhận tin nhắn realtime từ user khác | C55: 1. User B gửi tin 2. User A đang mở chat | D55: Có kết nối socket | E55: Tin nhắn hiển thị ngay không cần reload | F55: Tin nhắn realtime hiển thị ngay không cần reload | G55: passed | H55: 46143
A56: TC_MSG_29 | B56: Xác nhận hệ thống lưu tin nhắn vào database | C56: 1. Gửi tin nhắn | D56: DB hoạt động | E56: Tin nhắn được lưu với đầy đủ: sender_id, receiver_id, content, timestamp | F56: Tin nhắn được lưu đầy đủ vào database | G56: passed | H56: 46143
...

Sheet Gửi yêu cầu hỗ trợ
A1: Project Name | B1: XÂY DỰNG HỆ THỐNG DISHNET - NỀN TẢNG MẠNG XÃ HỘI KINH DOANH ẨM THỰC
A2: Module Code | B2: Gửi yêu cầu hỗ trợ
A3: Người kiểm tra | B3: Huỳnh Thị Vy
B4: Hoàn thành | C4: Lỗi | D4: Chưa kiểm tra | E4: Bị chăn | F4: Tổng số trường hợp thử nghiệm
A5: Round 1 | B5: =COUNTIF(G26:G1027,"passed") -> 42 | C5: =COUNTIF(G26:G1027,"failed") -> 2 | D5: =COUNTIF(G26:G1027,"untest") -> 0 | E5: =COUNTIF(G26:G1027,"blocked") -> 0 | F5: =COUNTIF(A22:A1023, "*SP*") -> 44
A6: Round 2 | B6: =COUNTIF(I26:I1028,"passed") -> 2 | C6: =COUNTIF(I26:I1027,"failed") -> 0 | D6: =COUNTIF(G26:G1027,"untest") -> 0 | E6: =COUNTIF(G26:G1027,"blocked") -> 0 | F6: =COUNTIF(A23:A1024, "*SP*") -> 44
A22: Test Case ID | B22: Mô tả | C22: Hành động | D22: Điều kiện tiên quyết | E22: Kết quả mong đợi | F22: Kết quả thực tế | G22: Kết quả | I22: Kết quả | K22: Chú thích
G23: Vòng 1 | I23: Vòng 2
G24: Trạng thái | H24: Ngày kiểm tra | I24: Trạng thái | J24: Ngày kiểm tra
A25: GUI
A26: GUI_SP_01 | B26: Kiểm tra hiển thị tổng thể trang Trợ giúp | C26: 1. Người dùng đã đăng nhập 2. Truy cập trang gửi yêu cầu hỗ trợ | D26: Đã đăng nhập | E26: Hiển thị trang trợ giúp và hỗ trợ, khung "Liên hệ hỗ trợ". | F26: Hiển thị đúng trang “Trợ giúp & hỗ trợ”, có đầy đủ khung “Liên hệ hỗ trợ” như thiết kế | G26: passed | H26: 46143
A27: GUI_SP_02 | B27: Kiểm tra khung Liên hệ hỗ trợ bên phải | C27: Màn hình hiển thị đầy đủ các thành phần bên phải. | D27: Truy cập trang gửi yêu cầu hỗ trợ | E27: Hiển thị nút "Gửi yêu cầu" màu xanh dương có mũi tên trắng và số hotline "0123 456 789" kèm icon điện thoại phía dưới | F27: Khung “Liên hệ hỗ trợ” hiển thị đúng, bao gồm nút gửi yêu cầu và số hotline | G27: passed | H27: 46143
A28: GUI_SP_03 | B28: Kiểm tra nút "Gửi yêu cầu" | C28: 1. Người dùng đã đăng nhập 2. Truy cập trang gửi yêu cầu hỗ trợ 3. Click "Gửi yêu cầu" | D28: Truy cập trang gửi yêu cầu hỗ trợ | E28: Mở form gửi yêu cầu hỗ trợ | F28: Khi click “Gửi yêu cầu”, hệ thống mở form gửi yêu cầu hỗ trợ đúng | G28: passed | H28: 46143
A29: GUI_SP_04 | B29: Kiểm tra số điện thoại liên hệ | C29: 1. Người dùng đã đăng nhập 2. Truy cập trang gửi yêu cầu hỗ trợ 3. Click "Số điện thoại" | D29: Truy cập trang gửi yêu cầu hỗ trợ | E29: Hiển thị số hotline của hệ thống | F29: Hiển thị đúng số hotline của hệ thống, click vào có phản hồi | G29: passed | H29: 46143
A30: GUI_SP_05 | B30: Kiểm tra nút Danh sách yêu cầu đã gửi | C30: 1. Người dùng đã đăng nhập 2. Truy cập trang gửi yêu cầu hỗ trợ 3. Quan sát danh sách | D30: Quan sát thanh ngang phía dưới các thẻ danh mục. | E30: Hiển thị danh sách yêu cầu | F30: Danh sách yêu cầu đã gửi hiển thị đầy đủ và đúng dữ liệu. | G30: passed | H30: 46143
A31: GUI_SP_06 | B31: Xác nhận responsive UI | C31: 1. Resize màn hình | D31: Trang đang mở | E31: Các nút không bị vỡ layout | F31: UI responsive tốt, không bị vỡ layout khi resize màn hình | G31: passed | H31: 46143
A32: GUI_SP_07 | B32: Xác nhận layout tổng thể | C32: 1. Quan sát toàn trang | D32: Trang load thành công | E32: Giao diện chia 2 cột rõ ràng, không lệch | F32: Layout giao diện rõ ràng, không bị lệch | G32: passed | H32: 46143
A33: FUNCTION
A34: TC_SP_08 | B34: Xác nhận hiển thị đúng trang hỗ trợ khi thành viên truy cập | C34: 1. Truy cập mục “Trợ giúp & hỗ trợ” | D34: Người dùng đã đăng nhập | E34: Hiển thị đầy đủ, có nút “Gửi yêu cầu hỗ trợ”, "số điện thoại hỗ trợ" | F34: Trang hiển thị đầy đủ nội dung: nút gửi yêu cầu và thông tin liên hệ | G34: passed | H34: 46143
A35: TC_SP_09 | B35: Xác nhận hiển thị form khi nhấn “Gửi yêu cầu hỗ trợ” | C35: 1. Click “Gửi yêu cầu hỗ trợ” | D35: Trang hỗ trợ hiển thị | E35: Hiển thị form gồm: Chủ đề, Nội dung, Tệp đính kèm, Thông tin liên hệ | F35: Khi click “Gửi yêu cầu hỗ trợ”, form hiển thị đầy đủ các trường | G35: passed | H35: 46143
A36: TC_SP_10 | B36: Xác nhận gửi yêu cầu thành công khi nhập đầy đủ thông tin hợp lệ | C36: 1. Mở form 2. Nhập đầy đủ thông tin hợp lệ 3. Click “Gửi yêu cầu” | D36: Form hợp lệ | E36: Hiển thị thông báo “Gửi yêu cầu thành công”, yêu cầu xuất hiện trong danh sách | F36: Khi nhập đúng dữ liệu và submit, hệ thống hiển thị thông báo “Gửi yêu cầu thành công” và thêm vào danh sách | G36: passed | H36: 46143
A37: TC_SP_11 | B37: Xác nhận nút “Gửi yêu cầu” bị vô hiệu hóa khi bỏ trống tất cả trường | C37: 1. Mở form 2. Không nhập dữ liệu | D37: Form mở | E37: Nút “Gửi yêu cầu” bị disable, không thể click | F37: Khi chưa nhập dữ liệu, nút “Gửi yêu cầu” bị disable, không thể click | G37: passed | H37: 46143
A38: TC_SP_12 | B38: Xác nhận hiển thị danh sách chủ đề trong dropdown | C38: 1. Click dropdown Chủ đề | D38: Form mở | E38: Hiển thị danh sách chủ đề đầy đủ | F38: Dropdown “Chủ đề” hiển thị đầy đủ các lựa chọn | G38: passed | H38: 46143
A39: TC_SP_13 | B39: Xác nhận hiển thị lỗi khi nội dung >1000 ký tự | C39: 1. Nhập nội dung >1000 ký tự 2. Submit | D39: Form mở | E39: Hiển thị lỗi hoặc chặn nhập thêm | F39: Khi nhập >1000 ký tự, hệ thống hiển thị lỗi và không cho nhập thêm | G39: passed | H39: 46143
A40: TC_SP_14 | B40: Xác nhận chấp nhận nội dung từ 1–1000 ký tự | C40: 1. Nhập nội dung hợp lệ 2. Submit | D40: Form mở | E40: Hệ thống chấp nhận và cho phép gửi | F40: Khi nhập nội dung hợp lệ, hệ thống chấp nhận và cho phép gửi | G40: passed | H40: 46143
A41: TC_SP_15 | B41: Xác nhận hệ thống gửi yêu cầu khi không có tệp đính kèm | C41: 1. Nhập thông tin hợp lệ 2. Không upload file 3. Submit | D41: Form mở | E41: Gửi thành công | F41: Khi không đính kèm file, hệ thống vẫn gửi yêu cầu thành công | G41: passed | H41: 46143
A42: TC_SP_16 | B42: Xác nhận hiển thị lỗi khi file >4MB | C42: 1. Upload file >4MB | D42: Form mở | E42: Hiển thị lỗi “Vượt quá dung lượng cho phép” | F42: Hệ thống thông báo "Vượt quá dung lượng cho phép nhưng ảnh vẫn được upload lên | G42: failed | H42: 46143 | I42: passed | J42: 46147
A43: TC_SP_17 | B43: Xác nhận hiển thị lỗi khi file sai định dạng | C43: 1. Upload file không hợp lệ | D43: Form mở | E43: Hiển thị lỗi “Tệp không nằm trong danh sách cho phép” | F43: Khi upload file sai định dạng, hệ thống hiển thị lỗi đúng | G43: passed | H43: 46143
A44: TC_SP_18 | B44: Xác nhận hiển thị lỗi khi số điện thoại <10 số | C44: 1. Nhập số <10 số | D44: Form mở | E44: Hiển thị lỗi "Số điện thoại không hợp lệ" | F44: Khi nhập số điện thoại <10 số, hệ thống hiển thị lỗi “Số điện thoại không hợp lệ” | G44: passed | H44: 46143
A45: TC_SP_19 | B45: Xác nhận hiển thị lỗi khi số điện thoại >10 số | C45: 1. Nhập số >10 số | D45: Form mở | E45: Hiển thị lỗi "Số điện thoại không hợp lệ" | F45: Khi nhập số điện thoại >10 số, hệ thống hiển thị lỗi “Số điện thoại không hợp lệ” | G45: passed | H45: 46143
A46: TC_SP_20 | B46: Xác nhận chấp nhận số điện thoại =10 số | C46: 1. Nhập đúng 10 số | D46: Form mở | E46: Hệ thống chấp nhận | F46: Khi nhập đúng 10 số, hệ thống chấp nhận số điện thoại. | G46: passed | H46: 46143
A47: TC_SP_21 | B47: Xác nhận hiển thị lỗi khi số điện thoại không bắt đầu bằng 0 | C47: 1. Nhập số bắt đầu ≠0 | D47: Form mở | E47: Hiển thị lỗi "Số điện thoại không hợp lệ" | F47: Khi số điện thoại bắt đầu ≠ 0, hệ thống hiển thị lỗi. | G47: passed | H47: 46143
A48: TC_SP_22 | B48: Xác nhận hiển thị lỗi khi nhập ký tự chữ/ký tự đặc biệt | C48: 1. Nhập chữ/ký tự đặc biệt | D48: Form mở | E48: Hiển thị lỗi "Số điện thoại không hợp lệ" | F48: Khi nhập ký tự đặc biệt vào số điện thoại, hệ thống hiển thị lỗi | G48: passed | H48: 46143
A49: TC_SP_23 | B49: Xác nhận hệ thống không tạo duplicate khi click submit liên tục | C49: 1. Click “Gửi yêu cầu” nhiều lần | D49: Form hợp lệ | E49: Hệ thông không crash, chỉ xử lý 1 yêu cầu đầu tiên | F49: Khi click submit nhiều lần liên tiếp, hệ thống chỉ xử lý 1 request đầu tiên | G49: passed | H49: 46143
A50: TC_SP_24 | B50: Xác nhận hiển thị thông báo sau khi gửi thành công | C50: 1. Gửi thành công | D50: Form hợp lệ | E50: Hiển thị toast/message thành công | F50: Sau khi gửi thành công, hệ thống hiển thị toast message “Gửi yêu cầu thành công” | G50: passed | H50: 46143
A51: TC_SP_25 | B51: Xác nhận hiển thị yêu cầu trong danh sách sau khi gửi | C51: 1. Gửi yêu cầu 2. Xem danh sách | D51: Có dữ liệu | E51: Yêu cầu hiển thị trong “Danh sách các yêu cầu đã gửi” | F51: Yêu cầu sau khi gửi xuất hiện trong danh sách “Danh sách các yêu cầu đã gửi” | G51: passed | H51: 46143
A52: TC_SP_26 | B52: Xác nhận trạng thái mặc định của yêu cầu mới | C52: 1. Gửi yêu cầu | D52: Có dữ liệu | E52: Trạng thái = “Chưa phản hồi” | F52: Trạng thái mặc định của yêu cầu mới là “Chưa phản hồi" | G52: passed | H52: 46143
A53: TC_SP_27 | B53: Xác nhận lưu đúng thời gian gửi yêu cầu | C53: 1. Gửi yêu cầu | D53: Hệ thống hoạt động | E53: Lưu đúng timestamp theo thời gian thực | F53: Thời gian gửi yêu cầu được lưu đúng theo timestamp thực tế. | G53: passed | H53: 46143
A54: TC_SP_28 | B54: Xác nhận hiển thị yêu cầu sau khi refresh trang | C54: 1. Gửi yêu cầu 2. Refresh | D54: Có dữ liệu | E54: Yêu cầu vẫn hiển thị | F54: Sau khi refresh trang, yêu cầu vẫn hiển thị đúng | G54: passed | H54: 46143
A55: TC_SP_29 | B55: Xác nhận hiển thị lỗi khi vượt quá số lượng yêu cầu tối đa | C55: 1. Gửi >50 yêu cầu | D55: Đã đạt limit | E55: Hiển thị “Số lượng yêu cầu không được vượt quá 50” | F55: Khi vượt quá 50 yêu cầu, hệ thống hiển thị thông báo lỗi đúng | G55: passed | H55: 46143
...

Sheet Kiếm tiền từ nội dung
A1: Project Name | B1: XÂY DỰNG HỆ THỐNG DISHNET - NỀN TẢNG MẠNG XÃ HỘI KINH DOANH ẨM THỰC
A2: Module Code | B2: Kiếm tiền từ nội dung
A3: Người kiểm tra | B3: Trần Thị Mai Yên
B4: Hoàn thành | C4: Lỗi | D4: Chưa kiểm tra | E4: Bị chăn | F4: Tổng số trường hợp thử nghiệm
A5: Round 1 | B5: =COUNTIF(G26:G1023,"passed") -> 39 | C5: =COUNTIF(G26:G1023,"failed") -> 2 | D5: =COUNTIF(G26:G1023,"untest") -> 0 | E5: =COUNTIF(G26:G1023,"blocked") -> 0 | F5: =COUNTIF(A22:A1019, "*MN*") -> 41
A6: Round 2 | B6: =COUNTIF(I26:I1024,"passed") -> 2 | C6: =COUNTIF(I26:I1023,"failed") -> 0 | D6: =COUNTIF(G26:G1023,"untest") -> 0 | E6: =COUNTIF(G26:G1023,"blocked") -> 0 | F6: =COUNTIF(A23:A1020, "*MN*") -> 41
A22: Test Case ID | B22: Mô tả | C22: Hành động | D22: Điều kiện tiên quyết | E22: Kết quả mong đợi | F22: Kết quả thực tế | G22: Kết quả | I22: Kết quả | K22: Chú thích
G23: Vòng 1 | I23: Vòng 2
G24: Trạng thái | H24: Ngày kiểm tra | I24: Trạng thái | J24: Ngày kiểm tra
A25: GUI
A26: GUI_MN_01 | B26: Kiểm tra hiển thị mặc định của menu trái | C26: 1, Quan sát danh sách menu bên trái tại trang cài đặt | D26: Người dùng đã đăng nhập | E26: Hiển thị đủ 4 mục: Thông tin cá nhân, Mật khẩu và bảo mật, Chế độ chuyên nghiệp, Quản lý chặn | F26: Hệ thống hiển thị đúng menu sidebar | G26: passed | H26: 46143
A27: GUI_MN_02 | B27: Kiểm tra hiển thị trang chế độ chuyên nghiệp | C27: 1. Quan sát nội dung chính khi ở tab Chế độ chuyên nghiệp | D27: Tài khoản đang trong trạng thái gửi yêu cầu xét duyệt | E27: Hiển thị 2 dòng: "Kiếm tiền từ nội dung" và "Mở cửa hàng" | F27: Trang chế độ chuyên nghiệp hiển thị đúng "Kiếm tiền từ nội dung" và "Mở cửa hàng" | G27: passed | H27: 46143
A28: GUI_MN_03 | B28: Kiểm tra giao diện form "Thông tin cơ bản" | C28: 1. Chọn cài đặt 2. Chọn chế độ chuyên nghiệp 3. Chọn kiếm tiền từ nội dung | D28: Đang ở tab Chế độ chuyên nghiệp | E28: Hiển thị đầy đủ các trường thông tin có trong trang đăng ký | F28: Hiển thị đúng và đầy đủ các trường thông tin có trong trang đăng ký | G28: passed | H28: 46143
A29: GUI_MN_04 | B29: Kiểm tra placeholder và icon trong các input | C29: 1. Chọn cài đặt 2. Chọn chế độ chuyên nghiệp 3. Chọn kiếm tiền từ nội dung 4. Quan sát UI | D29: Form đăng ký đang hiển thị | E29: Placeholder hiển thị đúng | F29: Các dòng chữ mờ hướng dẫn trong ô nhập liệu hiển thị đúng nội dung quy định | G29: passed | H29: 46143
A30: GUI_MN_05 | B30: Kiểm tra hiển thị vùng nhập "Mô tả" | C30: 1. Chọn cài đặt 2. Chọn chế độ chuyên nghiệp 3. Chọn kiếm tiền từ nội dung 4. Quan sát UI | D30: Form đăng ký đang hiển thị | E30: Hiển thị Textarea, cho phép nhập thông tin | F30: Khi nhập các ký tự hiển thị đúng trong ô textarea | G30: passed | H30: 46143
A31: GUI_MN_06 | B31: Kiểm tra hiển thị nút "Gửi" | C31: 1. Chọn cài đặt 2. Chọn chế độ chuyên nghiệp 3. Chọn kiếm tiền từ nội dung 4. Quan sát UI | D31: Form đăng ký đang hiển thị | E31: Hiển thị nút "Gửi" màu xanh lá cây, đúng vị trí, enable | F31: Button hiển thị đúng vị trí, có thể click | G31: passed | H31: 46143
A32: GUI_MN_07 | B32: Xác nhận responsive UI | C32: 1. Resize màn hình | D32: Trang đang mở | E32: Các nút không bị vỡ layout | F32: UI responsive tốt, không bị vỡ layout khi resize màn hình | G32: passed | H32: 46143
A33: GUI_MN_08 | B33: Xác nhận layout tổng thể | C33: 1. Quan sát toàn trang | D33: Trang load thành công | E33: Giao diện chia 2 cột rõ ràng, không lệch | F33: Layout giao diện rõ ràng, không bị lệch | G33: passed | H33: 46143
A34: FUNCTION
A35: TC_MN_09 | B35: Xác nhận hiển thị đúng chức năng khi truy cập chế độ chuyên nghiệp | C35: 1. Đăng nhập hệ thống 2. Truy cập chế độ chuyên nghiệp | D35: Người dùng đã đăng nhập hợp lệ | E35: Hiển thị "kiếm tiền từ nội dung" và "mở cửa hàng" | F35: Chế độ chuyên nghiệp đã liệt kê đúng hai tùy chọn về "kiếm tiền từ nội dung" và "mở cửa hàng" | G35: passed | H35: 46143
A36: TC_MN_10 | B36: Xác nhận điều hướng thành công khi click vào chức năng "Kiếm tiền từ nội dung" | C36: 1. Truy cập chế độ chuyên nghiệp 2. Click "Kiếm tiền từ nội dung" | D36: Người dùng đã đăng nhập | E36: Điều hướng tới màn hình form đăng ký hoặc màn hình trạng thái | F36: Hệ thống điều hướng đến đúng trang đăng ký hoặc màn hình trạng thái tương ứng | G36: passed | H36: 46143
A37: TC_MN_11 | B37: Xác nhận hiển thị thông báo lỗi khi thành viên chưa đăng nhập đăng ký kiếm tiền | C37: 1. Truy cập trực tiếp chức năng 2. Quan sát kết quả | D37: Người dùng chưa đăng nhập | E37: Hệ thống điều hướng về trang login hoặc hiển thị lỗi "Unauthorized" | F37: Truy cập trái phép bị chặn và hệ thống tự động đẩy về trang đăng nhập | G37: passed | H37: 46143
A38: TC_MN_12 | B38: Xác nhận hiển thị form đăng ký kiếm tiền khi thành viên truy cập | C38: 1. Truy cập chức năng đăng ký kiếm tiền | D38: Người dùng đã đăng nhập | E38: Hiển thị form đầy đủ: Tên tài khoản, Giới tính, Ngày sinh, Ngân hàng, STK, Email, SĐT, Địa chỉ, Mô tả | F38: Form đăng ký bao gồm 4 phần (Thông tin cơ bản, Cửa hàng, Điều khoản, Đính kèm) hiển thị rõ ràng | G38: passed | H38: 46143
A39: TC_MN_13 | B39: Xác nhận đăng ký thành công khi nhập đầy đủ thông tin hợp lệ | C39: 1. Nhập đầy đủ thông tin hợp lệ 2. Click “Gửi” | D39: Form hợp lệ | E39: Hiển thị trạng thái “Đang chờ duyệt”, disable nút submit | F39: Hệ thống đã chuyển sang trạng thái "Đang chờ duyệt" và nút submit không còn cho phép thao tác | G39: passed | H39: 46143
A40: TC_MN_14 | B40: Xác nhận hệ thống không cho sửa tên tài khoản khi hiển thị form | C40: 1. Quan sát field “Tên tài khoản” | D40: Form mở | E40: Field hiển thị mặc định, không cho chỉnh sửa | F40: Tên tài khoản được hiển thị cố định trong field, người dùng không thể đặt con trỏ chuột để xóa hoặc sửa | G40: passed | H40: 46143
A41: TC_MN_15 | B41: Xác nhận hiển thị lỗi khi bỏ trống giới tính | C41: 1. Không chọn giới tính 2. Click "Gửi" | D41: Form mở | E41: Hiển thị lỗi “Giới tính là bắt buộc” | F41: Thông báo nhắc nhở "Giới tính là bắt buộc" xuất hiện ngay phía dưới field khi để trống | G41: passed | H41: 46143
A42: TC_MN_16 | B42: Xác nhận hiển thị đúng dropdown giới tính | C42: 1. Click dropdown giới tính | D42: Form mở | E42: Hiển thị 2 option: Nam/Nữ/Khác | F42: Danh sách dropdown hiển thị chính xác lựa chọn là Nam và Nữ hoặc Khác | G42: passed | H42: 46143
A43: TC_MN_17 | B43: Xác nhận hiển thị lỗi khi bỏ trống ngày sinh | C43: 1. Không nhập ngày sinh 2. Click "Gửi" | D43: Form mở | E43: Hiển thị lỗi “Ngày sinh là bắt buộc” | F43: Cảnh báo “Ngày sinh là bắt buộc” khi người dùng bỏ qua trường này | G43: passed | H43: 46143
A44: TC_MN_18 | B44: Xác nhận không cho chọn ngày sinh trong tương lai | C44: 1. Chọn ngày > ngày hiện tại | D44: Form mở | E44: Hệ thống chặn không cho chọn | F44: Các ngày trong tương lai trên lịch bị làm mờ, không thể click chọn được | G44: passed | H44: 46143
A45: TC_MN_19 | B45: Xác nhận hiển thị lỗi khi người dùng <16 tuổi | C45: 1. Chọn ngày sinh <16 tuổi 2. Click "Gửi" | D45: Form mở | E45: Hiển thị lỗi “Ngày sinh không hợp lệ” | F45: Hệ thống không hiển thị lỗi "Ngày sinh không hợp lệ" mà vẫn cho phép gửi form dù người dùng <16 tuổi | G45: failed | H45: 46143 | I45: passed | J45: 46147
A46: TC_MN_20 | B46: Xác nhận hiển thị lỗi khi nhập ngày sinh bằng ký tự chữ/ đặc biệt | C46: 1. Nhập ký tự chữ/đặc biệt | D46: Form mở | E46: Hiển thị lỗi “Ngày sinh không hợp lệ” | F46: Khi nhập ký tự không phải số vào ngày sinh, hệ thống trả về lỗi báo ngày sinh không hợp lệ | G46: passed | H46: 46143
A47: TC_MN_21 | B47: Xác nhận hiển thị lỗi khi bỏ trống ngân hàng | C47: 1. Không chọn ngân hàng 2. Submit | D47: Form mở | E47: Hiển thị lỗi “Ngân hàng là bắt buộc” | F47: Giao diện xuất hiện dòng thông báo "Ngân hàng là bắt buộc" khi chưa chọn ngân hàng | G47: passed | H47: 46143
A48: TC_MN_22 | B48: Xác nhận hiển thị lỗi khi nhập ngân hàng không hợp lệ | C48: 1. Nhập tên ngân hàng không tồn tại | D48: Form mở | E48: Hiển thị lỗi “Ngân hàng không hợp lệ” | F48: Hệ thống ghi nhận tên ngân hàng không tồn tại và thông báo lỗi không hợp lệ cho người dùng | G48: passed | H48: 46143
A49: TC_MN_23 | B49: Xác nhận hiển thị lỗi khi bỏ trống số tài khoản | C49: 1. Không nhập STK 2. Click "Gửi" | D49: Form mở | E49: Hiển thị lỗi “Số tài khoản ngân hàng là bắt buộc” | F49: Lỗi bỏ trống số tài khoản ngân hàng hiển thị ngay sau khi bấm nút "Gửi" | G49: passed | H49: 46143
A50: TC_MN_24 | B50: Xác nhận hiển thị lỗi khi nhập STK chứa ký tự chữ | C50: 1. Nhập STK có chữ/ký tự đặc biệt | D50: Form mở | E50: Hiển thị lỗi “Số tài khoản không hợp lệ” | F50: Trường số tài khoản báo lỗi không hợp lệ khi phát hiện có chứa ký tự chữ hoặc ký hiệu đặc biệt | G50: passed | H50: 46143
A51: TC_MN_25 | B51: Xác nhận hệ thống tự động trim khoảng trắng khi nhập có chưa khoảng trắng đầu/cuối | C51: 1. Nhập dữ liệu có khoảng trắng đầu/cuối 2. Click "Gửi" | D51: Form hợp lệ | E51: Hệ thống tự động loại bỏ khoảng trắng | F51: Dữ liệu sau khi gửi đã được hệ thống tự động xóa các khoảng trắng dư thừa ở hai đầu | G51: passed | H51: 46143
A52: TC_MN_26 | B52: Xác nhận hệ thông hiển thị email mặc định của tài khoản đăng ký và không cho sửa | C52: 1. Quan sát field Email | D52: Form mở | E52: Email hiển thị sẵn, không chỉnh sửa | F52: Email đăng ký được điền sẵn vào ô và thuộc tính readonly được kích hoạt | G52: passed | H52: 46143
A53: TC_MN_27 | B53: Xác nhận hệ thông hiển thị số điện thoại mặc định của tài khoản đăng ký và không cho sửa | C53: 1. Quan sát field SĐT | D53: Form mở | E53: SĐT hiển thị sẵn, không chỉnh sửa | F53: Số điện thoại hiển thị đúng thông tin đã đăng ký và bị khóa chức năng chỉnh sửa | G53: passed | H53: 46143
A54: TC_MN_28 | B54: Xác nhận hiển thị lỗi khi bỏ trống địa chỉ | C54: 1. Không nhập địa chỉ 2. Click "Gửi" | D54: Form mở | E54: Hiển thị lỗi “Địa chỉ là bắt buộc" | F54: Thông báo nhắc nhở "Địa chỉ là bắt buộc" hiển thị ngay khi người dùng để trống trường địa chỉ và nhấn gửi | G54: passed | H54: 46143
A55: TC_MN_29 | B55: Xác nhận hệ thống chấp nhận khi bỏ trống trường mô tả | C55: 1. Không nhập mô tả 2. Click "Gửi" | D55: Form hợp lệ | E55: Hệ thống chấp nhận và gửi đăng ký | F55: Hệ thống ghi nhận biểu mẫu thành công và chuyển sang bước tiếp theo dù không có dữ liệu trong ô mô tả | G55: passed | H55: 46143
...

Sheet Đăng ký mở cửa hàng
A1: Project Name | B1: XÂY DỰNG HỆ THỐNG DISHNET - NỀN TẢNG MẠNG XÃ HỘI KINH DOANH ẨM THỰC
A2: Module Code | B2: Đăng ký mở cửa hàng
A3: Người kiểm tra | B3: Phạm Đình Vân Ly
B4: Hoàn thành | C4: Lỗi | D4: Chưa kiểm tra | E4: Bị chăn | F4: Tổng số trường hợp thử nghiệm
A5: Round 1 | B5: =COUNTIF(G26:G1046,"passed") -> 58 | C5: =COUNTIF(G26:G1046,"failed") -> 7 | D5: =COUNTIF(G26:G1046,"untest") -> 0 | E5: =COUNTIF(G26:G1046,"blocked") -> 0 | F5: =COUNTIF(A22:A1042, "*SHOP*") -> 65
A6: Round 2 | B6: =COUNTIF(I26:I1047,"passed") -> 7 | C6: =COUNTIF(I26:I1046,"failed") -> 0 | D6: =COUNTIF(G26:G1046,"untest") -> 0 | E6: =COUNTIF(G26:G1046,"blocked") -> 0 | F6: =COUNTIF(A23:A1043, "*SHOP*") -> 65
A22: Test Case ID | B22: Mô tả | C22: Hành động | D22: Điều kiện tiên quyết | E22: Kết quả mong đợi | F22: Kết quả thực tế | G22: Kết quả | I22: Kết quả | K22: Chú thích
G23: Vòng 1 | I23: Vòng 2
G24: Trạng thái | H24: Ngày kiểm tra | I24: Trạng thái | J24: Ngày kiểm tra
A25: GUI
A26: GUI_SHOP_01 | B26: Kiểm tra hiển thị mặc định của menu trái | C26: 1, Quan sát danh sách menu bên trái tại trang cài đặt | D26: Người dùng đã đăng nhập | E26: Hiển thị đủ 4 mục: Thông tin cá nhân, Mật khẩu và bảo mật, Chế độ chuyên nghiệp, Quản lý chặn | F26: Hệ thống hiển thị đúng menu sidebar | G26: passed | H26: 46143
A27: GUI_SHOP_02 | B27: Kiểm tra hiển thị trang chế độ chuyên nghiệp | C27: 1. Quan sát nội dung chính khi ở tab Chế độ chuyên nghiệp | D27: Tài khoản đang trong trạng thái gửi yêu cầu xét duyệt | E27: Hiển thị 2 dòng: "Kiếm tiền từ nội dung" và "Mở cửa hàng" | F27: Trang chế độ chuyên nghiệp hiển thị đúng "Kiếm tiền từ nội dung" và "Mở cửa hàng" | G27: passed | H27: 46143
A28: GUI_SHOP_03 | B28: Kiểm tra giao diện form "Đăng ký mở cửa hàng" | C28: 1. Chọn cài đặt 2. Chọn chế độ chuyên nghiệp 3. Chọn mở cửa hàng | D28: Đang ở tab Chế độ chuyên nghiệp | E28: Hiển thị đầy đủ các trường thông tin có trong trang đăng ký | F28: Hiển thị đầy đủ các trường thông tin có trong trang đăng ký | G28: passed | H28: 46143
A29: GUI_SHOP_04 | B29: Kiểm tra placeholder và icon trong các input | C29: 1. Chọn cài đặt 2. Chọn chế độ chuyên nghiệp 3. Chọn mở cửa hàng 4. Quan sát UI | D29: Form đăng ký đang hiển thị | E29: Placeholder hiển thị đúng | F29: Các dòng chữ mờ hướng dẫn trong ô nhập liệu hiển thị đúng nội dung quy định | G29: passed | H29: 46143
A30: GUI_SHOP_05 | B30: Kiểm tra hiển thị nút "Gửi" | C30: 1. Chọn cài đặt 2. Chọn chế độ chuyên nghiệp 3. Chọn mở cửa hàng 4. Quan sát UI | D30: Form đăng ký đang hiển thị | E30: Hiển thị nút "Gửi" màu xanh lá cây, đúng vị trí, enable | F30: Nút lệnh "Gửi" có màu xanh đặc trưng, nằm đúng vị trí thiết kế và sẵn sàng để tương tác | G30: passed | H30: 46143
A31: GUI_SHOP_06 | B31: Kiểm tra checkbox box điều khoản | C31: 1. Chọn cài đặt 2. Chọn chế độ chuyên nghiệp 3. Chọn mở cửa hàng 4. Tick vào điều khoản và phí | D31: Form đăng ký đang hiển thị | E31: Có thể tick/ untick các điều khoản | F31: Thao tác đánh dấu hoặc hủy đánh dấu tại ô điều khoản phản hồi ngay lập tức | G31: passed | H31: 46143
A32: GUI_SHOP_07 | B32: Kiểm tra nút chọn ảnh ở tệp đính kèm | C32: 1. Chọn cài đặt 2. Chọn chế độ chuyên nghiệp 3. Chọn mở cửa hàng 4. Click "chọn ảnh" | D32: Form đăng ký đang hiển thị | E32: Mở thư mục chọn ảnh | F32: Hệ thống đã kích hoạt được cửa sổ chọn tệp tin từ bộ nhớ thiết bị | G32: passed | H32: 46143
A33: GUI_SHOP_08 | B33: Hiển thị form thỏa thuận | C33: 1. Chọn mở cửa hàng 2. Nhập thông tin 3. Gửi thông tin 4. Mở form thỏa thuận | D33: Đã gửi đăng ký mở cửa hàng | E33: Sau khi nhập đủ thông tin và click gửi, form thỏa thuận được mở ra | F33: Hiển thị popup thỏa thuận dịch vụ với đầy đủ thông tin về chính sách khi đăng ký mở cửa hàng | G33: passed | H33: 46143
A34: GUI_SHOP_09 | B34: Xác nhận responsive UI | C34: 1. Resize màn hình | D34: Trang đang mở | E34: Các nút không bị vỡ layout | F34: UI responsive tốt, không bị vỡ layout khi resize màn hình | G34: passed | H34: 46143
A35: GUI_SHOP_10 | B35: Xác nhận layout tổng thể | C35: 1. Quan sát toàn trang | D35: Trang load thành công | E35: Giao diện chia 2 cột rõ ràng, không lệch | F35: Layout giao diện rõ ràng, không bị lệch | G35: passed | H35: 46143
A36: FUNCTION
A37: TC_SHOP_11 | B37: Xác nhận hiển thị đúng chức năng khi truy cập chế độ chuyên nghiệp | C37: 1. Đăng nhập hệ thống 2. Truy cập chế độ chuyên nghiệp | D37: Người dùng đã đăng nhập hợp lệ | E37: Hiển thị "kiếm tiền từ nội dung" và "mở cửa hàng" | F37: Chế độ chuyên nghiệp đã liệt kê đúng hai tùy chọn về "kiếm tiền từ nội dung" và "mở cửa hàng" | G37: passed | H37: 46143
A38: TC_SHOP_12 | B38: Xác nhận điều hướng thành công khi click vào chức năng "Mở cửa hàng" | C38: 1. Truy cập chế độ chuyên nghiệp 2. Click "Mở cửa hàng" | D38: Người dùng đã đăng nhập | E38: Điều hướng tới màn hình form đăng ký hoặc màn hình trạng thái | F38: Hệ thống điều hướng đến đúng trang đăng ký hoặc màn hình trạng thái tương ứng | G38: passed | H38: 46143
A39: TC_SHOP_13 | B39: Xác nhận hiển thị thông báo lỗi khi thành viên chưa đăng nhập đăng ký mở cửa hàng | C39: 1. Truy cập trực tiếp chức năng 2. Quan sát kết quả | D39: Người dùng chưa đăng nhập | E39: Hệ thống điều hướng về trang login hoặc hiển thị lỗi "Unauthorized" | F39: Truy cập trái phép bị chặn và hệ thống tự động đẩy về trang đăng nhập | G39: passed | H39: 46143
A40: TC_SHOP_14 | B40: Xác nhận hiển thị form khi mở chức năng đăng ký cửa hàng | C40: 1. Truy cập Cài đặt 2. Chọn "Chế độ chuyên nghiệp" 3. Click "Mở cửa hàng" | D40: User đã đăng nhập | E40: Hiển thị đầy đủ form gồm: Thông tin cơ bản, Thông tin cửa hàng, Điều khoản, Đính kèm | F40: Mẫu đơn đăng ký đã liệt kê đầy đủ các phần: Thông tin cơ bản, Thông tin cửa hàng, Điều khoản và Đính kèm | G40: passed | H40: 46143
A41: TC_SHOP_15 | B41: Xác nhận đăng ký thành công khi nhập đầy đủ thông tin hợp lệ | C41: 1. Nhập đầy đủ thông tin hợp lệ 2. Click "Gửi" | D41: Form hiển thị | E41: Hiển thị pop-up điều khoản | F41: Pop-up chứa các điều khoản dịch vụ hiển thị sau khi người dùng hoàn tất nhập liệu và nhấn gửi | G41: passed | H41: 46143
A42: TC_SHOP_16 | B42: Xác nhận hiển thị pop-up điều khoản | C42: 1. Click "Gửi" | D42: Form hợp lệ | E42: Hiển thị pop-up điều khoản sử dụng dịch vụ | F42: Nội dung điều khoản sử dụng dịch vụ trong pop-up hiển thị rõ ràn | G42: passed | H42: 46143
A43: TC_SHOP_17 | B43: Xác nhận chuyển sang trang thanh toán khi đồng ý điều khoản | C43: 1. Tick "Tôi đã đọc và đồng ý" 2. Click "Xác nhận" | D43: Pop-up hiển thị | E43: Điều hướng tới trang thanh toán | F43: Người dùng được chuyển hướng sang trang thanh toán sau khi xác nhận đồng ý với các điều khoản | G43: passed | H43: 46143
A44: TC_SHOP_18 | B44: Xác nhận hiển thị đầy đủ thông tin thanh toán | C44: 1. Quan sát trang thanh toán | D44: N/A | E44: Hiển thị: gói dịch vụ, QR code, thông tin chuyển khoản | F44: Trang thanh toán cung cấp đầy đủ mã QR, thông tin tài khoản chuyển khoản và gói dịch vụ tương ứng | G44: passed | H44: 46143
A45: TC_SHOP_19 | B45: Xác nhận gửi đăng ký sau khi thanh toán | C45: 1. Upload ảnh thanh toán2. Click "Gửi" | D45: Đã vào trang thanh toán | E45: Hệ thống lưu đơn đăng ký thành công | F45: Đơn đăng ký được ghi nhận thành công vào hệ thống sau khi người dùng tải lên minh chứng thanh toán | G45: passed | H45: 46143
A46: TC_SHOP_20 | B46: Xác nhận hệ thống hiển thị thông tin cơ bản đầy đủ | C46: 1. Truy cập form | D46: Trang mở | E46: Hiển thị các trường: Chủ sở hữu, CCCD, SĐT, Địa chỉ | F46: Các trường thông tin cá nhân như Chủ sở hữu, CCCD, SĐT và Địa chỉ được hiển thị đầy đủ trong form | G46: passed | H46: 46143
A47: TC_SHOP_21 | B47: Xác nhận hiển thị lỗi khi nhập tên chủ sở hữu >100 ký tự | C47: 1. Nhập >100 ký tự vào chủ sở hữu 2. Click "Gửi" | D47: Form mở | E47: Hiển thị lỗi “Vượt quá số ký tự cho phép” | F47: Hệ thống phát hiện và thông báo lỗi khi độ dài tên chủ sở hữu vượt quá ký tự cho phép | G47: passed | H47: 46143
A48: TC_SHOP_22 | B48: Xác nhận hiển thị đúng khi nhập CCCD đúng 12 số | C48: 1. Nhập CCCD =12 số 2. Click "Gửi" | D48: Form mở | E48: Hệ thống chấp nhận | F48: Dữ liệu CCCD gồm 12 chữ số được hệ thống ghi nhận thành công | G48: passed | H48: 46143
... A61: TC_SHOP_35 | B61: Xác nhận nhập địa chỉ kinh doanh khi nhập chính xác | C61: 1. Nhập địa chỉ | D61: Form mở | E61: Hệ thống chấp nhận | F61: Hệ thống chấp nhận khi nhập địa chỉ kinh doanh hợp lệ | G61: passed | H61: 46143
A62: TC_SHOP_36 | B62: Hiển thị lỗi khi chưa tick điều khoản mà gửi đăng ký | C62: 1. Không tick điều khoản 2. Click “Gửi” | D62: Form mở | E62: Hiển thị lỗi yêu cầu chọn điều khoản | F62: Người dùng vẫn có thể gửi đơn đăng ký dù chưa xác nhận vào ô điều khoản | G62: failed | H62: 46143 | I62: passed | J62: 46148
A63: TC_SHOP_37 | B63: Hiển thị lỗi khi chưa upload CCCD | C63: 1. Không upload file CCCD 2. Click “Gửi” | D63: Form mở | E63: Hiển thị lỗi yêu cầu upload CCCD | F63: Hệ thống không ngăn chặn hành vi gửi đơn khi thiếu tệp đính kèm ảnh CCCD | G63: failed | H63: 46143 | I63: passed | J63: 46148
A64: TC_SHOP_38 | B64: Xác nhận hiển thị đúng khi upload menu thành công | C64: 1. Upload file hợp lệ | D64: Form mở | E64: Hiển thị preview hoặc trạng thái upload thành công | F64: Menu upload thành công được hiển thị lên màn hình | G64: passed | H64: 46143
A65: TC_SHOP_39 | B65: Hiển thị lỗi khi upload menu sai định dạng | C65: 1. Upload file sai format | D65: Form mở | E65: Hiển thị lỗi định dạng file | F65: Menu sai định hiển thị thông báo và không cho phép gửi đăng ký | G65: passed | H65: 46143
A66: TC_SHOP_40 | B66: Hiển thị lỗi khi upload <5 ảnh menu | C66: 1. Upload <5 ảnh | D66: Form mở | E66: Hiển thị lỗi yêu cầu ≥5 ảnh | F66: Đơn đăng ký vẫn được gửi đi dù số lượng ảnh menu tải lên ít hơn 5 tấm | G66: failed | H66: 46143 | I66: passed | J66: 46148
A67: TC_SHOP_41 | B67: Hiển thị lỗi khi chưa nhập đủ thông tin | C67: 1. Bỏ trống ô input bắt buộc 2. Click “Gửi” | D67: Form mở | E67: Hiển thị lỗi dưới từng input hoặc disable nút | F67: Hiển thị thống báo yêu cầu nhập đầy đủ thông tin bắt buộc để tiếp tục đăng ký | G67: passed | H67: 46143
...

Sheet Giỏ hàng
A1: Project Name | B1: XÂY DỰNG HỆ THỐNG DISHNET - NỀN TẢNG MẠNG XÃ HỘI KINH DOANH ẨM THỰC
A2: Module Code | B2: Giỏ hàng
A3: Người kiểm tra | B3: Phan Thị Lệ Thi
B4: Hoàn thành | C4: Lỗi | D4: Chưa kiểm tra | E4: Bị chăn | F4: Tổng số trường hợp thử nghiệm
A5: Round 1 | B5: =COUNTIF(G27:G987,"passed") -> 59 | C5: =COUNTIF(G27:G987,"failed") -> 0 | D5: =COUNTIF(G27:G987,"untest") -> 0 | E5: =COUNTIF(G27:G987,"blocked") -> 0 | F5: =COUNTIF(A23:A983, "*CART*") -> 59
