Workbook

Sheet Sprint1
A1: Project name: | C1: Xây dựng hệ thống DishNet - Nền tảng mạng xã hội kinh doanh ẩm thực
A2: Module name: | C2: Sprint 1
A3: Start date: | C3: 46099 | K3: Kết thúc đúng hạn
A4: End date: | C4: 46111 | K4: Muộn
K5: Trước thời hạn
B6: SPRINT 1 REPORT
B7: No | C7: Thành viên | D7: Thực tế | E7: Ước tính
B8: 1 | C8: Lê Văn Cường | D8: =SUMIF(E15:F63,"Cường",G15:G63)+SUMIF(E15:F63,"Vy, Thi, Cường",G15:G63)/3+SUMIF(E15:F63,"All team",G15:G63)/5+SUMIF(E15:F63,"Cường, Vy",G15:G63)/2 -> 25.8 | E8: =SUMIF(E15:F63,"Cường",H15:H63)+SUMIF(E15:F63,"Vy, Thi, Cường",H15:H63)/3+SUMIF(E15:F63,"All team",H15:H63)/5+SUMIF(E15:F63,"Cường, Vy",H15:H63)/2 -> 26
B9: 2 | C9: Phạm Đình Vân Ly | D9: =SUMIF(E15:F63,"Ly",G15:G63)+SUMIF(E15:F63,"Yên, Ly",G15:G63)/2+SUMIF(E15:F63,"All team",G15:G63)/5 -> 25.8 | E9: =SUMIF(E15:F63,"Ly",H15:H63)+SUMIF(E15:F63,"Yên, Ly",H15:H63)/2+SUMIF(E15:F63,"All team",H15:H63)/5 -> 26
B10: 3 | C10: Phan Thị Lệ Thi | D10: =SUMIF(E15:F63,"Thi",G15:G63)+SUMIF(E15:F63,"Vy, Thi, Cường",G15:G63)/3+SUMIF(E15:F63,"All team",G15:G63)/5+SUMIF(E15:F63,"Vy, Thi",G15:G63)/2+SUMIF(E15:F63,"Yên, Thi",G15:G63)/2 -> 28.8 | E10: =SUMIF(E15:F63,"Thi",H15:H63)+SUMIF(E15:F63,"Vy, Thi, Cường",H15:H63)/3+SUMIF(E15:F63,"All team",H15:H63)/5+SUMIF(E15:F63,"Vy, Thi",H15:H63)/2+SUMIF(E15:F63,"Yên, Thi",H15:H63)/2 -> 28
B11: 4 | C11: Huỳnh Thị Vy | D11: =SUMIF(E15:F63,"Vy",G15:G63)+SUMIF(E15:F63,"Vy, Thi, Cường",G15:G63)/3+SUMIF(E15:F63,"All team",G15:G63)/5+SUMIF(E15:F63,"Cường, Vy",G15:G63)/2+SUMIF(E15:F63,"Vy, Thi",G15:G63)/2 -> 29.8 | E11: =SUMIF(E15:F63,"Vy",H15:H63)+SUMIF(E15:F63,"Vy, Thi, Cường",H15:H63)/3+SUMIF(E15:F63,"All team",H15:H63)/5+SUMIF(E15:F63,"Cường, Vy",H15:H63)/2+SUMIF(E15:F63,"Vy, Thi",H15:H63)/2 -> 28
B12: 5 | C12: Trần Thị Mai Yên | D12: =SUMIF(E15:F63,"Yên",G15:G63)+SUMIF(E15:F63,"Yên, Ly",G15:G63)/2+SUMIF(E15:F63,"All team",G15:G63)/5+SUMIF(E15:F63,"Yên, Thi",G15:G63)/2 -> 26.8 | E12: =SUMIF(E15:F63,"Yên",H15:H63)+SUMIF(E15:F63,"Yên, Ly",H15:H63)/2+SUMIF(E15:F63,"All team",H15:H63)/5+SUMIF(E15:F63,"Yên, Thi",H15:H63)/2 -> 26
B13: Tổng | D13: =SUM(D8:D12) -> 137 | E13: =SUM(E8:E12) -> 134
A15: Sprint | B15: Compoment | C15: Task name | E15: Responsible Member | G15: Thực tế | H15: Ước tính | I15: 46099 | J15: 46100 | K15: 46101 | L15: 46102 | M15: 46103 | N15: 46104 | O15: 46105 | P15: 46106 | Q15: 46107 | R15: 46108 | S15: 46109 | T15: 46110 | U15: 46111
A16: Sprint 1 | B16: Họp kế hoạch Sprint | E16: All team | G16: =H16+I16 -> 10 | H16: 10 | I16: 0 | J16: 0 | K16: 0 | L16: 0 | M16: 0 | N16: 0 | O16: 0 | P16: 0 | Q16: 0 | R16: 0 | S16: 0 | T16: 0 | U16: 0
B17: Tạo Sprint Backlog 1 | E17: Yên, Ly | G17: =H17+J17 -> 4 | H17: 4 | I17: 4 | J17: 0 | K17: 0 | L17: 0 | M17: 0 | N17: 0 | O17: 0 | P17: 0 | Q17: 0 | R17: 0 | S17: 0 | T17: 0 | U17: 0
B18: Tạo tài liệu kiểm thử cho Sprint 1 | E18: Vy, Thi, Cường | G18: =H18+J18 -> 6 | H18: 6 | I18: 6 | J18: 0 | K18: 0 | L18: 0 | M18: 0 | N18: 0 | O18: 0 | P18: 0 | Q18: 0 | R18: 0 | S18: 0 | T18: 0 | U18: 0
B19: User interface design | C19: Đăng nhập, Đăng ký | E19: Cường | G19: =H19+K19 -> 2 | H19: 2 | I19: 2 | J19: 2 | K19: 0 | L19: 0 | M19: 0 | N19: 0 | O19: 0 | P19: 0 | Q19: 0 | R19: 0 | S19: 0 | T19: 0 | U19: 0
C20: Quên mật khẩu, Thống kê hệ thống | E20: Thi | G20: =H20+K20 -> 2 | H20: 2 | I20: 2 | J20: 2 | K20: 0 | L20: 0 | M20: 0 | N20: 0 | O20: 0 | P20: 0 | Q20: 0 | R20: 0 | S20: 0 | T20: 0 | U20: 0
C21: Quản lý đơn hàng hệ thống, Kiểm duyệt yêu cầu hệ thống | E21: Yên | G21: =H21+K22 -> 3 | H21: 2 | I21: 2 | J21: 2 | K21: 0 | L21: 0 | M21: 0 | N21: 0 | O21: 0 | P21: 0 | Q21: 0 | R21: 0 | S21: 0 | T21: 0 | U21: 0
K22: 1 | L22: 0 | M22: 0 | N22: 0 | O22: 0 | P22: 0 | Q22: 0 | R22: 0 | S22: 0 | T22: 0 | U22: 0
C23: Quản lý tài khoản, Quản lý doanh thu hệ thống | E23: Ly | G23: =H23+K23 -> 2 | H23: 2 | I23: 2 | J23: 2 | K23: 0 | L23: 0 | M23: 0 | N23: 0 | O23: 0 | P23: 0 | Q23: 0 | R23: 0 | S23: 0 | T23: 0 | U23: 0
C24: Quản lý khuyến mãi hệ thống | E24: Vy | G24: =H24+K24 -> 2 | H24: 2 | I24: 2 | J24: 2 | K24: 0 | L24: 0 | M24: 0 | N24: 0 | O24: 0 | P24: 0 | Q24: 0 | R24: 0 | S24: 0 | T24: 0 | U24: 0
C25: Review all user interfaces of sprint 1 | E25: All team | G25: =H25+L25 -> 10 | H25: 10 | I25: 10 | J25: 10 | K25: 10 | L25: 0 | M25: 0 | N25: 0 | O25: 0 | P25: 0 | Q25: 0 | R25: 0 | S25: 0 | T25: 0 | U25: 0
B26: Design test case | C26: Thiết kế trường kiểm thử cho đăng nhập, đăng ký | E26: Ly | G26: =H26+M26 -> 2 | H26: 2 | I26: 2 | J26: 2 | K26: 2 | L26: 2 | M26: 0 | N26: 0 | O26: 0 | P26: 0 | Q26: 0 | R26: 0 | S26: 0 | T26: 0 | U26: 0
C27: Thiết kế trường kiểm thử cho quên mật khẩu, thống kê hệ thống | E27: Yên | G27: =H27+M27 -> 2 | H27: 2 | I27: 2 | J27: 2 | K27: 2 | L27: 2 | M27: 0 | N27: 0 | O27: 0 | P27: 0 | Q27: 0 | R27: 0 | S27: 0 | T27: 0 | U27: 0
C28: Thiết kế trường kiểm thử cho quản lý đơn hàng hệ thống, kiểm duyệt yêu cầu hệ thống | E28: Vy | G28: =H28+M29 -> 3 | H28: 2 | I28: 2 | J28: 2 | K28: 2 | L28: 2 | M28: 0 | N28: 0 | O28: 0 | P28: 0 | Q28: 0 | R28: 0 | S28: 0 | T28: 0 | U28: 0
M29: 1
C30: Thiết kế trường kiểm thử cho quản lý tài khoản, quản lý doanh thu hệ thống | E30: Thi | G30: =H30+M30 -> 2 | H30: 2 | I30: 2 | J30: 2 | K30: 2 | L30: 2 | M30: 0 | N30: 0 | O30: 0 | P30: 0 | Q30: 0 | R30: 0 | S30: 0 | T30: 0 | U30: 0
C31: Thiết kế trường kiểm thử cho quản lý khuyến mãi hệ thống | E31: Cường | G31: =H31+M31 -> 2 | H31: 2 | I31: 2 | J31: 2 | K31: 2 | L31: 2 | M31: 0 | N31: 0 | O31: 0 | P31: 0 | Q31: 0 | R31: 0 | S31: 0 | T31: 0 | U31: 0
C32: Review all test case of sprint 1 | E32: All team | G32: =H32+N33 -> 9 | H32: 10 | I32: 10 | J32: 10 | K32: 10 | L32: 10 | M32: 10 | N32: 0 | O32: 0 | P32: 0 | Q32: 0 | R32: 0 | S32: 0 | T32: 0 | U32: 0
N33: -1
B34: Coding | C34: Thiết kế front-end đăng nhập, đăng ký | E34: Yên | G34: =H34 -> 2 | H34: 2 | I34: 2 | J34: 2 | K34: 2 | L34: 2 | M34: 2 | N34: 2 | O34: 0 | P34: 0 | Q34: 0 | R34: 0 | S34: 0 | T34: 0 | U34: 0
C35: Thiết kế front-end quên mật khẩu, thống kê hệ thống | E35: Vy | G35: =H35 -> 2 | H35: 2 | I35: 2 | J35: 2 | K35: 2 | L35: 2 | M35: 2 | N35: 2 | O35: 0 | P35: 0 | Q35: 0 | R35: 0 | S35: 0 | T35: 0 | U35: 0
C36: Thiết kế front-end quản lý đơn hàng hệ thống, kiểm duyệt yêu cầu hệ thống | E36: Thi | G36: =H36 -> 2 | H36: 2 | I36: 2 | J36: 2 | K36: 2 | L36: 2 | M36: 2 | N36: 2 | O36: 0 | P36: 0 | Q36: 0 | R36: 0 | S36: 0 | T36: 0 | U36: 0
C37: Thiết kế front-end quản lý tài khoản, doanh thu hệ thống | E37: Cường | G37: =H37 -> 2 | H37: 2 | I37: 2 | J37: 2 | K37: 2 | L37: 2 | M37: 2 | N37: 2 | O37: 0 | P37: 0 | Q37: 0 | R37: 0 | S37: 0 | T37: 0 | U37: 0
C38: Thiết kế front-end quản lý khuyến mãi hệ thống | E38: Ly | G38: =H38 -> 2 | H38: 2 | I38: 2 | J38: 2 | K38: 2 | L38: 2 | M38: 2 | N38: 2 | O38: 0 | P38: 0 | Q38: 0 | R38: 0 | S38: 0 | T38: 0 | U38: 0
C39: Code back-end đăng nhập, đăng ký | E39: Yên | G39: =H39+P39 -> 2 | H39: 2 | I39: 2 | J39: 2 | K39: 2 | L39: 2 | M39: 2 | N39: 2 | O39: 2 | P39: 0 | Q39: 0 | R39: 0 | S39: 0 | T39: 0 | U39: 0
C40: Code back-end quên mật khẩu, thống kê hệ thống | E40: Vy | G40: =H40+P40 -> 2 | H40: 2 | I40: 2 | J40: 2 | K40: 2 | L40: 2 | M40: 2 | N40: 2 | O40: 2 | P40: 0 | Q40: 0 | R40: 0 | S40: 0 | T40: 0 | U40: 0
C41: Code back-end quản lý đơn hàng hệ thống, kiểm duyệt yêu cầu hệ thống | E41: Thi | G41: =H41+P42 -> 3 | H41: 2 | I41: 2 | J41: 2 | K41: 2 | L41: 2 | M41: 2 | N41: 2 | O41: 2 | P41: 0 | Q41: 0 | R41: 0 | S41: 0 | T41: 0 | U41: 0
...

Sheet Sprint2
A1: Project name: | C1: Xây dựng hệ thống DishNet - Nền tảng mạng xã hội kinh doanh ẩm thực
A2: Module name: | C2: Sprint 2
A3: Start date: | C3: 46112 | K3: Kết thúc đúng hạn
A4: End date: | C4: 46130 | K4: Muộn
K5: Trước thời hạn
B6: SPRINT 2 REPORT
B7: No | C7: Thành viên | D7: Thực tế | E7: Ước tính
B8: 1 | C8: Lê Văn Cường | D8: =SUMIF(E15:F104,"Cường",G15:G104)+SUMIF(E15:F104,"Vy, Thi, Cường",G15:G104)/3+SUMIF(E15:F104,"All team",G15:G104)/5 -> 39.8 | E8: =SUMIF(E15:F104,"Cường",H15:H104)+SUMIF(E15:F104,"Vy, Thi, Cường",H15:H104)/3+SUMIF(E15:F104,"All team",H15:H104)/5+SUMIF(E15:F104,"Cường, Ly",H15:H104)/2 -> 40
B9: 2 | C9: Phạm Đình Vân Ly | D9: =SUMIF(E15:F104,"Ly",G15:G104)+SUMIF(E15:F104,"Yên, Ly",G15:G104)/2+SUMIF(E15:F104,"All team",G15:G104)/5 -> 42.8 | E9: =SUMIF(E15:F104,"Ly",H15:H104)+SUMIF(E15:F104,"Yên, Ly",H15:H104)/2+SUMIF(E15:F104,"All team",H15:H104)/5+SUMIF(E15:F104,"Cường, Ly",H15:H104)/2 -> 40
B10: 3 | C10: Phan Thị Lệ Thi | D10: =SUMIF(E15:F104,"Thi",G15:G104)+SUMIF(E15:F104,"Vy, Thi, Cường",G15:G104)/3+SUMIF(E15:F104,"All team",G15:G104)/5 -> 38.8 | E10: =SUMIF(E15:F104,"Thi",H15:H104)+SUMIF(E15:F104,"Vy, Thi, Cường",H15:H104)/3+SUMIF(E15:F104,"All team",H15:H104)/5 -> 40
B11: 4 | C11: Huỳnh Thị Vy | D11: =SUMIF(E15:F104,"Vy",G15:G104)+SUMIF(E15:F104,"Vy, Thi, Cường",G15:G104)/3+SUMIF(E15:F104,"All team",G15:G104)/5 -> 39.8 | E11: =SUMIF(E15:F104,"Vy",H15:H104)+SUMIF(E15:F104,"Vy, Thi, Cường",H15:H104)/3+SUMIF(E15:F104,"All team",H15:H104)/5 -> 40
B12: 5 | C12: Trần Thị Mai Yên | D12: =SUMIF(E15:F104,"Yên",G15:G104)+SUMIF(E15:F104,"Yên, Ly",G15:G104)/2+SUMIF(E15:F104,"All team",G15:G104)/5 -> 41.8 | E12: =SUMIF(E15:F104,"Yên",H15:H104)+SUMIF(E15:F104,"Yên, Ly",H15:H104)/2+SUMIF(E15:F104,"All team",H15:H104)/5 -> 40
B13: Tổng | D13: =SUM(D8:D12) -> 203 | E13: =SUM(E8:E12) -> 200
A15: Sprint | B15: Compoment | C15: Task name | E15: Responsible Member | G15: Thực tế | H15: Ước tính | I15: 46112 | J15: 46113 | K15: 46114 | L15: 46115 | M15: 46116 | N15: 46117 | O15: 46118 | P15: 46119 | Q15: 46120 | R15: 46121 | S15: 46122 | T15: 46123 | U15: 46124 | V15: 46125 | W15: 46126 | X15: 46127 | Y15: 46128 | Z15: 46129 | AA15: 46130
A16: Sprint 2 | B16: Họp kế hoạch Sprint | E16: All team | G16: =H16+I16 -> 10 | H16: 10 | I16: 0 | J16: 0 | K16: 0 | L16: 0 | M16: 0 | N16: 0 | O16: 0 | P16: 0 | Q16: 0 | R16: 0 | S16: 0 | T16: 0 | U16: 0 | V16: 0 | W16: 0 | X16: 0 | Y16: 0 | Z16: 0 | AA16: 0
B17: Tạo Sprint Backlog 2 | E17: Yên, Ly | G17: =H17+J17 -> 4 | H17: 4 | I17: 4 | J17: 0 | K17: 0 | L17: 0 | M17: 0 | N17: 0 | O17: 0 | P17: 0 | Q17: 0 | R17: 0 | S17: 0 | T17: 0 | U17: 0 | V17: 0 | W17: 0 | X17: 0 | Y17: 0 | Z17: 0 | AA17: 0
B18: Tạo tài liệu kiểm thử cho Sprint | E18: Vy, Thi, Cường | G18: =H18+J18 -> 6 | H18: 6 | I18: 6 | J18: 0 | K18: 0 | L18: 0 | M18: 0 | N18: 0 | O18: 0 | P18: 0 | Q18: 0 | R18: 0 | S18: 0 | T18: 0 | U18: 0 | V18: 0 | W18: 0 | X18: 0 | Y18: 0 | Z18: 0 | AA18: 0
B19: User interface design | C19: Quản lý yêu cầu hỗ trợ | E19: Cường | G19: =H19+K19 -> 2 | H19: 2 | I19: 2 | J19: 2 | K19: 0 | L19: 0 | M19: 0 | N19: 0 | O19: 0 | P19: 0 | Q19: 0 | R19: 0 | S19: 0 | T19: 0 | U19: 0 | V19: 0 | W19: 0 | X19: 0 | Y19: 0 | Z19: 0 | AA19: 0
C20: Quản lý báo cáo/ khiếu nại | E20: Thi | G20: =H20+K20 -> 2 | H20: 2 | I20: 2 | J20: 2 | K20: 0 | L20: 0 | M20: 0 | N20: 0 | O20: 0 | P20: 0 | Q20: 0 | R20: 0 | S20: 0 | T20: 0 | U20: 0 | V20: 0 | W20: 0 | X20: 0 | Y20: 0 | Z20: 0 | AA20: 0
C21: Tổng quan cửa hàng | E21: Yên | G21: =H21+K21 -> 2 | H21: 2 | I21: 2 | J21: 2 | K21: 0 | L21: 0 | M21: 0 | N21: 0 | O21: 0 | P21: 0 | Q21: 0 | R21: 0 | S21: 0 | T21: 0 | U21: 0 | V21: 0 | W21: 0 | X21: 0 | Y21: 0 | Z21: 0 | AA21: 0
C22: Quản lý doanh thu cửa hàng | E22: Ly | G22: =H22+K22 -> 2 | H22: 2 | I22: 2 | J22: 2 | K22: 0 | L22: 0 | M22: 0 | N22: 0 | O22: 0 | P22: 0 | Q22: 0 | R22: 0 | S22: 0 | T22: 0 | U22: 0 | V22: 0 | W22: 0 | X22: 0 | Y22: 0 | Z22: 0 | AA22: 0
C23: Quản lý menu cửa hàng | E23: Vy | G23: =H23+K23 -> 2 | H23: 2 | I23: 2 | J23: 2 | K23: 0 | L23: 0 | M23: 0 | N23: 0 | O23: 0 | P23: 0 | Q23: 0 | R23: 0 | S23: 0 | T23: 0 | U23: 0 | V23: 0 | W23: 0 | X23: 0 | Y23: 0 | Z23: 0 | AA23: 0
C24: Quản lý đơn hàng của cửa hàng | E24: Cường | G24: =H24+L24 -> 2 | H24: 2 | I24: 2 | J24: 2 | K24: 2 | L24: 0 | M24: 0 | N24: 0 | O24: 0 | P24: 0 | Q24: 0 | R24: 0 | S24: 0 | T24: 0 | U24: 0 | V24: 0 | W24: 0 | X24: 0 | Y24: 0 | Z24: 0 | AA24: 0
C25: Quản lý khuyến mãi cửa hàng | E25: Thi | G25: =H25+L25 -> 2 | H25: 2 | I25: 2 | J25: 2 | K25: 2 | L25: 0 | M25: 0 | N25: 0 | O25: 0 | P25: 0 | Q25: 0 | R25: 0 | S25: 0 | T25: 0 | U25: 0 | V25: 0 | W25: 0 | X25: 0 | Y25: 0 | Z25: 0 | AA25: 0
C26: Tìm kiếm | E26: Yên | G26: =H26+L26 -> 2 | H26: 2 | I26: 2 | J26: 2 | K26: 2 | L26: 0 | M26: 0 | N26: 0 | O26: 0 | P26: 0 | Q26: 0 | R26: 0 | S26: 0 | T26: 0 | U26: 0 | V26: 0 | W26: 0 | X26: 0 | Y26: 0 | Z26: 0 | AA26: 0
C27: Hồ sơ cá nhân | E27: Ly | G27: =H27+L27 -> 2 | H27: 2 | I27: 2 | J27: 2 | K27: 2 | L27: 0 | M27: 0 | N27: 0 | O27: 0 | P27: 0 | Q27: 0 | R27: 0 | S27: 0 | T27: 0 | U27: 0 | V27: 0 | W27: 0 | X27: 0 | Y27: 0 | Z27: 0 | AA27: 0
C28: Tương tác bài viết | E28: Vy | G28: =H28+L28 -> 2 | H28: 2 | I28: 2 | J28: 2 | K28: 2 | L28: 0 | M28: 0 | N28: 0 | O28: 0 | P28: 0 | Q28: 0 | R28: 0 | S28: 0 | T28: 0 | U28: 0 | V28: 0 | W28: 0 | X28: 0 | Y28: 0 | Z28: 0 | AA28: 0
C29: Review all user interfaces of sprint 2 | E29: All team | G29: =H29+M29 -> 10 | H29: 10 | I29: 10 | J29: 10 | K29: 10 | L29: 10 | M29: 0 | N29: 0 | O29: 0 | P29: 0 | Q29: 0 | R29: 0 | S29: 0 | T29: 0 | U29: 0 | V29: 0 | W29: 0 | X29: 0 | Y29: 0 | Z29: 0 | AA29: 0
B30: Design test case | C30: Thiết kế trường kiểm thử cho quản lý yêu cầu hỗ trợ | E30: Ly | G30: =H30+N30 -> 2 | H30: 2 | I30: 2 | J30: 2 | K30: 2 | L30: 2 | M30: 2 | N30: 0 | O30: 0 | P30: 0 | Q30: 0 | R30: 0 | S30: 0 | T30: 0 | U30: 0 | V30: 0 | W30: 0 | X30: 0 | Y30: 0 | Z30: 0 | AA30: 0
C31: Thiết kế trường kiểm thử cho quản lý báo cáo/ khiếu nại | E31: Yên | G31: =H31+N31 -> 2 | H31: 2 | I31: 2 | J31: 2 | K31: 2 | L31: 2 | M31: 2 | N31: 0 | O31: 0 | P31: 0 | Q31: 0 | R31: 0 | S31: 0 | T31: 0 | U31: 0 | V31: 0 | W31: 0 | X31: 0 | Y31: 0 | Z31: 0 | AA31: 0
C32: Thiết kế trường kiểm thử cho tổng quan cửa hàng | E32: Vy | G32: =H32+N32 -> 2 | H32: 2 | I32: 2 | J32: 2 | K32: 2 | L32: 2 | M32: 2 | N32: 0 | O32: 0 | P32: 0 | Q32: 0 | R32: 0 | S32: 0 | T32: 0 | U32: 0 | V32: 0 | W32: 0 | X32: 0 | Y32: 0 | Z32: 0 | AA32: 0
C33: Thiết kế trường kiểm thử cho quản lý doanh thu cửa hàng | E33: Thi | G33: =H33+N33 -> 2 | H33: 2 | I33: 2 | J33: 2 | K33: 2 | L33: 2 | M33: 2 | N33: 0 | O33: 0 | P33: 0 | Q33: 0 | R33: 0 | S33: 0 | T33: 0 | U33: 0 | V33: 0 | W33: 0 | X33: 0 | Y33: 0 | Z33: 0 | AA33: 0
C34: Thiết kế trường kiểm thử cho quản lý menu cửa hàng | E34: Cường | G34: =H34+N34 -> 2 | H34: 2 | I34: 2 | J34: 2 | K34: 2 | L34: 2 | M34: 2 | N34: 0 | O34: 0 | P34: 0 | Q34: 0 | R34: 0 | S34: 0 | T34: 0 | U34: 0 | V34: 0 | W34: 0 | X34: 0 | Y34: 0 | Z34: 0 | AA34: 0
C35: Thiết kế trường kiểm thử cho quản lý đơn hàng của cửa hàng | E35: Ly | G35: =H35+O36 -> 3 | H35: 2 | I35: 2 | J35: 2 | K35: 2 | L35: 2 | M35: 2 | N35: 2 | O35: 0 | P35: 0 | Q35: 0 | R35: 0 | S35: 0 | T35: 0 | U35: 0 | V35: 0 | W35: 0 | X35: 0 | Y35: 0 | Z35: 0 | AA35: 0
O36: 1
C37: Thiết kế trường kiểm thử cho quản lý khuyến mãi cửa hàng | E37: Yên | G37: =H37+O37 -> 2 | H37: 2 | I37: 2 | J37: 2 | K37: 2 | L37: 2 | M37: 2 | N37: 2 | O37: 0 | P37: 0 | Q37: 0 | R37: 0 | S37: 0 | T37: 0 | U37: 0 | V37: 0 | W37: 0 | X37: 0 | Y37: 0 | Z37: 0 | AA37: 0
C38: Thiết kế trường kiểm thử cho tìm kiếm | E38: Vy | G38: =H38+O38 -> 2 | H38: 2 | I38: 2 | J38: 2 | K38: 2 | L38: 2 | M38: 2 | N38: 2 | O38: 0 | P38: 0 | Q38: 0 | R38: 0 | S38: 0 | T38: 0 | U38: 0 | V38: 0 | W38: 0 | X38: 0 | Y38: 0 | Z38: 0 | AA38: 0
C39: Thiết kế trường kiểm thử cho hồ sơ cá nhân | E39: Thi | G39: =H39+O39 -> 2 | H39: 2 | I39: 2 | J39: 2 | K39: 2 | L39: 2 | M39: 2 | N39: 2 | O39: 0 | P39: 0 | Q39: 0 | R39: 0 | S39: 0 | T39: 0 | U39: 0 | V39: 0 | W39: 0 | X39: 0 | Y39: 0 | Z39: 0 | AA39: 0
C40: Thiết kế trường kiểm thử cho tương tác bài viết | E40: Cường | G40: =H40+O40 -> 2 | H40: 2 | I40: 2 | J40: 2 | K40: 2 | L40: 2 | M40: 2 | N40: 2 | O40: 0 | P40: 0 | Q40: 0 | R40: 0 | S40: 0 | T40: 0 | U40: 0 | V40: 0 | W40: 0 | X40: 0 | Y40: 0 | Z40: 0 | AA40: 0
C41: Review all test case of sprint 2 | E41: All team | G41: =H41+P42 -> 9 | H41: 10 | I41: 10 | J41: 10 | K41: 10 | L41: 10 | M41: 10 | N41: 10 | O41: 10 | P41: 0 | Q41: 0 | R41: 0 | S41: 0 | T41: 0 | U41: 0 | V41: 0 | W41: 0 | X41: 0 | Y41: 0 | Z41: 0 | AA41: 0
...

Sheet Sprint3
A1: Project name: | C1: Xây dựng hệ thống DishNet - Nền tảng mạng xã hội kinh doanh ẩm thực
A2: Module name: | C2: Sprint 3
A3: Start date: | C3: 46131 | K3: Kết thúc đúng hạn
A4: End date: | C4: 46150 | K4: Muộn
K5: Trước thời hạn
B6: SPRINT 3 REPORT
B7: No | C7: Thành viên | D7: Thực tế | E7: Ước tính
B8: 1 | C8: Lê Văn Cường | D8: =SUMIF(E15:F96,"Cường",G15:G96)+SUMIF(E15:F96,"Vy, Thi, Cường",G15:G96)/3+SUMIF(E15:F96,"All team",G15:G96)/5 -> 42.8 | E8: =SUMIF(E15:F96,"Cường",H15:H96)+SUMIF(E15:F96,"Vy, Thi, Cường",H15:H96)/3+SUMIF(E15:F96,"All team",H15:H96)/5+SUMIF(E15:F96,"Cường, Ly",H15:H96)/2 -> 40
B9: 2 | C9: Phạm Đình Vân Ly | D9: =SUMIF(E15:F96,"Ly",G15:G96)+SUMIF(E15:F96,"Yên, Ly",G15:G96)/2+SUMIF(E15:F96,"All team",G15:G96)/5 -> 41.8 | E9: =SUMIF(E15:F96,"Ly",H15:H96)+SUMIF(E15:F96,"Yên, Ly",H15:H96)/2+SUMIF(E15:F96,"All team",H15:H96)/5+SUMIF(E15:F96,"Cường, Ly",H15:H96)/2 -> 40
B10: 3 | C10: Phan Thị Lệ Thi | D10: =SUMIF(E15:F96,"Thi",G15:G96)+SUMIF(E15:F96,"Vy, Thi, Cường",G15:G96)/3+SUMIF(E15:F96,"All team",G15:G96)/5 -> 42.8 | E10: =SUMIF(E15:F96,"Thi",H15:H96)+SUMIF(E15:F96,"Vy, Thi, Cường",H15:H96)/3+SUMIF(E15:F96,"All team",H15:H96)/5 -> 40
B11: 4 | C11: Huỳnh Thị Vy | D11: =SUMIF(E15:F96,"Vy",G15:G96)+SUMIF(E15:F96,"Vy, Thi, Cường",G15:G96)/3+SUMIF(E15:F96,"All team",G15:G96)/5 -> 42.8 | E11: =SUMIF(E15:F96,"Vy",H15:H96)+SUMIF(E15:F96,"Vy, Thi, Cường",H15:H96)/3+SUMIF(E15:F96,"All team",H15:H96)/5 -> 40
B12: 5 | C12: Trần Thị Mai Yên | D12: =SUMIF(E15:F96,"Yên",G15:G96)+SUMIF(E15:F96,"Yên, Ly",G15:G96)/2+SUMIF(E15:F96,"All team",G15:G96)/5 -> 41.8 | E12: =SUMIF(E15:F96,"Yên",H15:H96)+SUMIF(E15:F96,"Yên, Ly",H15:H96)/2+SUMIF(E15:F96,"All team",H15:H96)/5 -> 40
B13: Tổng | D13: =SUM(D8:D12) -> 212 | E13: =SUM(E8:E12) -> 200
A15: Sprint | B15: Compoment | C15: Task name | E15: Responsible Member | G15: Thực tế | H15: Ước tính | I15: 46131 | J15: 46132 | K15: 46133 | L15: 46134 | M15: 46135 | N15: 46136 | O15: 46137 | P15: 46138 | Q15: 46139 | R15: 46140 | S15: 46141 | T15: 46142 | U15: 46143 | V15: 46144 | W15: 46145 | X15: 46146 | Y15: 46147 | Z15: 46148 | AA15: 46149 | AB15: 46150
A16: Sprint 3 | B16: Họp kế hoạch Sprint | E16: All team | G16: =H16+I16 -> 10 | H16: 10 | I16: 0 | J16: 0 | K16: 0 | L16: 0 | M16: 0 | N16: 0 | O16: 0 | P16: 0 | Q16: 0 | R16: 0 | S16: 0 | T16: 0 | U16: 0 | V16: 0 | W16: 0 | X16: 0 | Y16: 0 | Z16: 0 | AA16: 0 | AB16: 0
B17: Tạo Sprint Backlog 3 | E17: Yên, Ly | G17: =H17+J17 -> 4 | H17: 4 | I17: 4 | J17: 0 | K17: 0 | L17: 0 | M17: 0 | N17: 0 | O17: 0 | P17: 0 | Q17: 0 | R17: 0 | S17: 0 | T17: 0 | U17: 0 | V17: 0 | W17: 0 | X17: 0 | Y17: 0 | Z17: 0 | AA17: 0 | AB17: 0
B18: Tạo tài liệu kiểm thử cho Sprint | E18: Vy, Thi, Cường | G18: =H18+J18 -> 6 | H18: 6 | I18: 6 | J18: 0 | K18: 0 | L18: 0 | M18: 0 | N18: 0 | O18: 0 | P18: 0 | Q18: 0 | R18: 0 | S18: 0 | T18: 0 | U18: 0 | V18: 0 | W18: 0 | X18: 0 | Y18: 0 | Z18: 0 | AA18: 0 | AB18: 0
B19: User interface design | C19: Tương tác người dùng | E19: Vy | G19: =H19+K19 -> 2 | H19: 2 | I19: 2 | J19: 2 | K19: 0 | L19: 0 | M19: 0 | N19: 0 | O19: 0 | P19: 0 | Q19: 0 | R19: 0 | S19: 0 | T19: 0 | U19: 0 | V19: 0 | W19: 0 | X19: 0 | Y19: 0 | Z19: 0 | AA19: 0 | AB19: 0
C20: Bảng xếp hạng | E20: Thi | G20: =H20+K20 -> 2 | H20: 2 | I20: 2 | J20: 2 | K20: 0 | L20: 0 | M20: 0 | N20: 0 | O20: 0 | P20: 0 | Q20: 0 | R20: 0 | S20: 0 | T20: 0 | U20: 0 | V20: 0 | W20: 0 | X20: 0 | Y20: 0 | Z20: 0 | AA20: 0 | AB20: 0
C21: Trò chuyện | E21: Cường | G21: =H21+K21 -> 2 | H21: 2 | I21: 2 | J21: 2 | K21: 0 | L21: 0 | M21: 0 | N21: 0 | O21: 0 | P21: 0 | Q21: 0 | R21: 0 | S21: 0 | T21: 0 | U21: 0 | V21: 0 | W21: 0 | X21: 0 | Y21: 0 | Z21: 0 | AA21: 0 | AB21: 0
C22: Gửi yêu cầu hỗ trợ | E22: Ly | G22: =H22+K22 -> 2 | H22: 2 | I22: 2 | J22: 2 | K22: 0 | L22: 0 | M22: 0 | N22: 0 | O22: 0 | P22: 0 | Q22: 0 | R22: 0 | S22: 0 | T22: 0 | U22: 0 | V22: 0 | W22: 0 | X22: 0 | Y22: 0 | Z22: 0 | AA22: 0 | AB22: 0
C23: Kiếm tiền từ nội dung | E23: Yên | G23: =H23+K23 -> 2 | H23: 2 | I23: 2 | J23: 2 | K23: 0 | L23: 0 | M23: 0 | N23: 0 | O23: 0 | P23: 0 | Q23: 0 | R23: 0 | S23: 0 | T23: 0 | U23: 0 | V23: 0 | W23: 0 | X23: 0 | Y23: 0 | Z23: 0 | AA23: 0 | AB23: 0
C24: Đăng ký mở cửa hàng | E24: Vy | G24: =H24+L24 -> 2 | H24: 2 | I24: 2 | J24: 2 | K24: 2 | L24: 0 | M24: 0 | N24: 0 | O24: 0 | P24: 0 | Q24: 0 | R24: 0 | S24: 0 | T24: 0 | U24: 0 | V24: 0 | W24: 0 | X24: 0 | Y24: 0 | Z24: 0 | AA24: 0 | AB24: 0
C25: Giỏ hàng | E25: Thi | G25: =H25+L25 -> 2 | H25: 2 | I25: 2 | J25: 2 | K25: 2 | L25: 0 | M25: 0 | N25: 0 | O25: 0 | P25: 0 | Q25: 0 | R25: 0 | S25: 0 | T25: 0 | U25: 0 | V25: 0 | W25: 0 | X25: 0 | Y25: 0 | Z25: 0 | AA25: 0 | AB25: 0
C26: Thanh toán | E26: Cường | G26: =H26+L26 -> 2 | H26: 2 | I26: 2 | J26: 2 | K26: 2 | L26: 0 | M26: 0 | N26: 0 | O26: 0 | P26: 0 | Q26: 0 | R26: 0 | S26: 0 | T26: 0 | U26: 0 | V26: 0 | W26: 0 | X26: 0 | Y26: 0 | Z26: 0 | AA26: 0 | AB26: 0
C27: Đơn hàng của tôi | E27: Ly | G27: =H27+L27 -> 2 | H27: 2 | I27: 2 | J27: 2 | K27: 2 | L27: 0 | M27: 0 | N27: 0 | O27: 0 | P27: 0 | Q27: 0 | R27: 0 | S27: 0 | T27: 0 | U27: 0 | V27: 0 | W27: 0 | X27: 0 | Y27: 0 | Z27: 0 | AA27: 0 | AB27: 0
C28: Đánh giá đơn hàng | E28: Yên | G28: =H28+L28 -> 2 | H28: 2 | I28: 2 | J28: 2 | K28: 2 | L28: 0 | M28: 0 | N28: 0 | O28: 0 | P28: 0 | Q28: 0 | R28: 0 | S28: 0 | T28: 0 | U28: 0 | V28: 0 | W28: 0 | X28: 0 | Y28: 0 | Z28: 0 | AA28: 0 | AB28: 0
C29: Review all user interfaces of sprint 3 | E29: All team | G29: =H29+M29 -> 10 | H29: 10 | I29: 10 | J29: 10 | K29: 10 | L29: 10 | M29: 0 | N29: 0 | O29: 0 | P29: 0 | Q29: 0 | R29: 0 | S29: 0 | T29: 0 | U29: 0 | V29: 0 | W29: 0 | X29: 0 | Y29: 0 | Z29: 0 | AA29: 0 | AB29: 0
B30: Design test case | C30: Thiết kế trường hợp kiểm thử cho tương tác người dùng | E30: Ly | G30: =H30+N30 -> 2 | H30: 2 | I30: 2 | J30: 2 | K30: 2 | L30: 2 | M30: 2 | N30: 0 | O30: 0 | P30: 0 | Q30: 0 | R30: 0 | S30: 0 | T30: 0 | U30: 0 | V30: 0 | W30: 0 | X30: 0 | Y30: 0 | Z30: 0 | AA30: 0 | AB30: 0
C31: Thiết kế trường hợp kiểm thử cho bảng xếp hạng | E31: Thi | G31: =H31+N32 -> 2 | H31: 2 | I31: 2 | J31: 2 | K31: 2 | L31: 2 | M31: 2 | N31: 0 | O31: 0 | P31: 0 | Q31: 0 | R31: 0 | S31: 0 | T31: 0 | U31: 0 | V31: 0 | W31: 0 | X31: 0 | Y31: 0 | Z31: 0 | AA31: 0 | AB31: 0
C32: Thiết kế trường hợp kiểm thử cho trò chuyện | E32: Vy | G32: =H32+N33 -> 2 | H32: 2 | I32: 2 | J32: 2 | K32: 2 | L32: 2 | M32: 2 | N32: 0 | O32: 0 | P32: 0 | Q32: 0 | R32: 0 | S32: 0 | T32: 0 | U32: 0 | V32: 0 | W32: 0 | X32: 0 | Y32: 0 | Z32: 0 | AA32: 0 | AB32: 0
C33: Thiết kế trường hợp kiểm thử cho gửi yêu cầu hỗ trợ | E33: Yên | G33: =H33+N33 -> 2 | H33: 2 | I33: 2 | J33: 2 | K33: 2 | L33: 2 | M33: 2 | N33: 0 | O33: 0 | P33: 0 | Q33: 0 | R33: 0 | S33: 0 | T33: 0 | U33: 0 | V33: 0 | W33: 0 | X33: 0 | Y33: 0 | Z33: 0 | AA33: 0 | AB33: 0
C34: Thiết kế trường hợp kiểm thử cho kiếm tiền từ nội dung | E34: Cường | G34: =H34+N34 -> 2 | H34: 2 | I34: 2 | J34: 2 | K34: 2 | L34: 2 | M34: 2 | N34: 0 | O34: 0 | P34: 0 | Q34: 0 | R34: 0 | S34: 0 | T34: 0 | U34: 0 | V34: 0 | W34: 0 | X34: 0 | Y34: 0 | Z34: 0 | AA34: 0 | AB34: 0
C35: Thiết kế trường hợp kiểm thử cho đăng ký mở cửa hàng | E35: Ly | G35: =H35+O35 -> 2 | H35: 2 | I35: 2 | J35: 2 | K35: 2 | L35: 2 | M35: 2 | N35: 2 | O35: 0 | P35: 0 | Q35: 0 | R35: 0 | S35: 0 | T35: 0 | U35: 0 | V35: 0 | W35: 0 | X35: 0 | Y35: 0 | Z35: 0 | AA35: 0 | AB35: 0
C36: Thiết kế trường hợp kiểm thử cho giỏ hàng | E36: Thi | G36: =H36+O36 -> 2 | H36: 2 | I36: 2 | J36: 2 | K36: 2 | L36: 2 | M36: 2 | N36: 2 | O36: 0 | P36: 0 | Q36: 0 | R36: 0 | S36: 0 | T36: 0 | U36: 0 | V36: 0 | W36: 0 | X36: 0 | Y36: 0 | Z36: 0 | AA36: 0 | AB36: 0
C37: Thiết kế trường hợp kiểm thử cho thanh toán | E37: Vy | G37: =H37+O37 -> 2 | H37: 2 | I37: 2 | J37: 2 | K37: 2 | L37: 2 | M37: 2 | N37: 2 | O37: 0 | P37: 0 | Q37: 0 | R37: 0 | S37: 0 | T37: 0 | U37: 0 | V37: 0 | W37: 0 | X37: 0 | Y37: 0 | Z37: 0 | AA37: 0 | AB37: 0
C38: Thiết kế trường hợp kiểm thử cho đơn hàng của tôi | E38: Yên | G38: =H38+O38 -> 2 | H38: 2 | I38: 2 | J38: 2 | K38: 2 | L38: 2 | M38: 2 | N38: 2 | O38: 0 | P38: 0 | Q38: 0 | R38: 0 | S38: 0 | T38: 0 | U38: 0 | V38: 0 | W38: 0 | X38: 0 | Y38: 0 | Z38: 0 | AA38: 0 | AB38: 0
C39: Thiết kế trường hợp kiểm thử cho đánh giá đơn hàng | E39: Cường | G39: =H39+O39 -> 2 | H39: 2 | I39: 2 | J39: 2 | K39: 2 | L39: 2 | M39: 2 | N39: 2 | O39: 0 | P39: 0 | Q39: 0 | R39: 0 | S39: 0 | T39: 0 | U39: 0 | V39: 0 | W39: 0 | X39: 0 | Y39: 0 | Z39: 0 | AA39: 0 | AB39: 0
C40: Review all test case of sprint 3 | E40: All team | G40: =H40+P41 -> 9 | H40: 10 | I40: 10 | J40: 10 | K40: 10 | L40: 10 | M40: 10 | N40: 10 | O40: 10 | P40: 0 | Q40: 0 | R40: 0 | S40: 0 | T40: 0 | U40: 0 | V40: 0 | W40: 0 | X40: 0 | Y40: 0 | Z40: 0 | AA40: 0 | AB40: 0
P41: -1
...

Sheet Total
A2: SPRINT BACKLOG REPORT
B3: Cường | D3: Ly | F3: Thi | H3: Vy | J3: Yên
B4: Thực tế | C4: Ước tính | D4: Thực tế | E4: Ước tính | F4: Thực tế | G4: Ước tính | H4: Thực tế | I4: Ước tính | J4: Thực tế | K4: Ước tính
A5: Sprint 1 | B5: =Sprint1!D8 -> 25.8 | C5: =Sprint1!E8 -> 26 | D5: =Sprint1!D9 -> 25.8 | E5: =Sprint1!E9 -> 26 | F5: =Sprint1!D10 -> 28.8 | G5: =Sprint1!E10 -> 28 | H5: =Sprint1!D11 -> 29.8 | I5: =Sprint1!E11 -> 28 | J5: =Sprint1!D12 -> 26.8 | K5: =Sprint1!E12 -> 26
A6: Sprint 2 | B6: =Sprint2!D8 -> 39.8 | C6: =Sprint2!E8 -> 40 | D6: =Sprint2!D9 -> 42.8 | E6: =Sprint2!E9 -> 40 | F6: =Sprint2!D10 -> 38.8 | G6: =Sprint2!E10 -> 40 | H6: =Sprint2!D11 -> 39.8 | I6: =Sprint2!E11 -> 40 | J6: =Sprint2!D12 -> 41.8 | K6: =Sprint2!E12 -> 40
A7: Sprint 3 | B7: =Sprint3!D8 -> 42.8 | C7: =Sprint3!E8 -> 40 | D7: =Sprint3!D9 -> 41.8 | E7: =Sprint3!E9 -> 40 | F7: =Sprint3!D10 -> 42.8 | G7: =Sprint3!E10 -> 40 | H7: =Sprint3!D11 -> 42.8 | I7: =Sprint3!E11 -> 40 | J7: =Sprint3!D12 -> 41.8 | K7: =Sprint3!E12 -> 40
A8: Tổng | B8: =SUM(B5:B7) -> 108.4 | C8: =SUM(C5:C7) -> 106 | D8: =SUM(D5:D7) -> 110.4 | E8: =SUM(E5:E7) -> 106 | F8: =SUM(F5:F7) -> 110.4 | G8: =SUM(G5:G7) -> 108 | H8: =SUM(H5:H7) -> 112.4 | I8: =SUM(I5:I7) -> 108 | ... K8: =SUM(K5:K7) -> 106
E11: FINAL TOTAL
E12: Thực tế | F12: =SUMIF(B4:K4,"Thực Tế",B8:K8) -> 552
E13: Ước tính | F13: =SUMIF(B4:K4,"Ước tính",B8:K8) -> 534
