Workbook

Sheet Trường hợp kiểm thử
C4: TEST CASE SYSTEM SPRINT 2
C6: Tên dự án | D6: XÂY DỰNG HỆ THỐNG DISHNET - NỀN TẢNG MẠNG XÃ HỘI KINH DOANH ẨM THỰC
C7: STT | D7: Chức năng | E7: Sheet Name | F7: Số Testcase
C8: 1 | D8: Quản lý yêu cầu hỗ trợ | E8: Quản lý yêu cầu hỗ trợ | F8: ='Quản lý yêu cầu hỗ trợ'!F6 -> 62
C9: 2 | D9: Quản lý báo cáo/ khiếu nại | E9: Quản lý báo cáo/ khiếu nại | F9: ='Quản lý báo cáo khiếu nại'!F6 -> 71
C10: 3 | D10: Tổng quan cửa hàng | E10: Tổng quan cửa hàng | F10: ='Tổng quan cửa hàng'!F6 -> 75
C11: 4 | D11: Quản lý doanh thu cửa hàng | E11: Quản lý doanh thu cửa hàng | F11: ='Quản lý doanh thu cửa hàng'!F6 -> 69
C12: 5 | D12: Quản lý menu cửa hàng | E12: Quản lý menu cửa hàng | F12: ='Quản lý menu cửa hàng'!F6 -> 91
C13: 6 | D13: Quản lý đơn hàng của cửa hàng | E13: Quản lý đơn hàng của cửa hàng | F13: ='Quản lý đơn hàng của cửa hàng'!F6 -> 82
C14: 7 | D14: Quản lý khuyến mãi cửa hàng | E14: Quản lý khuyến mãi cửa hàng | F14: ='Quản lý khuyến mãi cửa hàng'!F6 -> 65
C15: 8 | D15: Tìm kiếm | E15: Tìm kiếm | F15: ='Tìm kiếm'!F6 -> 48
C16: 9 | D16: Hồ sơ cá nhân | E16: Hồ sơ cá nhân | F16: ='Hồ sơ cá nhân'!F6 -> 81
C17: 10 | D17: Tương tác bài viết | E17: Tương tác bài viết | F17: ='Tương tác bài viết'!F6 -> 47
C18: Tổng số testcase của sprint 2 | F18: =SUM(F8:F17) -> 691

Sheet Quản lý yêu cầu hỗ trợ
A1: Project Name | B1: XÂY DỰNG HỆ THỐNG DISHNET - NỀN TẢNG MẠNG XÃ HỘI KINH DOANH ẨM THỰC
A2: Module Code | B2: Quản lý yêu cầu hỗ trợ
A3: Người kiểm tra | B3: Lê Văn Cường
B4: Hoàn thành | C4: Lỗi | D4: Chưa kiểm tra | E4: Bị chăn | F4: Tổng số trường hợp thử nghiệm
A5: Round 1 | B5: 57 | C5: 5 | D5: 0 | E5: 0 | F5: 62
A6: Round 2 | B6: 5 | C6: 0 | D6: 0 | E6: 0 | F6: 62
A23: Test Case ID | B23: Mô tả | C23: Hành động | D23: Điều kiện tiên quyết | E23: Kết quả mong đợi | F23: Kết quả thực tế | G23: Kết quả | I23: Kết quả | K23: Chú thích
G24: Vòng 1 | I24: Vòng 2
G25: Trạng thái | H25: Ngày kiểm tra | I25: Trạng thái | J25: Ngày kiểm tra
A26: GUI
A27: TC_SP_01 | B27: Kiểm tra menu “Yêu cầu hỗ trợ” | C27: 1. Truy cập hệ thống 2. Quan sát sidebar | D27: Admin đã đăng nhập | E27: Menu “Yêu cầu hỗ trợ” hiển thị và có thể click | F27: Menu “Yêu cầu hỗ trợ” hiển thị ở sidebar và có thể click sau khi admin đăng nhập. | G27: passed | H27: 46360
A28: TC_SP_02 | B28: Kiểm tra ô tìm kiếm | C28: 1. Quan sát ô tìm kiếm | D28: Trang hiển thị | E28: Hiển thị ô tìm kiếm với placeholder “Tìm kiếm tên mã, code…” | F28: Hệ thống cho phép nhập và hiển thị đúng nội dung trong ô tìm kiếm | G28: passed | H28: 46360
A29: TC_SP_03 | B29: Kiểm tra dropdown “Loại tài khoản” | C29: 1. Click dropdown | D29: Trang hiển thị | E29: Hiển thị danh sách lựa chọn (Người dùng, Cửa hàng, Nhà sáng tạo…) | F29: Dropdown "Loại tài khoản" hiển thị đầy đủ các lựa chọn | G29: passed | H29: 46360
A30: TC_SP_04 | B30: Kiểm tra dropdown “Trạng thái” | C30: 1. Click dropdown | D30: Trang hiển thị | E30: Hiển thị các trạng thái (Đã phản hồi, Chưa phản hồi…) | F30: Dropdown "Trạng thái" hiển thị đầy đủ các trạng thái | G30: passed | H30: 46360
A31: TC_SP_05 | B31: Kiểm tra bảng danh sách yêu cầu | C31: 1. Quan sát bảng | D31: Có dữ liệu | E31: Hiển thị các cột: Mã yêu cầu, Người gửi, Loại tài khoản, Chủ đề, Trạng thái, Thời gian | F31: Bảng danh sách hiển thị đúng các cột: ã yêu cầu, Người gửi, Loại tài khoản, Chủ đề, Trạng thái, Thời gian | G31: passed | H31: 46360
A32: TC_SP_06 | B32: Kiểm tra hiển thị trạng thái | C32: 1. Quan sát cột trạng thái | D32: Có dữ liệu | E32: Trạng thái hiển thị dạng label màu (Đã phản hồi/ Chưa phản hồi) | F32: Trạng thái hiển thị đúng label màu tương ứng (Đã phản hồi/Chưa phản hồi) | G32: passed | H32: 46360
A33: TC_SP_07 | B33: Kiểm tra nút “Xem” | C33: 1. Quan sát yêu cầu đã phản hồi | D33: Có dữ liệu | E33: Hiển thị nút “Xem” rõ ràng | F33: Nút "Xem" hiển thị rõ ràng tại các bản ghi đã phản hồi, trạng thái enable | G33: passed | H33: 46360
A34: TC_SP_08 | B34: Kiểm tra nút “Phản hồi” | C34: 1. Quan sát yêu cầu chưa phản hồi | D34: Có dữ liệu | E34: Hiển thị nút “Phản hồi” rõ ràng | F34: Nút "Phản hồi" hiển thị rõ ràng tại các bản ghi đã phản hồi, trạng thái enable | G34: passed | H34: 46360
A35: TC_SP_09 | B35: Kiểm tra phân trang | C35: 1. Quan sát cuối bảng | D35: Có nhiều dữ liệu | E35: Hiển thị pagination (1,2,3...) | F35: Thanh phân trang (1, 2, 3...) hiển thị ở cuối bảng khi có nhiều dữ liệu | G35: passed | H35: 46360
A36: TC_SP_10 | B36: Kiểm tra popup “Phản hồi” | C36: 1. Click “Phản hồi” | D36: Có yêu cầu chưa phản hồi | E36: Hiển thị popup “Phản hồi” | F36: Hệ thống hiển thị popup ở giữa trang khi click vào "Phản hồi" | G36: passed | H36: 46360
A37: TC_SP_11 | B37: Kiểm tra thông tin yêu cầu trong popup | C37: 1. Quan sát popup | D37: Popup mở | E37: Hiển thị popup ở giữa màn hình | F37: Popup phản hồi hiển thị đúng, căn giữa màn hình khi nhấn nút "Phản hồi" | G37: passed | H37: 46360
A38: TC_SP_12 | B38: Kiểm tra textarea “Nội dung chi tiết” | C38: 1. Quan sát nội dung | D38: Popup mở | E38: Nội dung hiển thị mặc định, không thể sửa | F38: Hiển thị nội dung chính xác nội dung mặc định, chỉ cho phép xem và không được sửa | G38: passed | H38: 46360
... A45: TC_SP_19 | B45: Kiểm tra responsive | C45: 1. Resize màn hình | D45: Trang đang mở | E45: Giao diện không bị vỡ layout | F45: Giao diện tự động co giãn theo kích thước màn hình, không bị vỡ layout | G45: passed | H45: 46360
A46: FUNCTION
A47: TC_SP_20 | B47: Xác nhận hiển thị đúng khi admin đăng nhập hợp lệ và truy cập thành công vào trang quản lý yêu cầu hỗ trợ | C47: 1. Đăng nhập tài khoản admin 2. Click đăng nhập 3. Truy cập trang quản lý yêu cầu | D47: Admin hợp lệ | E47: Hệ thống cho phép truy cập và hiển thị danh sách yêu cầu hỗ trợ đầy đủ | F47: Hệ thống truy cập đúng và hiển thị đầy đủ danh sách yêu cầu | G47: passed | H47: 46360
A48: TC_SP_21 | B48: Xác nhận chặn thành công các truy cập khi vào trực tiếp mà không qua đăng nhập | C48: 1. Truy cập URL trang quản lý 2. Không đăng nhập | D48: Chưa đăng nhập | E48: Hệ thống chuyển về trang đăng nhập và hiển thị cảnh báo | F48: Hệ thống chặn truy cập trực tiếp, chuyển về trang login và cảnh báo khi chưa đăng nhập | G48: passed | H48: 46360
A49: TC_SP_22 | B49: Xác nhận hiển thị lỗi khi người dùng không có quyền admin truy cập trang quản lý yêu cầu | C49: 1. Đăng nhập user thường 2. Truy cập trang quản lý | D49: User thường | E49: Hệ thống từ chối truy cập vào hệ thộng | F49: Hệ thống từ chối truy cập và báo lỗi khi tài khoản không phải admin | G49: passed | H49: 46360
A50: TC_SP_23 | B50: Xác nhận hiển thị đúng kết quả khi admin tìm kiếm với mã yêu cầu hợp lệ | C50: 1. Nhập mã yêu cầu 2. Nhấn Enter | D50: Có dữ liệu | E50: Hệ thống hiển thị đúng kết quả tìm kiếm yêu cầu theo mã | F50: Kết quả tìm kiếm trả về đúng bản ghi khớp với mã yêu cầu đã nhập | G50: passed | H50: 46360
A51: TC_SP_24 | B51: Xác nhận hiển thị đúng khi admin tìm kiếm với mã yêu cầu không tồn tại | C51: 1. Nhập mã không tồn tại 2. Enter | D51: N/A | E51: Hệ thống hiển thị danh sách rỗng | F51: Hệ thống hiển thị danh sách rỗng khi nhập mã yêu cầu không tồn tại. | G51: passed | H51: 46360
A52: TC_SP_25 | B52: Xác nhận hiển thị đúng kết quả khi admin tìm kiếm theo tên người gửi yêu cầu hợp lệ | C52: 1. Nhập tên người dùng 2. Enter | D52: Có dữ liệu | E52: Hệ thống hiển thị đúng kết quả tìm kiếm yêu cầu theo tên | F52: Kết quả tìm kiếm trả về đúng danh sách theo tên người gửi | G52: passed | H52: 46360
A53: TC_SP_26 | B53: Xác nhận hiển thị đúng kết quả khi admin tìm kiếm với từ khóa có cả chữ hoa và chữ thường | C53: 1. Nhập chữ hoa/thường 2. Enter | D53: Có dữ liệu | E53: Hệ thống tự động xử lý các ký tự đúng format và trả về kết quả tương ứng | F53: Hệ thống tự động xử lý định dạng và trả kết quả đúng dù nhập chữ hoa/thường | G53: passed | H53: 46360
A54: TC_SP_27 | B54: Xác nhận hiển thị đúng kết quả khi admin tìm kiếm với từ khóa có dấu và không dấu | C54: 1. Nhập từ khóa có dấu 2. Nhập không dấu 3. Enter | D54: Có dữ liệu | E54: Hệ thống tự động rà soát và hiển thị kết quả liên quan | F54: Kết quả tìm kiếm trả về chính xác dù nhập từ khóa có dấu hoặc không dấu | G54: passed | H54: 46360
A55: TC_SP_28 | B55: Xác nhận hệ thống xử lý đúng dữ liệu khi admin nhập ký tự đặc biệt vào ô tìm kiếm | C55: 1. Nhập ký tự đặc biệt 2. Enter | D55: N/A | E55: Không crash, hiển thị kết quả hợp lệ hoặc rỗng | F55: Hệ thống không bị crash, hiển thị kết quả hợp lệ hoặc rỗng khi nhập ký tự đặc biệt | G55: passed | H55: 46360
A56: TC_SP_29 | B56: Xác nhận hệ thống xử lý đúng khi admin nhập dữ liệu tìm kiếm >30 ký tự | C56: 1. Nhập chuỗi dài >30 ký tự 2. Enter | D56: N/A | E56: Không crash, hệ thống xử lý và giới hạn dữ liệu | F56: Hệ thống giới hạn ký tự và xử lý ổn định khi nhập từ khóa > 30 ký tự | G56: passed | H56: 46360
A57: TC_SP_30 | B57: Xác nhận hệ thống xử lý đúng khi admin nhập từ khóa tìm kiếm có chứa khoảng trắng đầu/cuối | C57: 1. Nhập từ khóa có khoảng trắng 2. Enter | D57: N/A | E57: Hệ thống tự động trim và trả kết quả đúng | F57: Hệ thống không tự động trim khoảng trắng đầu/cuối, dẫn đến không tìm thấy kết quả | G57: failed | H57: 46360 | I57: passed | J57: 16/04/26
A58: TC_SP_31 | B58: Xác nhận hệ thống xử lý đúng khi người dùng chỉ nhập ký tự trắng | C58: 1. Nhập khoảng trắng 2. Enter | D58: N/A | E58: Hệ thống không hiển thị danh sách tìm kiếm | F58: Hệ thống xử lý đúng khi chỉ nhập toàn khoảng trắng vào ô tìm kiếm | G58: passed | H58: 46360
A59: TC_SP_32 | B59: Xác nhận hệ thống hiển thị đúng khi admin xóa từ khóa tìm kiếm | C59: 1. Nhập từ khóa 2. Xóa nội dung | D59: N/A | E59: Hệ thống hiển thị lại danh sách ban đầu | F59: Danh sách ban đầu hiển thị lại đầy đủ sau khi xóa từ khóa tìm kiếm | G59: passed | H59: 46360
A60: TC_SP_33 | B60: Xác nhận hệ thống xử lý đúng khi admin nhấn Enter liên tục | C60: 1. Nhập từ khóa 2. Nhấn Enter nhiều lần | D60: N/A | E60: Hệ thống chỉ xử lý request đầu tiên | F60: Hệ thống chỉ xử lý request đầu tiên khi nhấn Enter liên tục, không bị treo | G60: passed | H60: 46360
A61: TC_SP_34 | B61: Xác nhận hệ thống hiển thị đúng kết quả khi người dùng copy–paste từ khóa | C61: 1. Paste từ khóa 2. Enter | D61: N/A | E61: Hệ thống nhận input và trả kết quả đúng | F61: Hệ thống nhận diện nội dung copy-paste và trả kết quả tìm kiếm đúng | G61: passed | H61: 46360
A62: TC_SP_35 | B62: Xác nhận đúng kết quả khi admin lọc dữ liệu theo loại tài khoản | C62: 1. Chọn loại tài khoản 2. Áp dụng | D62: Có dữ liệu | E62: Hiển thị danh sách đã lọc đúng theo loại tài khoản | F62: Hệ thống trả về danh sách được lọc chính xác theo loại tài khoản đã chọn | G62: passed | H62: 46360
...

Sheet Quản lý báo cáo khiếu nại
A1: Project Name | B1: XÂY DỰNG HỆ THỐNG DISHNET - NỀN TẢNG MẠNG XÃ HỘI KINH DOANH ẨM THỰC
A2: Module Code | B2: Quản lý báo cáo/khiếu nại
A3: Người kiểm tra | B3: Trần Thị Mai Yên
B4: Hoàn thành | C4: Lỗi | D4: Chưa kiểm tra | E4: Bị chăn | F4: Tổng số trường hợp thử nghiệm
A5: Round 1 | B5: =COUNTIF(G27:G993,"passed") -> 61 | C5: =COUNTIF(G27:G993,"failed") -> 10 | D5: =COUNTIF(G27:G993,"untest") -> 0 | E5: =COUNTIF(G27:G993,"blocked") -> 0 | F5: =COUNTIF(A23:A989, "TC*") -> 71
A6: Round 2 | B6: =COUNTIF(I27:I994,"passed") -> 10 | C6: =COUNTIF(I27:I993,"failed") -> 0 | D6: =COUNTIF(G27:G993,"untest") -> 0 | E6: =COUNTIF(G27:G993,"blocked") -> 0 | F6: =COUNTIF(A24:A990, "TC*") -> 71
A23: Test Case ID | B23: Mô tả | C23: Hành động | D23: Điều kiện tiên quyết | E23: Kết quả mong đợi | F23: Kết quả thực tế | G23: Kết quả | I23: Kết quả | K23: Chú thích
G24: Vòng 1 | I24: Vòng 2
G25: Trạng thái | H25: Ngày kiểm tra | I25: Trạng thái | J25: Ngày kiểm tra
A26: GUI
A27: TC_RP_01 | B27: Kiểm tra menu “Báo cáo / Khiếu nại” | C27: 1. Truy cập hệ thống 2. Quan sát sidebar | D27: Admin đã đăng nhập | E27: Menu “Báo cáo / Khiếu nại” hiển thị và có thể click | F27: Menu “Báo cáo/Khiếu nại” hiển thị đúng và có thể click truy cập bình thường | G27: passed | H27: 46124
A28: TC_RP_02 | B28: Kiểm tra danh sách báo cáo | C28: 1. Quan sát danh sách | D28: Có dữ liệu | E28: Hiển thị danh sách báo cáo (Mã báo cáo, người báo cáo, nội dung, trạng thái) | F28: Danh sách báo cáo hiển thị đầy đủ thông tin (mã, người báo cáo, nội dung, trạng thái) | G28: passed | H28: 46124
A29: TC_RP_03 | B29: Kiểm tra hiển thị trạng thái báo cáo | C29: 1. Quan sát label trạng thái | D29: Có dữ liệu | E29: Hiển thị trạng thái (Chờ xử lý / Đã xử lý) với màu sắc phân biệt | F29: Trạng thái báo cáo hiển thị đúng (Chờ xử lý/Đã xử lý) và có màu sắc phân biệt | G29: passed | H29: 46124
A30: TC_RP_04 | B30: Kiểm tra nút “Xử lý” | C30: 1. Quan sát dòng chưa xử lý | D30: Có báo cáo chưa xử lý | E30: Hiển thị nút “Xử lý” rõ ràng | F30: Nút “Xử lý” hiển thị rõ ràng với các báo cáo chưa xử lý | G30: passed | H30: 46124
A31: TC_RP_05 | B31: Kiểm tra nút “Xem chi tiết báo cáo” | C31: 1. Quan sát dòng đã xử lý | D31: Có báo cáo đã xử lý | E31: Chuyển màn hình đến trang chi tiết | F31: Click “Xem chi tiết” điều hướng đúng đến trang chi tiết báo cáo | G31: passed | H31: 46124
A32: TC_RP_06 | B32: Kiểm tra ô tìm kiếm | C32: 1. Quan sát ô tìm kiếm | D32: Trang hiển thị | E32: Hiển thị ô tìm kiếm với placeholder phù hợp | F32: Ô tìm kiếm hiển thị đúng với placeholder phù hợp | G32: passed | H32: 46124
A33: TC_RP_07 | B33: Kiểm tra nhập ô tìm kiếm | C33: 1. Click ô tìm kiếm 2. Nhập nội dung | D33: Trang hiển thị | E33: Cho phép nhập và hiển thị đúng nội dung | F33: Nhập nội dung vào ô tìm kiếm hiển thị đúng ký tự đã nhập | G33: passed | H33: 46124
A34: TC_RP_08 | B34: Kiểm tra card báo cáo | C34: 1. Quan sát từng card | D34: Có dữ liệu | E34: Hiển thị đầy đủ: mã báo cáo, người gửi, thời gian, nội dung | F34: Card báo cáo hiển thị đầy đủ thông tin (mã, người gửi, thời gian, nội dung) | G34: passed | H34: 46124
A35: TC_RP_09 | B35: Kiểm tra hiển thị hình ảnh/video bị báo cáo | C35: 1. Quan sát nội dung | D35: Có dữ liệu media | E35: Hiển thị thumbnail hoặc preview nội dung | F35: Hình ảnh/video hiển thị dạng thumbnail/preview đúng | G35: passed | H35: 46124
A36: TC_RP_10 | B36: Kiểm tra phân trang | C36: 1. Quan sát cuối danh sách | D36: Có nhiều dữ liệu | E36: Hiển thị pagination (1,2,3...) | F36: Phân trang hiển thị đúng (1,2,3,...) và hoạt động bình thường | G36: passed | H36: 46124
A37: TC_RP_11 | B37: Kiểm tra màn hình “Xử lý báo cáo” | C37: 1. Click “Xử lý” | D37: Có báo cáo chưa xử lý | E37: Điều hướng sang màn hình xử lý | F37: Click “Xử lý” điều hướng đúng sang màn hình xử lý báo cáo | G37: passed | H37: 46124
A38: TC_RP_12 | B38: Kiểm tra section “Thông tin báo cáo” | C38: 1. Quan sát panel | D38: Trang xử lý mở | E38: Hiển thị đầy đủ thông tin: mã, người báo cáo, thời gian | F38: Section “Thông tin báo cáo” hiển thị đầy đủ và chính xác | G38: passed | H38: 46124
... A48: TC_RP_22 | B48: Kiểm tra responsive | C48: 1. Resize màn hình | D48: Trang đang mở | E48: Giao diện không bị vỡ layout | F48: Giao diện responsive tốt, không vỡ layout khi resize | G48: passed | H48: 46124
A49: FUNCTION
A50: TC_RP_23 | B50: Xác nhận hiển thị đúng khi admin đăng nhập hợp lệ và truy cập trang quản lý báo cáo | C50: 1. Nhập tài khoản admin 2. Click đăng nhập 3. Truy cập trang quản lý báo cáo | D50: Admin hợp lệ | E50: Hệ thống cho phép truy cập và hiển thị danh sách báo cáo/khiếu nại đầy đủ | F50: Admin đăng nhập hợp lệ và truy cập trang quản lý báo cáo thành công, danh sách báo cáo/khiếu nại hiển thị đầy đủ | G50: passed | H50: 46124
A51: TC_RP_24 | B51: Xác nhận chặn thành công các truy cập khi vào trực tiếp mà không qua đăng nhập | C51: 1. Truy cập URL 2. Không đăng nhập | D51: Chưa đăng nhập | E51: Hệ thống chuyển về trang đăng nhập và hiển thị cảnh báo | F51: Truy cập khi chưa đăng nhập bị chuyển về trang login và hiển thị cảnh báo | G51: passed | H51: 46124
A52: TC_RP_25 | B52: Xác nhận hiển thị lỗi khi người dùng không phải admin truy cập trang quản lý báo cáo khiếu nại | C52: 1. Đăng nhập user thường 2. Truy cập trang | D52: User thường | E52: Hệ thống từ chối truy cập và hiển thị thông báo | F52: User không phải admin bị từ chối truy cập và hiển thị thông báo | G52: passed | H52: 46124
A53: TC_RP_26 | B53: Hệ thống ghi nhận lịch sử xử lý khi admin thực hiện các thao tác lưu/bỏ qua báo cáo | C53: 1. Admin chọn một yêu cầu cần xử lý. 2. Thực hiện một trong hai thao tác: Gửi phản hồi/ bỏ qua 3. Truy cập vào phần “Hoạt động xử lý”. 4. Kiểm tra bản ghi vừa được tạo. | D53: Có dữ liệu | E53: Hệ thống tạo một bản ghi mới trong phần “Hoạt động xử lý” ngay sau mỗi thao tác, bao gồm đầy đủ các thông tin: ID Admin thực hiện, Hành động, và Thời gian chính xác | F53: Không tạo bản ghi trong lịch sử xử lý sau khi admin thực hiện thao tác | G53: failed | H53: 46124 | I53: passed | J53: 46097
A54: TC_RP_27 | B54: Xác nhận hiển thị đúng khi admin tìm kiếm báo cáo theo từ khóa hợp lệ | C54: 1. Nhập từ khóa 2. Nhấn Enter | D54: Có dữ liệu | E54: Hệ thống hiển thị danh sách báo cáo/khiếu nại phù hợp từ khóa | F54: Tìm kiếm theo từ khóa hợp lệ trả về đúng danh sách kết quả | G54: passed | H54: 46124
A55: TC_RP_28 | B55: Xác nhận hiển thị đúng khi admin tìm kiếm báo cáo với từ khóa không tồn tại | C55: 1. Nhập từ khóa không tồn tại 2. Enter | D55: N/A | E55: Hiển thị danh sách rỗng | F55: Tìm kiếm với từ khóa không tồn tại hiển thị danh sách rỗng | G55: passed | H55: 46124
A56: TC_RP_29 | B56: Xác nhận hiển thị đúng khi admin nhập ký tự đặc biệt vào ô tìm kiếm | C56: 1. Nhập ký tự đặc biệt 2. Enter | D56: N/A | E56: Không crash, hiển thị kết quả hợp lệ hoặc rỗng | F56: Nhập ký tự đặc biệt không gây crash, hệ thống trả kết quả hợp lệ hoặc rỗng | G56: passed | H56: 46124
A57: TC_RP_30 | B57: Xác nhận hệ thống trim dữ liệu khi nhập khoảng trắng đầu/cuối vào ô tìm kiếm | C57: 1. Nhập từ khóa có khoảng trắng 2. Enter | D57: N/A | E57: Hệ thống loại bỏ khoảng trắng và trả kết quả đúng | F57: Nhập từ khóa có khoảng trắng đầu/cuối được trim và trả kết quả đúng | G57: passed | H57: 46124
A58: TC_RP_31 | B58: Xác nhận hiển thị đúng khi chỉ nhập khoảng trắng vào ô tìm kiếm | C58: 1. Nhập khoảng trắng 2. Enter | D58: N/A | E58: Hệ thống hiển thị danh sách kết quả =0 | F58: Nhập chỉ khoảng trắng hiển thị kết quả rỗng | G58: passed | H58: 46124
A59: TC_RP_32 | B59: Xác nhận hiển thị đúng khi admin xóa từ khóa tìm kiếm | C59: 1. Nhập từ khóa 2. Xóa nội dung | D59: N/A | E59: Hiển thị danh sách ban đầu | F59: Xóa từ khóa tìm kiếm hiển thị lại danh sách ban đầu | G59: passed | H59: 46124
A60: TC_RP_33 | B60: Xác nhận hệ thống chỉ xử lý 1 lần khi nhấn Enter liên tục | C60: 1. Nhập từ khóa 2. Nhấn Enter nhiều lần | D60: N/A | E60: Chỉ xử lý 1 request đầu tiên | F60: Hệ thống chỉ xử lý đúng 1 request đầu tiên | G60: passed | H60: 46124
A61: TC_RP_34 | B61: Xác nhận hiển thị đúng khi copy-paste từ khóa | C61: 1. Paste từ khóa 2. Enter | D61: N/A | E61: Hệ thống nhận input và trả kết quả đúng | F61: Copy-paste từ khóa vào ô tìm kiếm vẫn trả kết quả đúng | G61: passed | H61: 46124
A62: TC_RP_35 | B62: Xác nhận hệ thống hiển thị đầy đủ và chính xác trường thông tin chi tiết của một báo cáo/khiếu nại | C62: 1. Quan sát danh sách | D62: Có dữ liệu | E62: Danh sách đầy đủ các trường: mã báo cáo, người báo cáo, thời gian tạo báo cáo, trạng thái báo cáo, nội dung bị báo cáo, thời gian, trạng thái | F62: Thông tin báo cáo hiển thị đầy đủ và chính xác các trường | G62: passed | H62: 46124
A63: TC_RP_36 | B63: Xác nhận hiển thị đúng khi không có dữ liệu báo cáo/khiếu nại | C63: 1. Truy cập khi không có báo cáo | D63: N/A | E63: Hiển thị danh sách rỗng | F63: Khi không có dữ liệu hiển thị danh sách rỗng đúng | G63: passed | H63: 46124
A64: TC_RP_37 | B64: Xác nhận hiển thị đúng khi load lại trang báo cáo/khiếu nại | C64: 1. Truy cập trang | D64: Có dữ liệu | E64: Dữ liệu load đúng và đầy đủ | F64: Reload trang dữ liệu vẫn được load đúng và đầy đủ | G64: passed | H64: 46124
A65: TC_RP_38 | B65: Xác nhận hệ thống hiển thị đúng màn hình xử lý khi admin click vào nút “Xử lý báo cáo” | C65: 1. Truy cập danh sách báo cáo2. Click "Xử lý" | D65: Có báo cáo | E65: Hệ thống chuyển sang màn hình xử lý báo cáo tương ứng | F65: Hệ thống chuyển hướng đúng sang màn hình xử lý báo cáo tương ứng khi admin click vào nút “Xử lý” | G65: passed | H65: 46124
...

Sheet Tổng quan cửa hàng
A1: Project Name | B1: XÂY DỰNG HỆ THỐNG DISHNET - NỀN TẢNG MẠNG XÃ HỘI KINH DOANH ẨM THỰC
A2: Module Code | B2: Tổng quan cửa hàng
A3: Người kiểm tra | B3: Huỳnh Thị Vy
B4: Hoàn thành | C4: Lỗi | D4: Chưa kiểm tra | E4: Bị chăn | F4: Tổng số trường hợp thử nghiệm
A5: Round 1 | B5: 61 | C5: 14 | D5: 0 | E5: 0 | F5: 75
A6: Round 2 | B6: 14 | C6: 0 | D6: 0 | E6: 0 | F6: 75
A23: Test Case ID | B23: Mô tả | C23: Hành động | D23: Điều kiện tiên quyết | E23: Kết quả mong đợi | F23: Kết quả thực tế | G23: Kết quả | I23: Kết quả | K23: Chú thích
G24: Vòng 1 | I24: Vòng 2
G25: Trạng thái | H25: Ngày kiểm tra | I25: Trạng thái | J25: Ngày kiểm tra
A26: GUI
A27: TC_SHOP_01 | B27: Kiểm tra hiển thị trạng thái “Đang nhận đơn” | C27: 1. Truy cập trang tổng quan | D27: Chủ cửa hàng đã đăng nhập | E27: Hiển thị toggle “Đang nhận đơn” ON/OFF | F27: Hệ thống hiển thị toggle “Đang nhận đơn” ở trạng thái ON/OFF rõ ràng | G27: passed | H27: 46360
A28: TC_SHOP_02 | B28: Kiểm tra bật/tắt trạng thái nhận đơn | C28: 1. Click toggle | D28: Trang tổng quan | E28: Toggle chuyển trạng thái ON/OFF | F28: Khi click, toggle chuyển trạng thái ON/OFF thành công | G28: passed | H28: 46360
A29: TC_SHOP_03 | B29: Kiểm tra dropdown chọn cửa hàng | C29: 1. Click dropdown | D29: Có nhiều cửa hàng | E29: Hiển thị danh sách cửa hàng | F29: Danh sách các cửa hàng hiển thị đầy đủ khi click vào dropdown | G29: passed | H29: 46360
A30: TC_SHOP_04 | B30: Kiểm tra thông tin cửa hàng | C30: 1. Quan sát card thông tin | D30: Trang load thành công | E30: Hiển thị tên, địa chỉ, giờ mở cửa, rating | F30: Các thông tin: tên, địa chỉ, giờ mở cửa và rating hiển thị chính xác trên card | G30: passed | H30: 46360
A31: TC_SHOP_05 | B31: Kiểm tra hiển thị rating | C31: 1. Quan sát điểm đánh giá | D31: Có dữ liệu | E31: Hiển thị điểm rating | F31: Điểm rating của cửa hàng được hiển thị đúng dữ liệu | G31: passed | H31: 46360
A32: TC_SHOP_06 | B32: Kiểm tra nút “Đổi ảnh đại diện” | C32: 1. Quan sát button | D32: Trang hiển thị | E32: Hiển thị nút rõ ràng | F32: Nút “Đổi ảnh đại diện” hiển thị rõ ràng trên giao diện | G32: passed | H32: 46360
A33: TC_SHOP_07 | B33: Kiểm tra nút “Thêm món” | C33: 1. Quan sát button | D33: Trang hiển thị | E33: Hiển thị nút “Thêm món” | F33: Nút “Thêm món” hiển thị đúng vị trí và rõ ràng | G33: passed | H33: 46360
A34: TC_SHOP_08 | B34: Kiểm tra nút “Tạo khuyến mãi” | C34: 1. Quan sát button | D34: Trang hiển thị | E34: Hiển thị nút “Tạo khuyến mãi” | F34: Nút “Tạo khuyến mãi” hiển thị đúng vị trí và rõ ràng | G34: passed | H34: 46360
A35: TC_SHOP_09 | B35: Kiểm tra nút “Tạm nghỉ bán” | C35: 1. Quan sát button | D35: Trang hiển thị | E35: Hiển thị nút rõ ràng | F35: Nút “Tạm nghỉ bán” hiển thị đúng vị trí và rõ ràng trên trang | G35: passed | H35: 46360
A36: TC_SHOP_10 | B36: Kiểm tra phần “Quản lý đơn hàng” | C36: 1. Quan sát section | D36: Có dữ liệu | E36: Hiển thị % trạng thái đơn (hoàn thành, hủy, đang giao…) | F36: Hiển thị đầy đủ % các trạng thái đơn (hoàn thành, hủy, đang giao...) | G36: passed | H36: 46360
A37: TC_SHOP_11 | B37: Kiểm tra màu sắc trạng thái đơn | C37: 1. Quan sát các label | D37: Có dữ liệu | E37: Mỗi trạng thái có màu khác nhau | F37: Mỗi trạng thái đơn hàng (hủy, giao,...) được phân biệt bằng các màu sắc khác nhau | G37: passed | H37: 46360
A38: TC_SHOP_12 | B38: Kiểm tra phần “Top món bán chạy” | C38: 1. Quan sát section | D38: Có dữ liệu | E38: Hiển thị danh sách món + số lượt bán | F38: Danh sách các món bán chạy cùng số lượt bán tương ứng được hiển thị chính xác | G38: passed | H38: 46360
... A46: TC_SHOP_20 | B46: Kiểm tra layout tổng thể | C46: 1. Quan sát toàn trang | D46: Trang load thành công | E46: UI hiển thị đúng bố cục | F46: Giao diện người dùng (UI) hiển thị đúng bố cục, không bị lỗi trình bày | G46: passed | H46: 46360
A47: FUNCTION
A48: TC_SHOP_21 | B48: Xác nhận hiển thị đúng khi chủ cửa hàng đăng nhập hợp lệ và truy cập trang quản lý | C48: 1. Đăng nhập tài khoản cửa hàng 2. Click đăng nhập 3. Truy cập dashboard | D48: Tài khoản hợp lệ | E48: Hệ thống đăng nhập thành công và hiển thị đầy đủ thông tin tổng quan cửa hàng | F48: Hệ thống đăng nhập thành công và hiển thị đầy đủ thông tin tổng quan cửa hàng | G48: passed | H48: 46360
A49: TC_SHOP_22 | B49: Xác nhận hiển thị đúng khi chủ cửa hàng bật trạng thái nhận đơn | C49: 1. Click bật trạng thái ON | D49: N/A | E49: Trạng thái cửa hàng chuyển sang ON, cho phép nhận đơn | F49: Hệ thống cho phép nhận đơn hàng mới khi trạng thái cửa hàng chuyển sang ON | G49: passed | H49: 46360
A50: TC_SHOP_23 | B50: Xác nhận hiển thị đúng khi chủ cửa hàng tắt trạng thái nhận đơn | C50: 1. Click chuyển OFF | D50: N/A | E50: Trạng thái OFF, không nhận đơn | F50: Hệ thống không nhận đơn khi trạng thái cửa chuyển sang OFF | G50: passed | H50: 46360
A51: TC_SHOP_24 | B51: Xác nhận hệ thống không crash khi đổi trạng thái liên tục | C51: 1. Click ON/OFF liên tục | D51: N/A | E51: Không crash, trạng thái cập nhật chính xác | F51: Hệ thống hoạt động ổn định, không crash; trạng thái được cập nhật chính xác sau các lần chuyển đổi | G51: passed | H51: 46360
A52: TC_SHOP_25 | B52: Xác nhận hiển thị đúng rating trung bình cửa hàng khi chủ cửa hàng truy cập trang tổng quan cửa hàng | C52: 1. Kiểm tra rating | D52: Có dữ liệu | E52: Hiển thị đúng giá trị rating | F52: Giá trị rating hiển thị đúng với dữ liệu thực tế của cửa hàng | G52: passed | H52: 46360
A53: TC_SHOP_26 | B53: Xác nhận hệ thống hiển thị đúng trạng thái hoạt động của cửa hàng khi chủ cửa hàng truy cập tổng quan cửa hàng | C53: 1. Kiểm tra trạng thái | D53: N/A | E53: Hiển thị đúng (Đang mở/Tạm nghỉ) | F53: Hệ thống hiển thị đúng trạng thái hiện tại của cửa hàng (Đang mở hoặc Tạm nghỉ) | G53: passed | H53: 46360
A54: TC_SHOP_27 | B54: Xác nhận hệ thống hiển thị đúng doanh thu hôm nay khi có dữ liệu phát sinh trong ngày | C54: 1. Kiểm tra doanh thu | D54: Có đơn hàng | E54: Hiển thị đúng tổng doanh thu của cửa hàng hôm nay | F54: Tổng doanh thu hiển thị chính xác dựa trên các đơn hàng phát sinh trong ngày | G54: passed | H54: 46360
A55: TC_SHOP_28 | B55: Xác nhận hệ thống hiển thị đúng số đơn hàng hôm nay khi có đơn đặt hàng | C55: 1. Kiểm tra đơn hàng | D55: Có dữ liệu | E55: Hiển thị đúng tổng số đơn đặt hàng hôm nay | F55: Hệ thống hiển thị đúng tổng số lượng đơn đặt hàng thành công trong ngày | G55: passed | H55: 46360
A56: TC_SHOP_29 | B56: Xác nhận hệ thống hiển thị đúng số đơn hủy hôm nay khi có đơn bị hủy trong ngày | C56: 1. Kiểm tra đơn hủy | D56: Có dữ liệu | E56: Hiển thị đúng tổng số đơn hủy hôm nay | F56: Hệ thống hiển thị đúng tổng số lượng đơn hàng bị hủy trong ngày | G56: passed | H56: 46360
A57: TC_SHOP_30 | B57: Xác nhận hệ thống hiển thị đúng khi không có dữ liệu phát sinh | C57: 1. Truy cập khi không có đơn | D57: N/A | E57: Hiển thị giá trị = 0 | F57: Các giá trị doanh thu, số đơn hàng, đơn hủy đều hiển thị bằng 0 | G57: passed | H57: 46360
A58: TC_SHOP_31 | B58: Xác nhận hệ thống hiển thị số liệu doanh thu, đơn hàng, đơn hủy đúng với dữ liệu thực tế phát sinh trong ngày | C58: 1. So sánh dữ liệu | D58: Có database | E58: Số liệu hiển thị đúng, phải nhảy realtime khi có đơn hàng mới hoặc đơn bị hủy | F58: Số liệu hiển thị không chính xác, không cập nhật realtime khi có đơn hàng mới/đơn bị hủy | G58: failed | H58: 46360 | I58: passed | J58: 16/04/26
A59: TC_SHOP_32 | B59: Xác nhận hiển thị đúng khi chủ cửa hàng click đổi ảnh đại diện | C59: 1. Click "Đổi ảnh đại diện" | D59: N/A | E59: Chuyển màn hình đến trang đổi ảnh đại diện | F59: Hệ thống chuyển hướng thành công đến màn hình thay đổi ảnh đại diện | G59: passed | H59: 46360
A60: TC_SHOP_33 | B60: Xác nhận hệ thống hiển thị đúng khi chủ cửa hàng upload ảnh đại diện thành công | C60: 1. Click đổi ảnh 2. Upload ảnh | D60: File hợp lệ | E60: Upload thành công và hiển thị ảnh | F60: Hệ thống cho phép upload thành công và hiển thị ảnh đại diện mới | G60: passed | H60: 46360
A61: TC_SHOP_34 | B61: Xác nhận hệ thống hiển thị đúng khi chủ cửa hàng click thêm món | C61: 1. Click "Thêm món" | D61: N/A | E61: Hiển thị popup thêm món | F61: Popup thêm món mới hiển thị đúng khi người dùng click vào nút "Thêm món" | G61: passed | H61: 46360
A62: TC_SHOP_35 | B62: Xác nhận hệ thống hiển thị đúng khi chủ cửa hàng click tạo khuyến mãi | C62: 1. Click "Tạo mã khuyến mãi" | D62: N/A | E62: Hiển thị popup tạo mã khuyến mãi | F62: Popup tạo mã khuyến mãi hiển thị đúng khi người dùng click vào nút | G62: passed | H62: 46360
A63: TC_SHOP_36 | B63: Xác nhận hệ thống hiển thị đúng trạng thái khi click tạm nghỉ bán | C63: 1. Click "Tạm nghỉ" | D63: N/A | E63: Trạng thái chuyển OFF | F63: Trạng thái của cửa hàng chuyển sang OFF ngay sau khi click "Tạm nghĩ bán", cửa hàng không nhận thêm đơn mới | G63: passed | H63: 46360
...

Sheet Quản lý doanh thu cửa hàng
A1: Project Name | B1: XÂY DỰNG HỆ THỐNG DISHNET - NỀN TẢNG MẠNG XÃ HỘI KINH DOANH ẨM THỰC
A2: Module Code | B2: Quản lý doanh thu cửa hàng
A3: Người kiểm tra | B3: Phan Thị Lệ Thi
B4: Hoàn thành | C4: Lỗi | D4: Chưa kiểm tra | E4: Bị chăn | F4: Tổng số trường hợp thử nghiệm
A5: Round 1 | B5: =COUNTIF(G27:G998,"passed") -> 63 | C5: =COUNTIF(G27:G998,"failed") -> 6 | D5: =COUNTIF(G27:G998,"untest") -> 0 | E5: =COUNTIF(G27:G998,"blocked") -> 0 | F5: =COUNTIF(A23:A994, "TC*") -> 69
A6: Round 2 | B6: =COUNTIF(I27:I999,"passed") -> 6 | C6: =COUNTIF(I27:I998,"failed") -> 0 | D6: =COUNTIF(G27:G998,"untest") -> 0 | E6: =COUNTIF(G27:G998,"blocked") -> 0 | F6: =COUNTIF(A24:A995, "TC*") -> 69
A23: Test Case ID | B23: Mô tả | C23: Hành động | D23: Điều kiện tiên quyết | E23: Kết quả mong đợi | F23: Kết quả thực tế | G23: Kết quả | I23: Kết quả | K23: Chú thích
G24: Vòng 1 | I24: Vòng 2
G25: Trạng thái | H25: Ngày kiểm tra | I25: Trạng thái | J25: Ngày kiểm tra
A26: GUI
A27: TC_REV_01 | B27: Kiểm tra menu “Quản lý doanh thu” | C27: Click menu bên trái | D27: Đã đăng nhập tài khoản cửa hàng | E27: Menu được highlight, chuyển đúng trang | F27: Khi click menu “Quản lý doanh thu”, menu được highlight và điều hướng đúng trang. | G27: passed | H27: 46124
A28: TC_REV_02 | B28: Kiểm tra card “Hôm nay” | C28: Quan sát | D28: Có dữ liệu | E28: Hiển thị số tiền, format đúng (VNĐ) | F28: Card “Hôm nay” hiển thị số tiền chính xác, đúng định dạng VND. | G28: passed | H28: 46124
A29: TC_REV_03 | B29: Kiểm tra card “Thực nhận” | C29: Quan sát | D29: Có dữ liệu | E29: Hiển thị số tiền + % tăng/giảm | F29: Card “Thực nhận” hiển thị đúng số tiền và % tăng/giảm. | G29: passed | H29: 46124
A30: TC_REV_04 | B30: Kiểm tra card “Tổng đơn hàng” | C30: Quan sát | D30: Có dữ liệu | E30: Hiển thị số lượng đơn | F30: Card “Tổng đơn hàng” hiển thị đúng số lượng đơn. | G30: passed | H30: 46124
A31: TC_REV_05 | B31: Kiểm tra card “Tỷ lệ hủy/hoàn” | C31: Quan sát | D31: Có dữ liệu | E31: Hiển thị % đúng format | F31: Card “Tỷ lệ hủy/hoàn” hiển thị đúng % và đúng format. | G31: passed | H31: 46124
A32: TC_REV_06 | B32: Kiểm tra icon refresh ở card | C32: Click icon | D32: Trang đang mở | E32: Icon hiển thị, có thể click | F32: Icon refresh hiển thị đúng, click hoạt động bình thường. | G32: passed | H32: 46124
A33: TC_REV_07 | B33: Kiểm tra biểu đồ “Doanh thu 30 ngày” | C33: Quan sát | D33: Có dữ liệu | E33: Biểu đồ hiển thị đúng layout | F33: Biểu đồ “Doanh thu 30 ngày” hiển thị đúng dữ liệu và layout. | G33: passed | H33: 46124
A34: TC_REV_08 | B34: Kiểm tra trục thời gian biểu đồ | C34: Quan sát | D34: Có dữ liệu | E34: Hiển thị ngày/tháng rõ ràng | F34: Trục thời gian hiển thị rõ ràng ngày/tháng đúng định dạng. | G34: passed | H34: 46124
A35: TC_REV_09 | B35: Kiểm tra biểu đồ “Doanh thu theo món” | C35: Quan sát | D35: Có dữ liệu | E35: Biểu đồ tròn hiển thị đầy đủ | F35: Biểu đồ “Doanh thu theo món” hiển thị đầy đủ dữ liệu. | G35: passed | H35: 46124
A36: TC_REV_10 | B36: Kiểm tra dropdown “Theo thời gian” | C36: Click dropdown | D36: Trang hiển thị | E36: Hiển thị danh sách chọn | F36: Dropdown “Theo thời gian” hiển thị đầy đủ danh sách chọn. | G36: passed | H36: 46124
A37: TC_REV_11 | B37: Kiểm tra dropdown “Trạng thái đơn” | C37: Click dropdown | D37: Trang hiển thị | E37: Hiển thị danh sách trạng thái | F37: Dropdown “Trạng thái đơn” hiển thị đúng danh sách trạng thái. | G37: passed | H37: 46124
A38: TC_REV_12 | B38: Kiểm tra ô tìm kiếm | C38: Click input | D38: Trang hiển thị | E38: Có placeholder, nhập được | F38: Ô tìm kiếm có placeholder, nhập dữ liệu bình thường. | G38: passed | H38: 46124
... A41: TC_REV_15 | B41: Kiểm tra layout tổng thể | C41: Quan sát toàn trang | D41: Trang load | E41: UI không bị lệch | F41: Layout tổng thể hiển thị đúng, UI không bị lệch. | G41: passed | H41: 46124
A42: FUNCTION
A43: TC_REV_16 | B43: Xác nhận hiển thị đúng khi chủ cửa hàng đăng nhập hợp lệ và truy cập trang quản lý doanh thu | C43: 1. Nhập tài khoản cửa hàng 2. Click đăng nhập 3. Truy cập trang doanh thu | D43: Tài khoản hợp lệ | E43: Hệ thống đăng nhập thành công và hiển thị trang quản lý doanh thu | F43: Đăng nhập thành công và chuyển đúng đến trang quản lý doanh thu | G43: passed | H43: 46124
A44: TC_REV_17 | B44: Xác nhận hiển thị đúng khi truy cập trang quản lý doanh thu | C44: 1. Truy cập menu doanh thu | D44: Đã đăng nhập | E44: Hiển thị đầy đủ dữ liệu doanh thu | F44: Truy cập menu doanh thu hiển thị đầy đủ dữ liệu | G44: passed | H44: 46124
A45: TC_REV_18 | B45: Xác nhận hệ thống hiển thị đúng dữ liệu doanh thu hôm nay | C45: 1. Truy cập trang quản lý doanh thu cửa hàng | D45: Có dữ liệu | E45: Hiển thị đúng tổng doanh thu hôm nay | F45: Hệ thống hiển thị đúng tính toán tổng doanh thu hôm nay | G45: passed | H45: 46124
A46: TC_REV_19 | B46: Xác nhận hệ thống hiển thị đúng giá trị thực nhận doanh thu cửa hàng hôm nay | C46: 1. Kiểm tra thực nhận | D46: Có dữ liệu | E46: Thực nhận = Tổng tiền đơn - giảm giá - phí | F46: Giá trị thực nhận được tính đúng (tổng tiền - giảm giá - phí) | G46: passed | H46: 46124
A47: TC_REV_20 | B47: Xác nhận hệ thống hiển thị đúng tổng số đơn hàng của cửa hàng trong hôm nay | C47: 1. Kiểm tra tổng đơn hàng | D47: Có dữ liệu | E47: Hiển thị chính xác tổng đơn hàng bán được của cửa hàng | F47: Tổng số đơn hàng bán được cửa cửa hàng trong hôm nay hiển thị chính xác | G47: passed | H47: 46124
A48: TC_REV_21 | B48: Xác nhận hệ thống hiển thị đúng tỉ lệ hủy/hoàn của cửa hàng trong hôm nay | C48: 1. Kiểm tra tỉ lệ hủy/hoàn | D48: Có dữ liệu | E48: Tính toán tỉ lệ = (đơn hủy + hoàn) / tổng đơn | F48: Tỉ lệ hủy/hoàn hiển thị đúng theo dữ liệu | G48: passed | H48: 46124
A49: TC_REV_22 | B49: Xác nhận hiển thị đúng khi tính % thay đổi so với hôm qua | C49: 1. Kiểm tra % thay đổi | D49: Có dữ liệu | E49: Hiển thị đúng % tăng/giảm | F49: Hiển thị không đúng % tăng/giảm so với hôm qua, | G49: failed | H49: 46124 | I49: passed | J49: 46128
A50: TC_REV_23 | B50: Xác nhận hiển thị đúng % thay đổi khi dữ liệu hôm trước = 0 | C50: 1. Kiểm tra doanh thu của hôm trước và hôm nay | D50: Có dữ liệu | E50: Hiển thị giá trị thay đổi là 100% | F50: Không hiển thị đúng giá trị 100% khi dữ liệu hôm trước = 0 | G50: failed | H50: 46124 | I50: passed | J50: 46128
A51: TC_REV_24 | B51: Xác nhận hiển thị đúng khi giá trị hôm qua không có thay đổi so với hôm nay | C51: 1. Kiểm tra doanh thu của hôm trước và hôm nay | D51: Có dữ liệu | E51: Hiển thị 0% khi không có sự thay đổi | F51: Không hiển thị đúng 0% khi không có thay đổi doanh thu | G51: failed | H51: 46124 | I51: passed | J51: 46128
A52: TC_REV_25 | B52: Xác nhận hiển thị đúng khi không có dữ liệu doanh thu cửa hàng | C52: 1. Truy cập trang quản lý doanh thu cửa hàng | D52: Không có dữ liệu | E52: Hiển thị 0 hoặc empty state | F52: Khi không có dữ liệu, hiển thị 0 hoặc empty state đúng | G52: passed | H52: 46124
A53: TC_REV_26 | B53: Xác nhận hệ thống hiển thị đúng dữ liệu khi refresh lại trang | C53: 1. Click refresh | D53: Có dữ liệu mới | E53: Load lại dữ liệu, cập nhật dữ liệu mới nhất từ hệ thống | F53: Refresh cập nhật dữ liệu mới chính xác | G53: passed | H53: 46124
A54: TC_REV_27 | B54: Xác nhận hệ thống hiển thị đúng biểu đồ doanh thu của 30 ngày gần đây | C54: 1. Truy cập trang quản lý doanh thu cửa hàng 2. Quan sát biểu đồ | D54: Có dữ liệu | E54: Hiển thị đúng dữ liệu theo từng ngày | F54: Biểu đồ 30 ngày hiển thị đúng dữ liệu theo từng ngày | G54: passed | H54: 46124
A55: TC_REV_28 | B55: Xác nhận hệ thống hiển thị giá trị chính xác khi di chuột vào các điểm dữ liệu | C55: 1. Truy cập trang quản lý doanh thu cửa hàng 2. Hover vào line biểu đồ | D55: Có dữ liệu | E55: Tooltip hiển thị đúng giá trị | F55: Tooltip hiển thị đúng giá trị khi hover | G55: passed | H55: 46124
A56: TC_REV_29 | B56: Xác nhận trục X hiển thị đúng format ngày | C56: 1. Quan sát trục X | D56: N/A | E56: Hiển thị 30 ngày gần nhất (dd/MM) | F56: Trục X hiển thị đúng format ngày (dd/MM) | G56: passed | H56: 46124
A57: TC_REV_30 | B57: Xác nhận hiển thị đúng scale trục Y | C57: 1. Quan sát trục Y | D57: N/A | E57: Giá trị max/min hợp lý, không bị dồn điểm | F57: Trục Y hiển thị scale hợp lý, không bất thường | G57: passed | H57: 46124
A58: TC_REV_31 | B58: Xác nhận hiển thị đúng giá trị doanh thu trên biểu đồ | C58: 1. Click refresh | D58: Có dữ liệu | E58: Cập nhật dữ liệu mới | F58: Click refresh, biểu đồ cập nhật dữ liệu mới | G58: passed | H58: 46124
...

Sheet Quản lý menu cửa hàng
A1: Project Name | B1: XÂY DỰNG HỆ THỐNG DISHNET - NỀN TẢNG MẠNG XÃ HỘI KINH DOANH ẨM THỰC
A2: Module Code | B2: Quản lý menu cửa hàng
A3: Người kiểm tra | B3: Lê Văn Cường
B4: Hoàn thành | C4: Lỗi | D4: Chưa kiểm tra | E4: Bị chăn | F4: Tổng số trường hợp thử nghiệm
A5: Round 1 | B5: =COUNTIF(G27:G1019,"passed") -> 86 | C5: =COUNTIF(G29:G1019,"failed") -> 5 | D5: =COUNTIF(G29:G1019,"untest") -> 0 | E5: =COUNTIF(G29:G1019,"blocked") -> 0 | F5: =COUNTIF(A26:A1015, "TC*") -> 91
A6: Round 2 | B6: =COUNTIF(I29:I1020,"passed") -> 5 | C6: =COUNTIF(I29:I1019,"failed") -> 0 | D6: =COUNTIF(I29:I1019,"untest") -> 0 | E6: =COUNTIF(I29:I1019,"blocked") -> 0 | F6: =COUNTIF(A27:A1016, "TC*") -> 91
A23: Test Case ID | B23: Mô tả | C23: Hành động | D23: Điều kiện tiên quyết | E23: Kết quả mong đợi | F23: Kết quả thực tế | G23: Kết quả | I23: Kết quả | K23: Chú thích
G24: Vòng 1 | I24: Vòng 2
G25: Trạng thái | H25: Ngày kiểm tra | I25: Trạng thái | J25: Ngày kiểm tra
A26: GUI
A27: TC_MN_01 | B27: Kiểm tra hiển thị tiêu đề trang "QUẢN LÝ MENU" | C27: 1. Truy cập vào trang Quản lý menu 2. Quan sát phần đầu của nội dung trang | D27: N/A | E27: Hệ thống hiển thị dòng chữ "QUẢN LÝ MENU" in hoa, đậm, đúng vị trí bên trái màn hình. | F27: Tiêu đề "QUẢN LÝ MENU" hiển thị rõ ràng, font chữ đồng bộ với hệ thống, không bị lỗi font hay đè chữ. | G27: passed | H27: 46125
A28: TC_MN_02 | B28: Kiểm tra hiển thị khung tìm kiếm món | C28: 1. Quan sát phía trên bên phải, cạnh nút Thêm món 2. Nhìn vào placeholder trong ô nhập | D28: N/A | E28: Hệ thống hiển thị ô nhập liệu kèm icon kính lúp và placeholder "Tìm kiếm món". | F28: Ô tìm kiếm hiển thị đúng vị trí, placeholder hiển thị mờ đúng thiết kế, icon kính lúp căn lề phải trong ô. | G28: passed | H28: 46125
A29: TC_MN_03 | B29: Kiểm tra hiển thị nút "+ Thêm món" | C29: 1. Quan sát góc trên bên phải màn hình | D29: N/A | E29: Hệ thống hiển thị nút màu xanh lá, có icon "+" và chữ "Thêm món" rõ ràng. | F29: Nút xanh lá nổi bật, chữ trắng dễ đọc, bo góc đúng chuẩn giao diện DishNet. | G29: passed | H29: 46125
A30: TC_MN_04 | B30: Kiểm tra hiển thị Card "Top món bán chạy hôm nay" | C30: 1. Quan sát bố cục khung bên trái | D30: N/A | E30: Hệ thống hiển thị khung bao gồm tiêu đề, danh sách xếp hạng 1, 2, 3 kèm ảnh và thông tin món. | F30: Khung Card hiển thị trực quan, các dòng thông tin (Tên, Giá, Lượt bán) được căn chỉnh thẳng hàng, dễ nhìn. | G30: passed | H30: 46125
A31: TC_MN_05 | B31: Kiểm tra hiển thị Card "Danh sách các món đã hết" | C31: 1. Quan sát bố cục khung bên phải | D31: N/A | E31: Hệ thống hiển thị khung có tiêu đề và dòng chữ "Xem thêm (0)" ở góc phải. | F31: Khung hiển thị đúng bố cục đối xứng với Card Top món, nội dung bên trong thông báo tình trạng món đã hết rõ ràng. | G31: passed | H31: 46125
A32: TC_MN_06 | B32: Kiểm tra hiển thị các tab phân loại món | C32: 1. Quan sát thanh phân loại phía trên bảng danh sách | D32: N/A | E32: Hệ thống hiển thị các nút: Tất cả, Món chính, Món phụ, Đồ uống. | F32: Các tab phân loại hiển thị đúng thứ tự, tab "Tất cả" đang được chọn có màu nền tối để phân biệt. | G32: passed | H32: 46125
A33: TC_MN_07 | B33: Kiểm tra hiển thị bảng danh sách món (Data Grid) | C33: 1. Quan sát các cột và hàng trong bảng | D33: N/A | E33: Hệ thống hiển thị đủ 7 cột: STT, Mã món, Tên món, Đơn giá, Số lượng đã bán, Trạng thái, Thao tác. | F33: Cấu trúc bảng ngay ngắn, tên các cột hiển thị đậm, dữ liệu trong các hàng nằm đúng cột tương ứng. | G33: passed | H33: 46125
A34: TC_MN_08 | B34: Kiểm tra hiển thị các nút chức năng Sửa/Xóa | C34: 1. Quan sát cột "Thao tác" trong bảng danh sách | D34: N/A | E34: Hệ thống hiển thị nút "Sửa" màu cam và nút "Xóa" màu đỏ cho từng dòng. | F34: Các nút thao tác hiển thị rõ ràng, màu sắc phân biệt tốt, kích thước nút vừa phải dễ tương tác. | G34: passed | H34: 46125
A35: TC_MN_09 | B35: Kiểm tra hiển thị trạng thái "Đang bán" | C35: 1. Quan sát cột "Trạng thái" của các món ăn | D35: N/A | E35: Hệ thống hiển thị chữ "Đang bán" màu xanh lá cây đậm. | F35: Trạng thái hiển thị đúng màu sắc chỉ định, giúp người dùng dễ dàng nhận diện nhanh tình trạng món. | G35: passed | H35: 46125
A36: FUNCTION
A37: TC_MN_10 | B37: Xác nhận Admin truy cập trang Quản lý menu thành công khi đăng nhập đúng | C37: 1. Truy cập hệ thống 2. Quan sát sidebar 3. Click chọn Quản lý menu | D37: Tài khoản Admin hợp lệ | E37: Hệ thống phải chuyển hướng người dùng vào giao diện Quản lý menu. | F37: Truy cập đúng trang, không giật lag. | G37: passed | H37: 46125
A38: TC_MN_11 | B38: Xác nhận hệ thống lấy danh sách món từ database thành công khi load trang | C38: 1. Tải trang Quản lý menu 2. Quan sát danh sách | D38: Database có dữ liệu món ăn | E38: Hệ thống phải hiển thị đầy đủ danh sách món ăn từ cơ sở dữ liệu. | F38: Danh sách hiện đầy đủ như database. | G38: passed | H38: 46125
A39: TC_MN_12 | B39: Xác nhận hệ thống lấy dữ liệu Top món bán chạy thành công khi tải trang | C39: 1. Truy cập trang 2. Quan sát CARD Top món bán chạy | D39: N/A | E39: Hệ thống hiển thị đúng thông tin các món có lượt bán cao nhất. | F39: Hiển thị đúng 3 món bán chạy nhất. | G39: passed | H39: 46125
A40: TC_MN_13 | B40: Xác nhận hệ thống lấy danh sách món hết hàng thành công khi tải trang | C40: 1. Truy cập trang 2. Quan sát CARD Danh sách các món đã hết | D40: N/A | E40: Hệ thống hiển thị đúng danh sách các món có số lượng bằng 0. | F40: Hiện đúng các món có tồn kho bằng 0. | G40: passed | H40: 46125
A41: TC_MN_14 | B41: Xác nhận trả về danh sách rỗng khi hệ thống không có dữ liệu | C41: 1. Xóa dữ liệu database 2. Quan sát bảng danh sách | D41: Database trống | E41: Hệ thống hiển thị thông báo hoặc bảng trống không có dữ liệu. | F41: Bảng trống, hiện thông báo không có món. | G41: passed | H41: 46125
A42: BOX SEARCH
A43: TC_MN_15 | B43: Xác nhận trả về danh sách đúng khi nhập tên món vào Box tìm kiếm | C43: 1. Click ô tìm kiếm 2. Nhập tên món hợp lệ | D43: N/A | E43: Hệ thống hiển thị đúng danh sách món ăn khớp với tên đã nhập. | F43: Hiển thị đúng kết quả tìm kiếm. | G43: passed | H43: 46125
A44: TC_MN_16 | B44: Xác nhận thực hiện tìm kiếm khi nhấn phím Enter | C44: 1. Nhập từ khóa 2. Nhấn phím Enter | D44: N/A | E44: Hệ thống phải thực hiện lọc dữ liệu ngay sau khi nhấn phím. | F44: Tìm kiếm phản hồi ngay khi nhấn phím. | G44: passed | H44: 46125
A45: TC_MN_17 | B45: Xác nhận tìm kiếm không phân biệt hoa thường khi nhập từ khóa | C45: 1. Nhập từ khóa bằng chữ thường 2. Nhấn Enter | D45: N/A | E45: Hệ thống phải hiển thị kết quả bao gồm cả chữ hoa và chữ thường. | F45: Kết quả trả về đúng món cần tìm. | G45: passed | H45: 46125
A46: TC_MN_18 | B46: Xác nhận tìm kiếm gần đúng theo tên món khi nhập từ khóa | C46: 1. Nhập một phần tên món 2. Nhấn Enter | D46: N/A | E46: Hệ thống hiển thị các món có tên chứa chuỗi ký tự đã nhập. | F46: Hiển thị các kết quả gợi ý gần đúng. | G46: passed | H46: 46125
A47: TC_MN_19 | B47: Xác nhận trả về rỗng khi tìm món không tồn tại trong hệ thống | C47: 1. Nhập tên món không tồn tại 2. Nhấn Enter | D47: N/A | E47: Hệ thống hiển thị thông báo không tìm thấy kết quả. | F47: Hiển thị thông báo không tìm thấy món. | G47: passed | H47: 46125
A48: TC_MN_20 | B48: Xác nhận không filter dữ liệu khi nhập khoảng trắng vào ô tìm kiếm | C48: 1. Nhập các khoảng trắng 2. Nhấn Enter | D48: N/A | E48: Hệ thống không thực hiện lọc hoặc hiển thị toàn bộ danh sách. | F48: Danh sách giữ nguyên hoặc hiện toàn bộ. | G48: passed | H48: 46125
A49: TC_MN_21 | B49: Xác nhận hệ thống không lỗi khi nhập ký tự đặc biệt vào ô tìm kiếm | C49: 1. Nhập ký tự đặc biệt (@, #) 2. Nhấn Enter | D49: N/A | E49: Hệ thống phải xử lý an toàn và không phát sinh lỗi mã nguồn. | F49: Xử lý chuỗi ký tự lạ bình thường. | G49: passed | H49: 46125
A50: TC_MN_22 | B50: Xác nhận không crash khi nhấn Enter nhiều lần tại ô tìm kiếm | C50: 1. Nhập từ khóa 2. Nhấn phím Enter liên tục | D50: N/A | E50: Hệ thống phải xử lý ổn định các yêu cầu dồn dập. | F50: Xử lý các request dồn dập ổn định. | G50: passed | H50: 46125
A51: TC_MN_23 | B51: Xác nhận tìm kiếm đúng khi sử dụng thao tác Copy paste từ khóa | C51: 1. Copy từ khóa 2. Paste vào ô tìm kiếm | D51: N/A | E51: Hệ thống phải nhận diện dữ liệu paste và thực hiện tìm kiếm. | F51: Thực thi tìm kiếm chính xác. | G51: passed | H51: 46125
A52: TC_MN_24 | B52: Xác nhận trả về danh sách rỗng khi API lỗi trong quá trình tìm kiếm | C52: 1. Ngắt kết nối API 2. Thực hiện tìm kiếm | D52: N/A | E52: Hệ thống hiển thị bảng trống thay vì dữ liệu cũ hoặc lỗi. | F52: Không hiện dữ liệu rác khi API lỗi. | G52: passed | H52: 46125
A53: CARD TOP BÁN CHẠY
A54: TC_MN_25 | B54: Xác nhận lấy danh sách món bán chạy trong ngày hiện tại cho CARD Top món | C54: 1. Truy cập trang 2. Quan sát CARD Top món | D54: Có đơn hàng thành công | E54: Hệ thống phải lọc đúng các món có phát sinh lượt bán trong ngày. | F54: Dữ liệu đúng theo mốc thời gian thực. | G54: passed | H54: 46125
A55: TC_MN_26 | B55: Xác nhận hệ thống sắp xếp món theo số lượng bán giảm dần tại CARD Top món | C55: 1. Quan sát thứ tự món trên CARD | D55: N/A | E55: Món bán nhiều nhất phải nằm ở vị trí đầu tiên. | F55: Thứ tự 1, 2, 3 đúng lượt bán giảm dần. | G55: passed | H55: 46125
A56: TC_MN_27 | B56: Xác nhận hiển thị 3 món có số lượng bán cao nhất | C56: 1. Đếm số lượng món hiển thị | D56: Có > 3 món bán | E56: Hệ thống chỉ được hiển thị đúng 3 món có lượt bán dẫn đầu. | F56: Hiển thị đúng 3 món cao nhất. | G56: passed | H56: 46125
...

Sheet Quản lý đơn hàng của cửa hàng
A1: Project Name | B1: XÂY DỰNG HỆ THỐNG DISHNET - NỀN TẢNG MẠNG XÃ HỘI KINH DOANH ẨM THỰC
A2: Module Code | B2: Quản lý đơn hàng của cửa hàng
A3: Người kiểm tra | B3: Phạm Đình Vân Ly
B4: Hoàn thành | C4: Lỗi | D4: Chưa kiểm tra | E4: Bị chăn | F4: Tổng số trường hợp thử nghiệm
A5: Round 1 | B5: =COUNTIF(G27:G1012,"passed") -> 82 | C5: =COUNTIF(G27:G1012,"failed") -> 0 | D5: =COUNTIF(G27:G1012,"untest") -> 0 | E5: =COUNTIF(G27:G1012,"blocked") -> 0 | F5: =COUNTIF(A26:A1008, "TC*") -> 82
A6: Round 2 | B6: =COUNTIF(I27:I1013,"passed") -> 0 | C6: =COUNTIF(I27:I1012,"failed") -> 0 | D6: =COUNTIF(I27:I1012,"untest") -> 0 | E6: =COUNTIF(I27:I1012,"blocked") -> 0 | F6: =COUNTIF(A27:A1009, "TC*") -> 82
A23: Test Case ID | B23: Mô tả | C23: Hành động | D23: Điều kiện tiên quyết | E23: Kết quả mong đợi | F23: Kết quả thực tế | G23: Kết quả | I23: Kết quả | K23: Chú thích
G24: Vòng 1 | I24: Vòng 2
G25: Trạng thái | H25: Ngày kiểm tra | I25: Trạng thái | J25: Ngày kiểm tra
A26: GUI
A27: TC_ORD_01 | B27: Kiểm tra hiển thị thanh điều hướng trạng thái đơn hàng | C27: 1. Truy cập màn hình Đơn đặt hàng 2. Quan sát các nút trạng thái | D27: N/A | E27: Hiển thị đủ 7 tab: Chờ xác nhận, Đang chuẩn bị, Đang giao, Đã giao, Đã hủy, Trả hàng, Tất cả đơn. | F27: Các tab trạng thái hiển thị đầy đủ, rõ ràng. | G27: passed | H27: 46125
A28: TC_ORD_02 | B28: Kiểm tra hiệu ứng highlight khi chọn Tab trạng thái | C28: 1. Click lần lượt vào từng tab (VD: Đang chuẩn bị) | D28: N/A | E28: Tab được chọn phải đổi màu nền (đỏ hoặc đen) và có bo góc để phân biệt với tab khác. | F28: Tab đang chọn nổi bật hơn các tab còn lại. | G28: passed | H28: 46125
A29: TC_ORD_03 | B29: Kiểm tra hiển thị số lượng đơn hàng trên nhãn Tab | C29: 1. Quan sát con số trong ngoặc đơn trên mỗi tab | D29: Hệ thống có dữ liệu đơn hàng. | E29: Số lượng hiển thị (VD: Chờ xác nhận (3)) phải khớp với số lượng đơn thực tế bên dưới. | F29: Con số hiển thị đúng số lượng đơn tương ứng. | G29: passed | H29: 46125
A30: TC_ORD_04 | B30: Kiểm tra hiển thị ô tìm kiếm đơn hàng | C30: 1. Quan sát thanh tìm kiếm bên dưới các tab | D30: N/A | E30: Ô tìm kiếm hiển thị đúng placeholder "Tìm kiếm mã đơn, tên khách...". | F30: Thanh tìm kiếm nằm đúng vị trí, dễ nhìn. | G30: passed | H30: 46125
A31: TC_ORD_05 | B31: Kiểm tra hiển thị các Dropdown lọc (Filter) | C31: 1. Quan sát góc bên phải thanh tìm kiếm | D31: N/A | E31: Hiển thị 2 dropdown: Lọc theo thời gian (Tất cả) và Loại đơn (Tất cả đơn). | F31: Các nút lọc hiển thị đúng định dạng dropdown. | G31: passed | H31: 46125
A32: TC_ORD_06 | B32: Kiểm tra bố cục hiển thị một Card đơn hàng | C32: 1. Quan sát cấu trúc 1 đơn hàng bất kỳ | D32: N/A | E32: Phải hiển thị đủ: Mã đơn, Trạng thái (label góc phải), Thông tin khách, Danh sách món, Tổng tiền, Nút thao tác. | F32: Bố cục sắp xếp khoa học, không bị chồng chéo chữ. | G32: passed | H32: 46125
A33: TC_ORD_07 | B33: Kiểm tra hiển thị nhãn "Mới" cho đơn hàng mới | C33: 1. Tìm đơn hàng vừa phát sinh | D33: Có đơn hàng mới chưa xử lý. | E33: Hiển thị nhãn "Mới" màu xanh lá cạnh mã đơn hàng để gây chú ý. | F33: Nhãn "Mới" hiển thị đúng vị trí cạnh mã đơn. | G33: passed | H33: 46125
A34: TC_ORD_08 | B34: Kiểm tra định dạng tiền tệ (VNĐ) | C34: 1. Quan sát các mục giá tiền và phí vận chuyển | D34: N/A | E34: Số tiền phải có dấu chấm phân cách hàng nghìn và đơn vị "đ" (VD: 123.000đ). | F34: Định dạng tiền tệ hiển thị đúng chuẩn. | G34: passed | H34: 46125
A35: TC_ORD_09 | B35: Kiểm tra hiển thị Avatar và thông tin khách hàng | C35: 1. Quan sát phần thông tin người mua | D35: Khách hàng có cập nhật ảnh đại diện. | E35: Ảnh avatar hiển thị hình tròn, tên khách hàng in đậm, kèm thời gian đặt hàng. | F35: Thông tin khách hàng hiển thị rõ nét, đúng font. | G35: passed | H35: 46125
A36: TC_ORD_10 | B36: Kiểm tra hiển thị địa chỉ giao hàng (Icon định vị) | C36: 1. Quan sát dòng địa chỉ ở cuối mỗi Card | D36: N/A | E36: Địa chỉ phải đi kèm icon định vị màu hồng/đỏ và hiển thị đầy đủ text. | F36: Địa chỉ hiện đúng, có icon minh họa sinh động. | G36: passed | H36: 46125
A37: TC_ORD_11 | B37: Kiểm tra màu sắc các nút hành động (Xác nhận/Từ chối) | C37: 1. Quan sát tab "Chờ xác nhận" | D37: N/A | E37: Nút Xác nhận màu xanh lá, nút Từ chối màu đỏ để phân biệt rõ hành động. | F37: Màu sắc nút tương phản tốt, dễ phân biệt. | G37: passed | H37: 46125
A38: TC_ORD_12 | B38: Kiểm tra hiển thị liên kết "Xem chi tiết đơn hàng" | C38: 1. Quan sát phía dưới các nút thao tác | D38: N/A | E38: Dòng chữ "Xem chi tiết đơn hàng ->" có gạch chân hoặc màu khác để nhận biết là link. | F38: Liên kết hiển thị đúng style của một hyperlink. | G38: passed | H38: 46125
... A48: TC_ORD_22 | B48: Kiểm tra sự thay đổi layout linh hoạt theo trạng thái đơn hàng | C48: 1. So sánh tab Đang giao với tab Đã hủy/Trả hàng | D48: N/A | E48: Giao diện phải tự động mở rộng thêm cột thông tin bên phải để hiện Lý do hủy/Khiếu nại khi cần thiết. | F48: Layout thay đổi linh hoạt, không bị tràn viền khi thêm thông tin. | G48: passed | H48: 46125
A49: FUNCTION
A50: TC_ORD_23 | B50: Xác nhận hiển thị đúng danh sách đơn hàng theo trạng thái đã chọn khi Click từng tab | C50: 1. Truy cập màn hình Quản lý đơn hàng 2. Click lần lượt các tab: Chờ xác nhận, Đang chuẩn bị, Đang giao, Đã giao, Đã hủy, Trả hàng | D50: Có dữ liệu đơn hàng ở các trạng thái tương ứng. | E50: Hệ thống hiển thị đúng danh sách đơn hàng theo trạng thái đã chọn. | F50: Danh sách đơn hàng thay đổi chính xác theo từng tab trạng thái được click. | G50: passed | H50: 46125
A51: TC_ORD_24 | B51: Xác nhận dữ liệu load lại đúng theo tab được chọn khi Chuyển tab liên tục | C51: 1. Click chuyển đổi qua lại liên tục giữa các tab trạng thái | D51: N/A | E51: Hệ thống phải load lại đúng dữ liệu theo tab được chọn. | F51: Dữ liệu được làm mới ngay lập tức và chính xác sau mỗi lần chuyển tab. | G51: passed | H51: 46125
A52: TC_ORD_25 | B52: Xác nhận hiển thị danh sách rỗng khi chọn tab hiện không có đơn hàng | C52: 1. Click vào tab trạng thái bất kỳ | D52: Database không có đơn ở trạng thái này. | E52: Hệ thống hiển thị danh sách rỗng. | F52: Giao diện hiển thị thông báo "Không có đơn hàng" hoặc bảng trống. | G52: passed | H52: 46125
A53: TC_ORD_26 | B53: Xác nhận không xảy ra lỗi khi Click vào cùng một tab nhiều lần | C53: 1. Click liên tục vào cùng một tab trạng thái đơn hàng | D53: N/A | E53: Hệ thống hoạt động bình thường, không xảy ra lỗi. | F53: Không có lỗi phát sinh, hệ thống vẫn giữ nguyên dữ liệu tab hiện tại. | G53: passed | H53: 46125
A54: TC_ORD_27 | B54: Xác nhận không xảy ra tình trạng trùng lặp dữ liệu khi Click chuyển các tab cực nhanh | C54: 1. Click chuyển đổi giữa các tab với tốc độ cực nhanh | D54: N/A | E54: Hệ thống không xảy ra tình trạng trùng lặp dữ liệu (duplicate data). | F54: Dữ liệu hiển thị duy nhất, không bị nhân đôi các card đơn hàng. | G54: passed | H54: 46125
A55: TC_ORD_28 | B55: Xác nhận trả về đúng đơn hàng có mã tương ứng khi Nhập mã đơn hàng vào ô tìm kiếm | C55: 1. Nhập mã đơn hàng vào ô tìm kiếm 2. Nhấn phím Enter | D55: Mã đơn hàng tồn tại trong hệ thống. | E55: Hệ thống hiển thị trả về đúng đơn hàng có mã tương ứng. | F55: Kết quả trả về đúng duy nhất 1 đơn hàng khớp với mã đã nhập. | G55: passed | H55: 46125
A56: TC_ORD_29 | B56: Xác nhận trả về đúng danh sách đơn hàng của khách khi Nhập tên khách hàng vào ô tìm kiếm | C56: 1. Nhập tên khách hàng vào ô tìm kiếm 2. Nhấn phím Enter | D56: Khách hàng có đơn hàng trong hệ thống. | E56: Hệ thống hiển thị trả về đúng danh sách đơn hàng của khách hàng đó. | F56: Hiển thị đầy đủ các đơn hàng thuộc quyền sở hữu của khách hàng tìm kiếm. | G56: passed | H56: 46125
A57: TC_ORD_30 | B57: Xác nhận kết quả chính xác khi Nhập tên khách không dấu | C57: 1. Nhập tên khách hàng không có dấu (VD: "Net Hue") 2. Nhấn phím Enter | D57: Tên khách trong hệ thống có dấu. | E57: Hệ thống vẫn trả ra kết quả chính xác. | F57: Hệ thống tự động nhận diện và trả về kết quả của khách "Nét Huế". | G57: passed | H57: 46125
A58: TC_ORD_31 | B58: Xác nhận trả ra các kết quả chứa từ khóa khi Nhập một phần mã đơn hoặc tên khách | C58: 1. Nhập một phần mã đơn hoặc một phần tên khách hàng 2. Nhấn phím Enter | D58: N/A | E58: Hệ thống trả ra các kết quả có chứa từ khóa đó. | F58: Các đơn hàng có chứa chuỗi ký tự nhập vào đều được hiển thị. | G58: passed | H58: 46125
A59: TC_ORD_32 | B59: Xác nhận hiển thị lại toàn bộ danh sách khi Xóa trắng nội dung trong ô tìm kiếm | C59: 1. Xóa hết ký tự trong ô tìm kiếm | D59: Đang hiển thị kết quả tìm kiếm. | E59: Hệ thống hiển thị lại toàn bộ danh sách đơn hàng. | F59: Bộ lọc tìm kiếm được gỡ bỏ, danh sách đơn hàng quay về trạng thái ban đầu. | G59: passed | H59: 46125
A60: TC_ORD_33 | B60: Xác nhận không thực hiện filter dữ liệu khi Nhập chuỗi chỉ gồm khoảng trắng | C60: 1. Nhập các ký tự khoảng trắng vào ô tìm kiếm 2. Nhấn phím Enter | D60: N/A | E60: Hệ thống không thực hiện filter dữ liệu. | F60: Danh sách đơn hàng không thay đổi so với trước khi tìm kiếm. | G60: passed | H60: 46125
A61: TC_ORD_34 | B61: Xác nhận không bị crash khi Nhập các ký tự đặc biệt vào ô tìm kiếm | C61: 1. Nhập các ký tự như @, #, $, % vào ô tìm kiếm 2. Nhấn phím Enter | D61: N/A | E61: Hệ thống xử lý bình thường, không bị crash. | F61: Hệ thống báo "Không tìm thấy kết quả" nhưng không xảy ra lỗi ứng dụng. | G61: passed | H61: 46125
... A109: TC_ORD_82 | B109: Xác nhận không mở nhiều request khi Click nhiều lần vào Xem chi tiết | C109: 1. Nhấn liên tục vào dòng "Xem chi tiết đơn hàng" | D109: N/A | E109: Hệ thống phải xử lý để không mở nhiều yêu cầu truy cập cùng lúc. | F109: Chỉ thực hiện duy nhất 1 lần chuyển trang. | G109: passed | H109: 46125
B242: quản lý đơn hàng | C242: Tabs trạng thái đơn hàng | D242: - Click từng tab (Chờ xác nhận / Đang chuẩn bị / Đang giao / Đã giao / Đã hủy / Trả hàng) → hiển thị đúng danh sách - Chuyển tab → dữ liệu load lại đúng - Không có đơn → hiển thị danh sách rỗng - Click tab nhiều lần → không lỗi - Click tab cực nhanh → không duplicate data-
C243: Ô tìm kiếm | D243: - Nhập mã đơn → trả đúng đơn - Nhập tên khách → trả đúng danh sách - Tìm không dấu vẫn ra kết quả - Tìm gần đúng (partial) → có kết quả - Clear input → hiển thị lại toàn bộ - Nhập khoảng trắng → không filter - Nhập ký tự đặc biệt → không crash - Nhập chuỗi dài (>500 ký tự) → không vỡ UI - Spam Enter → không gửi request trùng
C244: Dropdown filter thời gian | D244: - Chọn "Tất cả" → hiển thị toàn bộ đơn - Chọn "Hôm nay" → chỉ hiển thị đơn trong ngày hiện tại - Chọn "7 ngày" → hiển thị đơn trong 7 ngày gần nhất - Chọn "30 ngày" → hiển thị đơn trong 30 ngày gần nhất - Chọn "Tùy chỉnh" → cho phép chọn khoảng ngày (from – to) - Chọn khoảng ngày hợp lệ → hiển thị đúng dữ liệu - From > To → báo lỗi / không cho chọn - Không có dữ liệu → hiển thị rỗng - Kết hợp với search → trả kết quả đúng - Kết hợp với tab trạng thái → không conflict - Click đổi filter liên tục → không lỗi - Timezone khác nhau → vẫn lọc đúng ngày - Chọn ngày tương lai → không trả dữ liệu hoặc cảnh báo
...

Sheet Quản lý khuyến mãi cửa hàng
A1: Project Name | B1: XÂY DỰNG HỆ THỐNG DISHNET - NỀN TẢNG MẠNG XÃ HỘI KINH DOANH ẨM THỰC
A2: Module Code | B2: Quản lý khuyến mãi cửa hàng
A3: Người kiểm tra | B3: Trần Thị Mai Yên
B4: Hoàn thành | C4: Lỗi | D4: Chưa kiểm tra | E4: Bị chăn | F4: Tổng số trường hợp thử nghiệm
A5: Round 1 | B5: =COUNTIF(G27:G997,"passed") -> 65 | C5: =COUNTIF(G27:G997,"failed") -> 0 | D5: =COUNTIF(G27:G997,"untest") -> 0 | E5: =COUNTIF(G27:G997,"blocked") -> 0 | F5: =COUNTIF(A26:A993, "TC*") -> 65
A6: Round 2 | B6: =COUNTIF(I27:I998,"passed") -> 0 | C6: =COUNTIF(I27:I997,"failed") -> 0 | D6: =COUNTIF(I27:I997,"untest") -> 0 | E6: =COUNTIF(I27:I997,"blocked") -> 0 | F6: =COUNTIF(A27:A994, "TC*") -> 65
A23: Test Case ID | B23: Mô tả | C23: Hành động | D23: Điều kiện tiên quyết | E23: Kết quả mong đợi | F23: Kết quả thực tế | G23: Kết quả | I23: Kết quả | K23: Chú thích
G24: Vòng 1 | I24: Vòng 2
G25: Trạng thái | H25: Ngày kiểm tra | I25: Trạng thái | J25: Ngày kiểm tra
A26: GUI
A27: TC_PROM_01 | B27: Kiểm tra hiển thị tiêu đề và nút Thêm khuyến mãi | C27: 1. Truy cập màn hình Khuyến mãi 2. Quan sát tiêu đề trang và nút chức năng góc trên bên phải | D27: N/A | E27: Hệ thống hiển thị đúng tiêu đề "QUẢN LÝ KHUYẾN MÃI" in đậm và nút "+ Thêm khuyến mãi" màu xanh lá. | F27: Tiêu đề và nút hiển thị đúng màu sắc và font chữ theo thiết kế. | G27: passed | H27: 46125
A28: TC_PROM_02 | B28: Kiểm tra placeholder của ô tìm kiếm chương trình | C28: 1. Quan sát ô nhập liệu tìm kiếm ở giữa trang | D28: N/A | E28: Hệ thống hiển thị placeholder: "Tìm kiếm tên mã, code khuyến mãi" kèm icon kính lúp. | F28: Placeholder hiển thị rõ ràng, giúp người dùng nhận diện chức năng. | G28: passed | H28: 46125
A29: TC_PROM_03 | B29: Kiểm tra màu sắc của các nhãn trạng thái khuyến mãi | C29: 1. Quan sát cột trạng thái bên phải các Card khuyến mãi | D29: Hệ thống có sẵn các mã khuyến mãi với đầy đủ các trạng thái: Sắp diễn ra, Đang diễn ra, Đã kết thúc | E29: Nhãn trạng thái phải đúng màu: Sắp diễn ra (Xám), Đang diễn ra (Xanh lá), Đã kết thúc (Đỏ). | F29: Các nhãn trạng thái hiển thị màu sắc tương ứng, dễ phân biệt. | G29: passed | H29: 46125
