Workbook

Sheet Trường hợp kiểm thử
A1: ĐẠI HỌC DUY TÂN
A2: KHOA CÔNG NGHỆ THÔNG TIN
A3: NGÀNH: CÔNG NGHỆ PHẦN MỀM
C6: TEST CASE SYSTEM SPRINT 1
C8: Tên dự án | D8: XÂY DỰNG HỆ THỐNG DISHNET - NỀN TẢNG MẠNG XÃ HỘI KINH DOANH ẨM THỰC
C9: STT | D9: Chức năng | E9: Sheet Name | F9: Số Testcase
C10: 1 | D10: Đăng nhập | E10: Đăng nhập | F10: ='Đăng nhập'!F6 -> 44
C11: 2 | D11: Đăng ký | E11: Đăng ký | F11: ='Đăng ký'!F6 -> 66
C12: 3 | D12: Quên mật khẩu | E12: Quên mật khẩu | F12: ='Quên mật khẩu'!F6 -> 55
C13: 4 | D13: Thống kê hệ thống | E13: Thống kê hệ thống | F13: ='Thống kê hệ thống'!F6 -> 68
C14: 5 | D14: Quản lý đơn hàng hệ thống | E14: Quản lý đơn hàng hệ thống | F14: ='Quản lý đơn hàng hệ thống'!F6 -> 67
C15: 6 | D15: Kiểm duyệt yêu cầu hệ thống | E15: Kiểm duyệt yêu cầu hệ thống | F15: ='Kiểm duyệt yêu cầu hệ thống'!F6 -> 42
C16: 7 | D16: Quản lý tài khoản | E16: Quản lý tài khoản | F16: ='Quản lý tài khoản'!F6 -> 55
C17: 8 | D17: Quản lý doanh thu hệ thống | E17: Quản lý doanh thu hệ thống | F17: ='Quản lý doanh thu hệ thống'!F6 -> 66
C18: 9 | D18: Quản lý khuyến mãi hệ thống | E18: Quản lý khuyến mãi hệ thống | F18: ='Quản lý khuyến mãi hệ thống'!F6 -> 65
C19: Tổng số testcase của sprint 1 | F19: =SUM(F10:F18) -> 528

Sheet Đăng nhập
A1: Project Name | B1: XÂY DỰNG HỆ THỐNG DISHNET - NỀN TẢNG MẠNG XÃ HỘI KINH DOANH ẨM THỰC
A2: Module Code | B2: Đăng nhập
A3: Người kiểm tra | B3: Phạm Đình Vân Ly
B4: Hoàn thành | C4: Lỗi | D4: Chưa kiểm tra | E4: Bị chăn | F4: Tổng số trường hợp thử nghiệm
A5: Round 1 | B5: =COUNTIF(G23:G1035,"passed") -> 43 | C5: =COUNTIF(G32:G1035,"failed") -> 1 | D5: =COUNTIF(G32:G1035,"untest") -> 0 | E5: =COUNTIF(G32:G1035,"blocked") -> 0 | F5: =COUNTIF(A23:A1031, "*LOG*") -> 44
A6: Round 2 | B6: =COUNTIF(I33:I1036,"passed") -> 1 | C6: =COUNTIF(I32:I1035,"failed") -> 0 | D6: =COUNTIF(G32:G1035,"untest") -> 0 | E6: =COUNTIF(G32:G1035,"blocked") -> 0 | F6: =COUNTIF(A24:A1032, "*LOG*") -> 44
A23: Test Case ID | B23: Mô tả | C23: Hành động | D23: Điều kiện tiên quyết | E23: Kết quả mong đợi | F23: Kết quả thực tế | G23: Kết quả | I23: Kết quả | K23: Chú thích
G24: Vòng 1 | I24: Vòng 2
G25: Trạng thái | H25: Ngày kiểm tra | I25: Trạng thái | J25: Ngày kiểm tra
A26: GUI_SHOW Trang đăng nhập
A27: GUI_LOG_01 | B27: Kiểm tra hiển thị tiêu đề đăng nhập | C27: 1. Mở trang đăng nhập | D27: Truy cập được trang | E27: Hiển thị tiêu đề “Đăng nhập” | F27: Hiển thị đúng tiêu đề đăng nhập | G27: passed | H27: 46114
A28: GUI_LOG_02 | B28: Kiểm tra ô nhập tên đăng nhập/email | C28: 1. Mở trang đăng nhập 2. Quan sát ô Email | D28: Trang load thành công | E28: Có placeholder, text màu đen, hiển thị rõ | F28: Hiển thị đúng placeholder và màu text đen | G28: passed | H28: 46114
A29: GUI_LOG_03 | B29: Kiểm tra ô nhập mật khẩu | C29: 1. Mở trang đăng nhập 2. Quan sát ô Password | D29: Trang load thành công | E29: Có placeholder, text bị ẩn dạng *** | F29: Text nhập vào được mã hóa ẩn dưới dạng dấu *** | G29: passed | H29: 46114
A30: GUI_LOG_04 | B30: Kiểm tra icon hiển thị mật khẩu | C30: 1. Mở trang đăng nhập 2. Click icon mắt | D30: Có dữ liệu trong password | E30: Mật khẩu được hiển thị/ẩn đúng | F30: Icon mắt hoạt động chính xác, chuyển đổi được trạng thái ẩn/hiện | G30: passed | H30: 46114
A31: GUI_LOG_05 | B31: Kiểm tra checkbox “Lưu thông tin đăng nhập” | C31: 1. Mở trang đăng nhập 2. Click checkbox | D31: Trang load | E31: Có thể chọn/bỏ chọn | F31: Checkbox hoạt động nhạy, có thể tick chọn hoặc bỏ chọn | G31: passed | H31: 46114
A32: GUI_LOG_06 | B32: Kiểm tra link “Quên mật khẩu” | C32: 1. Mở trang đăng nhập 2. Click link “Quên mật khẩu” | D32: Trang load | E32: Chuyển sang màn quên mật khẩu | F32: Hệ thống điều hướng đúng về trang quên mật khẩu | G32: passed | H32: 46114
A33: GUI_LOG_07 | B33: Kiểm tra link "Bạn chưa có tài khoản" | C33: 1. Mở trang đăng nhập 2. Click link “Bạn chưa có tài khoản” | D33: Trang load | E33: Chuyển sang màn đăng ký | F33: Hệ thống điều hướng đúng về trang Đăng ký | G33: passed | H33: 46114
A34: GUI_LOG_08 | B34: Kiểm tra button “Đăng nhập” | C34: 1. Mở trang đăng nhập 2. Quan sát button | D34: Trang load | E34: Button hiển thị rõ, enable | F34: Button hiển thị đúng vị trí, có thể tương tác | G34: passed | H34: 46114
A35: GUI_LOG_09 | B35: Kiểm tra button “Google” | C35: 1. Mở trang đăng nhập 2. Quan sát button | D35: Trang load | E35: Button hiển thị đúng màu, enable | F35: Button Google hiển thị đúng màu thương hiệu và có thể click | G35: passed | H35: 46114
A36: GUI_LOG_10 | B36: Kiểm tra card dành tài khoản cho người dùng | C36: 1. Mở popup 2. Quan sát card | D36: Popup hiển thị | E36: Hiển thị đầy đủ icon, text, border xanh | F36: Card hiển thị đúng các thành phần và màu border xanh | G36: passed | H36: 46114
A37: GUI_LOG_11 | B37: Kiểm tra card dành cho tài khoản cửa hàng | C37: 1. Mở popup 2. Quan sát card | D37: Popup hiển thị | E37: Hiển thị icon, text | F37: Các thành phần của card hiển thị rõ | G37: passed | H37: 46114
A38: GUI_LOG_12 | B38: Kiểm tra button đi vào tài khoản | C38: 1. Mở popup 2. Quan sát button | D38: Popup hiển thị | E38: Button màu xanh, text trắng | F38: Màu sắc button và text hiển thị đúng như yêu cầu | G38: passed | H38: 46114
... A42: GUI_LOG_16 | B42: Kiểm tra responsive | C42: 1. Mở trang đăng nhập 2. Thay đổi kích thước màn hình | D42: Trang load | E42: UI không bị vỡ | F42: Layout tổng thể cân đối, không bị vỡ hay chồng lấn | G42: passed | H42: 46114
A43: FUNCTION_SHOW Trang đăng nhập
A44: TC_LOG_17 | B44: Xác nhận đăng nhập thành công khi nhập đúng và đủ thông tin | C44: 1. Nhập tên đăng nhập/email 2. Nhập mật khẩu 3. Click "Đăng nhập" | D44: Người dùng đã có tài khoản | E44: Hệ thống đăng nhập thành công, chuyển đến trang chủ hoặc trang thống kê | F44: Đăng nhập thành công, hệ thống chuyển hướng về Trang chủ/Thống kê đúng như mong đợi | G44: passed | H44: 46114
A45: TC_LOG_18 | B45: Xác nhận thành công khi đăng nhập bằng Google | C45: 1. Click "Đăng nhập với Google" 2. Chọn gmail hợp lệ | D45: Tài khoản Google hợp lệ | E45: Hệ thống đăng nhập thành công, chuyển đến trang chủ | F45: Hệ thống nhận diện đúng tài khoản Google và chuyển màn hình vào trang chủ | G45: passed | H45: 46114
A46: TC_LOG_19 | B46: Xác nhận đăng nhập thành công khi không tick lưu mật khẩu | C46: 1. Nhập email 2. Nhập mật khẩu 3. Không tick "Lưu mật khẩu" 4. Click "Đăng nhập" | D46: Tài khoản đăng nhập hợp lệ | E46: Hệ thống đăng nhập thành công và không lưu mật khẩu | F46: Đăng nhập thành công, sau khi tắt trình duyệt và mở lại, hệ thống yêu cầu đăng nhập lại (không lưu) | G46: passed | H46: 46114
A47: TC_LOG_20 | B47: Hiển thị lỗi khi bỏ trống trường tên đăng nhập/email | C47: 1. Không nhập tên đăng nhập/email 2. Nhập mật khẩu 3. Click "Đăng nhập" | D47: N/A | E47: Hiển thị thông báo "Vui lòng điền vào mục này" | F47: Hiển thị thông báo "Vui lòng điền vào mục này" tại trường Tên đăng nhập | G47: passed | H47: 46114
A48: TC_LOG_21 | B48: Hiển thị lỗi khi nhập tên đăng nhập hoặc email không tồn tại | C48: 1. Nhập tên đăng nhập/email không tồn tại 2. Nhập mật khẩu 3. Click "Đăng nhập" | D48: N/A | E48: Hiển thị thông báo "Tên đăng nhâp/ email không tồn tại" | F48: Thông báo lỗi "Tên đăng nhập/ email không tồn tại" hiển thị đúng định dạng và vị trí | G48: passed | H48: 46114
A49: TC_LOG_22 | B49: Hiển thị lỗi khi nhập email có chứa khoảng trắng | C49: 1. Nhập email có chứa khoảng trắng 2. Nhập mật khẩu 3. Click "Đăng nhập" | D49: N/A | E49: Hiển thị thông báo "Lỗi định dạng" | F49: Hệ thống báo lỗi định dạng khi email chứa khoảng trắng | G49: passed | H49: 46114
A50: TC_LOG_23 | B50: Hiển thị lỗi khi người dùng nhập tên đăng nhập <5 ký tự | C50: 1. Nhập tên đăng nhập/email <5 ký tự 2. Nhập mật khẩu 3. Click "Đăng nhập" | D50: N/A | E50: Hiển thị thông báo "Tên đăng nhập không đúng" | F50: Hiển thị thông báo "Tên đăng nhập không đúng" tại trường tên đăng nhập | G50: passed | H50: 46114
A51: TC_LOG_24 | B51: Hiển thị lỗi khi nhập tên đăng nhập >30 ký tự | C51: 1. Nhập tên đăng nhập/email >30 ký tự 2. Nhập mật khẩu 3. Click "Đăng nhập" | D51: N/A | E51: Hiển thị thông báo "Tên đăng nhập không đúng" | F51: Hiển thị thông báo "Tên đăng nhập không đúng" tại trường tên đăng nhập | G51: passed | H51: 46114
A52: TC_LOG_25 | B52: Hiển thị lỗi khi nhập email có chứa ký tự đặc biệt | C52: 1. Nhập email chứa ký tự đặc biệt khác (!,#,%,...) 2. Nhập mật khẩu 3. Click "Đăng nhập" | D52: N/A | E52: Hiển thị thông báo "Lỗi định dạng" | F52: Hệ thống ngăn chặn và báo lỗi định dạng khi có ký tự đặc biệt trong email | G52: passed | H52: 46114
A53: TC_LOG_26 | B53: Hiển thị lỗi khi nhập email không có user | C53: 1. Nhập email không có user 2. Nhập mật khẩu 3. Click "Đăng nhập" | D53: N/A | E53: Hiển thị thông báo "Lỗi định dạng" | F53: Thông báo "Lỗi định dạng" hiển thị khi thiếu phần định danh người dùng trong email | G53: passed | H53: 46114
A54: TC_LOG_27 | B54: Hiển thị lỗi khi nhập email không có ký tự @ | C54: 1. Nhập email không có @ 2. Nhập mật khẩu 3. Click "Đăng nhập" | D54: N/A | E54: Hiển thị thông báo "Lỗi định dạng" | F54: Báo lỗi định dạng chính xác khi thiếu ký tự "@" | G54: passed | H54: 46114
A55: TC_LOG_28 | B55: Hiển thị lỗi khi nhập email không có domain | C55: 1. Nhập email không có domain 2. Nhập mật khẩu 3. Click "Đăng nhập" | D55: N/A | E55: Hiển thị thông báo "Lỗi định dạng" | F55: Báo lỗi định dạng chính xác khi thiếu phần domain (ví dụ: @gmail.com) | G55: passed | H55: 46114
... A59: TC_LOG_32 | B59: Hiển thị lỗi khi nhập mật khẩu không chính xác | C59: 1. Nhập tên đăng nhập/email 2. Nhập mật khẩu không đúng 3. Click "Đăng nhập" | D59: Tài khoản đăng nhập tồn tại trong hệ thống | E59: Hiển thị thông báo "Sai mật khẩu" | F59: Thông báo "Sai mật khẩu" hiển thị ngay sau khi nhấn đăng nhập với mật khẩu không đúng | G59: passed | H59: 46114
A60: TC_LOG_33 | B60: Kiểm tra lỗi hiễn thị khi nhập sai mật khẩu quá 5 lần | C60: 1. Nhập tên đăng nhập/email 2. Nhập mật khẩu sai 5 lần liên tiếp 3. Click "Đăng nhập" | D60: N/A | E60: Hệ thống khóa tài khoản tạm thời | F60: Sau 5 lần sai, hệ thống vẫn cho phép tiếp tục thao tác đăng nhập | G60: failed | H60: 46114 | I60: passed | J60: 46117
A61: TC_LOG_34 | B61: Xác nhận thành công khi tick vào lưu mật khẩu | C61: 1. Nhập email 2. Nhập mật khẩu 3. Tick "Lưu mật khẩu" 4. Click "Đăng nhập" | D61: N/A | E61: Hệ thống lưu thông tin đăng nhập cho lần sau | F61: Đăng nhập thành công, hệ thống tự động điền thông tin đăng nhập trong lần truy cập sau | G61: passed | H61: 46114
A62: TC_LOG_35 | B62: Kiểm tra lỗi hiển thị khi đăng nhập bằng google account chưa đăng ký | C62: 1. Click "Đăng nhập với Google" 2. Chọn gmail chưa đăng ký | D62: N/A | E62: Hiển thị thông báo "Không tìm thấy tài khoản Google của bạn" | F62: Hiển thị đúng thông báo không tìm thấy tài khoản đối với email Google chưa đăng ký hệ thống | G62: passed | H62: 46114
...

Sheet Đăng ký
A1: Project Name | B1: XÂY DỰNG HỆ THỐNG DISHNET - NỀN TẢNG MẠNG XÃ HỘI KINH DOANH ẨM THỰC
A2: Module Code | B2: Đăng ký
A3: Người kiểm tra | B3: Phạm Đình Vân Ly
B4: Hoàn thành | C4: Lỗi | D4: Chưa kiểm tra | E4: Bị chăn | F4: Tổng số trường hợp thử nghiệm
A5: Round 1 | B5: =COUNTIF(G27:G1056,"passed") -> 66 | C5: =COUNTIF(G27:G1056,"failed") -> 0 | D5: =COUNTIF(H27:H1056,"untest") -> 0 | E5: =COUNTIF(G27:G1056,"blocked") -> 0 | F5: =COUNTIF(A23:A1052, "*REG*") -> 66
A6: Round 2 | B6: =COUNTIF(I27:I1057,"passed") -> 0 | C6: =COUNTIF(G27:G1056,"failed") -> 0 | D6: =COUNTIF(G27:G1056,"untest") -> 0 | E6: =COUNTIF(G27:G1056,"blocked") -> 0 | F6: =COUNTIF(A24:A1053, "*REG*") -> 66
A23: Test Case ID | B23: Mô tả | C23: Hành động | D23: Điều kiện tiên quyết | E23: Kết quả mong đợi | F23: Kết quả thực tế | G23: Kết quả | I23: Kết quả | K23: Chú thích
G24: Vòng 1 | I24: Vòng 2
G25: Trạng thái | H25: Ngày kiểm tra | I25: Trạng thái | J25: Ngày kiểm tra
A26: GUI_SHOW Trang đăng ký
A27: GUI_REG_01 | B27: Kiểm tra tiêu đề “Đăng ký” | C27: 1. Mở trang đăng ký | D27: Truy cập trang | E27: Hiển thị tiêu đề “Đăng ký” | F27: Tiêu đề "Đăng ký" hiển thị đúng font chữ và vị trí thiết kế | G27: passed | H27: 46114
A28: GUI_REG_02 | B28: Kiểm tra ô email | C28: 1. Mở trang đăng ký 2. Quan sát ô email | D28: Trang load | E28: Có placeholder, text màu đen | F28: Ô nhập email hiển thị đúng placeholder, text nhập vào có màu đen rõ ràng | G28: passed | H28: 46114
A29: GUI_REG_03 | B29: Kiểm tra ô số điện thoại | C29: 1. Mở trang đăng ký 2. Quan sát ô số điện thoại | D29: Trang load | E29: Có placeholder, text màu đen | F29: Ô số điện thoại hiển thị đúng placeholder và định dạng text | G29: passed | H29: 46114
A30: GUI_REG_04 | B30: Kiểm tra ô tên hiển thị | C30: 1. Mở trang đăng ký 2. Quan sát ô tên hiển thị | D30: Trang load | E30: Có placeholder, text màu đen | F30: Ô tên hiển thị hiển thị placeholder và màu chữ khớp với thiết kế | G30: passed | H30: 46114
A31: GUI_REG_05 | B31: Kiểm tra ô khu vực/địa chỉ | C31: 1. Mở trang đăng ký 2. Quan sát ô khu vực/ địa chỉ | D31: Trang load | E31: Có placeholder, text màu đen | F31: Ô khu vực/địa chỉ hiển thị đúng placeholder và màu text đen | G31: passed | H31: 46114
A32: GUI_REG_06 | B32: Kiểm tra ô mật khẩu | C32: 1. Mở trang đăng ký 2. Quan sát ô mật khẩu | D32: Trang load | E32: Có placehoder, text bị ẩn dạng *** | F32: Mật khẩu khi nhập tự động chuyển sang dạng dấu * để bảo mật | G32: passed | H32: 46114
A33: GUI_REG_07 | B33: Kiểm tra ô xác nhận mật khẩu | C33: 1. Mở trang đăng ký 2. Quan sát ô xác nhận mật khẩu | D33: Trang load | E33: Có placehoder, text bị ẩn dạng *** | F33: Xác nhận mật khẩu hiển thị đúng dạng ẩn *** như ô mật khẩu | G33: passed | H33: 46114
A34: GUI_REG_08 | B34: Kiểm tra icon hiển thị mật khẩu | C34: 1. Mở trang đăng ký 2.Click icon mắt | D34: Có dữ liệu trong password | E34: Toggle hiển thị/ẩn | F34: Icon mắt hoạt động tốt, cho phép chuyển đổi giữa ẩn và hiện mật khẩu | G34: passed | H34: 46114
A35: GUI_REG_09 | B35: Kiểm tra button “Đăng ký” | C35: 1. Mở trang đăng ký 2. Quan sát ô button | D35: Trang load | E35: Button màu xanh, enable | F35: Button "Đăng ký" hiển thị đúng màu xanh chủ đạo và có thể tương tác | G35: passed | H35: 46114
A36: GUI_REG_10 | B36: Kiểm tra link đăng nhập | C36: 1. Mở trang đăng ký 2. Click vào link đăng nhập | D36: Trang load | E36: Chuyển màn hình đến trang đăng nhập | F36: Hệ thống điều hướng chính xác về trang đăng nhập khi click vào link | G36: passed | H36: 46114
A37: GUI_REG_11 | B37: Kiểm tra ô nhập OTP | C37: 1. Mở trang xác thực OTP 2. Quan sát ô nhập mã OTP | D37: N/A | E37: Input hiển thị đúng | F37: Các ô nhập mã OTP hiển thị rõ ràng, cho phép nhập ký tự số | G37: passed | H37: 46114
A38: GUI_REG_12 | B38: Kiểm tra button “Gửi lại mã” | C38: 1. Mở trang xác thực OTP 2. Quan sát button | D38: Đã gửi OTP | E38: Button hiển thị đúng, enable | F38: Button "Gửi lại mã" hiển thị đúng vị trí và có thể nhấn được | G38: passed | H38: 46114
... A44: GUI_REG_18 | B44: Kiểm tra responsive | C44: 1. Mở trang đăng ký 2. Thay đổi kích thước màn hình | D44: Trang load | E44: Không vỡ layout | F44: Giao diện tự động co giãn, không bị vỡ hay chồng lấn khi thay đổi kích thước màn hình | G44: passed | H44: 46114
A45: FUNCTION_SHOW Trang đăng ký
A46: TC_REG_19 | B46: Xác nhận đăng ký thành công khi nhập đúng và đầy đủ thông tin | C46: 1. Nhập email hợp lệ 2. Nhập số điện thoại hợp lệ 3. Nhập tên hiển thị hợp lệ 4. Nhập khu vực 5. Nhập mật khẩu hợp lệ 6. Nhập xác nhận mật khẩu đúng 7. Click "Đăng ký" | D46: Email/ số điện thoại chưa tồn tại trong hệ thống | E46: Hệ thống đăng ký thành công, chuyển sang màn hình OTP | F46: Đăng ký thành công, hệ thống chuyển sang giao diện nhập mã OTP đúng quy trình | G46: passed | H46: 46114
A47: TC_REG_20 | B47: Xác nhận hiển thị đúng khi copy-paste email hợp lệ | C47: 1. Paste email hợp lệ 2. Nhập đầy đủ các trường còn lại 3. Click "Đăng ký" | D47: N/A | E47: Hệ thống chấp nhận | F47: Hệ thống chấp nhận email được dán vào và cho phép thực hiện các bước tiếp theo | G47: passed | H47: 46114
A48: TC_REG_21 | B48: Hiển thị lỗi khi bỏ trống trường email | C48: 1. Không nhập email 2. Nhập đầy đủ các trường còn lại 3. Click "Đăng ký" | D48: N/A | E48: Hiển thị thông báo "Vui lòng điền vào mục này" | F48: Xuất hiện thông báo "Vui lòng điền vào mục này" ngay dưới trường email còn trống | G48: passed | H48: 46114
A49: TC_REG_22 | B49: Hiển thị lỗi khi nhập email không có user | C49: 1. Nhập email thiếu user 2. Click "Đăng ký" | D49: N/A | E49: Hiển thị thông báo "Lỗi định dạng" | F49: Hiển thị thông báo "Lỗi định dạng" do thiếu phần định danh người dùng trong email | G49: passed | H49: 46114
A50: TC_REG_23 | B50: Hiển thị lỗi khi nhập email không có @ | C50: 1. Nhập email thiếu @ 2. Click "Đăng ký" | D50: N/A | E50: Hiển thị thông báo "Lỗi định dạng" | F50: Hệ thống báo "Lỗi định dạng" khi phát hiện email không có ký tự @ | G50: passed | H50: 46114
A51: TC_REG_24 | B51: Hiển thị lỗi khi nhập email không có domain | C51: 1. Nhập email thiếu domain 2. Click "Đăng ký" | D51: N/A | E51: Hiển thị thông báo "Lỗi định dạng" | F51: Hệ thống báo "Lỗi định dạng" khi phát hiện thiếu phần domain (ví dụ: @gmail.com) | G51: passed | H51: 46114
A52: TC_REG_25 | B52: Hiển thị lỗi khi nhập email đã tồn tại | C52: 1. Nhập email đã đăng ký 2. Click "Đăng ký" | D52: Email đã tồn tại | E52: Hiển thị thông báo "Email đã tồn tại" | F52: Hệ thống báo lỗi "Email đã tồn tại" và ngăn chặn việc tạo tài khoản trùng lặp | G52: passed | H52: 46114
A53: TC_REG_26 | B53: Hiển thị lỗi khi nhập email có khoảng trắng | C53: 1. Nhập email có khoảng trắng 2. Click "Đăng ký" | D53: N/A | E53: Hiển thị thông báo "Lỗi định dạng" | F53: Hiển thị thông báo lỗi định dạng khi email có chứa khoảng trắng giữa các ký tự | G53: passed | H53: 46114
A54: TC_REG_27 | B54: Hiển thị lỗi khi nhập email có chứa ký tự đặc biệt khác | C54: 1. Nhập email chứa ký tự đặc biệt khác (!,#,%,...) 2. Click "Đăng ký" | D54: N/A | E54: Hiển thị thông báo "Lỗi định dạng" | F54: Hệ thống ngăn chặn đăng ký và báo lỗi khi email chứa các ký tự đặc biệt không hợp lệ | G54: passed | H54: 46114
A55: TC_REG_28 | B55: Hiển thị lỗi khi bỏ trống trường số điện thoại | C55: 1. Không nhập số điện thoại 2. Nhập đầy đủ các trường còn lại 3. Click "Đăng ký" | D55: N/A | E55: Hiển thị thông báo "Vui lòng điền vào mục này" | F55: Hiển thị thông báo "Vui lòng điền vào mục này" tại trường số điện thoại | G55: passed | H55: 46114
A56: TC_REG_29 | B56: Xác nhận hiển thị đúng khi nhập số điện thoại =10 và bắt đầu bằng số 0 | C56: 1. Nhập số điện thoại hợp lệ 2. Click "Đăng ký" | D56: N/A | E56: Hệ thống chấp nhận | F56: Hệ thống chấp nhận số điện thoại bắt đầu bằng số 0 và đủ 10 chữ số | G56: passed | H56: 46114
A57: TC_REG_30 | B57: Xác nhận hiển thị đúng khi copy-paste số điện thoại hợp lệ | C57: 1. Paste số điện thoại hợp lệ 2. Click "Đăng ký" | D57: N/A | E57: Hệ thống chấp nhận | F57: Thao tác copy-paste số điện thoại hoạt động đúng, hệ thống nhận diện đúng dữ liệu | G57: passed | H57: 46114
... A78: TC_REG_51 | B78: Kiểm tra hiển thị đúng khi nhấn enter để đăng ký | C78: 1. Nhập đầy đủ thông tin 2. Nhấn Enter | D78: N/A | E78: Hệ thống thực hiện đăng ký | F78: Lệnh đăng ký được thực thi ngay lập tức khi nhấn phím Enter trên bàn phím | G78: passed | H78: 46114
A79: FUNCTION_SHOW Trang xác thực OTP
A80: TC_REG_52 | B80: Xác nhận đăng ký thành công khi nhập OTP đúng | C80: 1. Nhập OTP đúng 2. Click "Gửi" | D80: Đã đăng ký thành công | E80: Hệ thống thông báo xác thực thành công, hiển thị nút đăng nhập | F80: Mã OTP đúng được chấp nhận, hệ thống hiển thị nút để người dùng tiếp tục đăng nhập | G80: passed | H80: 46114
A81: TC_REG_53 | B81: Hiển thị lỗi khi không nhập OTP | C81: 1. Không nhập OTP 2. Click "Gửi" | D81: Đã gửi OTP | E81: Hiển thị thông báo "Vui lòng nhập đầy đủ mã xác nhận" | F81: Thông báo lỗi hiển thị rõ ràng khi người dùng nhấn gửi mà chưa nhập mã OTP | G81: passed | H81: 46114
...

Sheet Quên mật khẩu
A1: Project Name | B1: XÂY DỰNG HỆ THỐNG DISHNET - NỀN TẢNG MẠNG XÃ HỘI KINH DOANH ẨM THỰC
A2: Module Code | B2: Quên mật khẩu
A3: Người kiểm tra | B3: Huỳnh Thị Vy
B4: Hoàn thành | C4: Lỗi | D4: Chưa kiểm tra | E4: Bị chăn | F4: Tổng số trường hợp thử nghiệm
A5: Round 1 | B5: =COUNTIF(G27:G1033,"passed") -> 53 | C5: =COUNTIF(G27:G1033,"failed") -> 2 | D5: =COUNTIF(H27:H1033,"untest") -> 0 | E5: =COUNTIF(G27:G1033,"blocked") -> 0 | F5: =COUNTIF(A23:A1029, "*FP*") -> 55
A6: Round 2 | B6: =COUNTIF(I27:I1034,"passed") -> 2 | C6: =COUNTIF(I27:I1033,"failed") -> 0 | D6: =COUNTIF(G27:G1033,"untest") -> 0 | E6: =COUNTIF(G27:G1033,"blocked") -> 0 | F6: =COUNTIF(A24:A1030, "*FP*") -> 55
A23: Test Case ID | B23: Mô tả | C23: Hành động | D23: Điều kiện tiên quyết | E23: Kết quả mong đợi | F23: Kết quả thực tế | G23: Kết quả | I23: Kết quả | K23: Chú thích
G24: Vòng 1 | I24: Vòng 2
G25: Trạng thái | H25: Ngày kiểm tra | I25: Trạng thái | J25: Ngày kiểm tra
A26: GUI_SHOW Trang quên mật khẩu
A27: GUI_FP_01 | B27: Kiểm tra tiêu đề “Quên mật khẩu” | C27: 1. Mở màn hình quên mật khẩu | D27: Truy cập trang | E27: Hiển thị tiêu đề rõ ràng | F27: Tiêu đề "Quên mật khẩu" hiển thị đúng font chữ, vị trí và dễ quan sát | G27: passed | H27: 46114
A28: GUI_FP_02 | B28: Kiểm tra ô nhập email | C28: 1. Mở màn hình quên mật khẩu 2. Quan sát ô nhập email | D28: Trang load | E28: Có placeholder, text màu đen | F28: Ô nhập email hiển thị đúng placeholder, text nhập vào có màu đen rõ ràng | G28: passed | H28: 46114
A29: GUI_FP_03 | B29: Kiểm tra button "Gửi" email | C29: 1. Mở màn hình quên mật khẩu 2. Quan sát button | D29: Trang load | E29: Có màu xanh, enable | F29: Button hiển thị màu xanh và đúng vị trí, có thể nhấn được | G29: passed | H29: 46114
A30: GUI_FP_04 | B30: Kiểm tra link "Bạn chưa có tài khoản" | C30: 1. Mở màn hình quên mật khẩu 2. Click vào "Bạn chưa có tài khoản" | D30: Trang load | E30: Chuyển màn hình đến trang đăng ký | F30: Hệ thống điều hướng chính xác về trang đăng ký khi nhấn vào link | G30: passed | H30: 46114
A31: GUI_FP_05 | B31: Kiểm tra ô nhập OTP | C31: 1. Mở màn hình xác thực OTP 2. Quan sát ô nhập OTP | D31: Đã gửi OTP | E31: Ô input hiển thị đúng | F31: Các ô nhập mã OTP hiển thị rõ ràng, căn chỉnh đều và dễ nhìn | G31: passed | H31: 46114
A32: GUI_FP_06 | B32: Kiểm tra thời gian OTP | C32: 1. Mở màn hình xác thực OTP 2. Quan sát thời gian hiển thị | D32: Đã gửi OTP | E32: Hiển thị thời gian (01:00) | F32: Thời gian đếm ngược (60s) bắt đầu chạy ngay khi mã được gửi thành công | G32: passed | H32: 46114
A33: GUI_FP_07 | B33: Kiểm tra button “Gửi lại mã” | C33: 1. Mở trang xác thực OTP 2. Quan sát button | D33: Đã gửi OTP | E33: Button hiển thị đúng, enable | F33: Button "Gửi lại mã" hiển thị đúng vị trí và có thể tương tác | G33: passed | H33: 46114
A34: GUI_FP_08 | B34: Kiểm tra button “Gửi” OTP | C34: 1. Mở màn hình xác thực OTP 2. Quan sát button | D34: Đã nhập OTP | E34: Button màu xanh, enable | F34: Button "Gửi" tại màn hình OTP hiển thị đúng màu xanh và sẵn sàng click | G34: passed | H34: 46114
A35: GUI_FP_09 | B35: Kiểm tra ô mật khẩu mới | C35: 1. Mở màn hình đổi mật khẩu 2. Quan sát ô nhập mật khẩu mới | D35: OTP đúng | E35: Có placehoder, text bị ẩn dạng *** | F35: Ô mật khẩu mới hiển thị đúng placeholder, ký tự nhập vào tự động ẩn thành dấu * | G35: passed | H35: 46114
A36: GUI_FP_10 | B36: Kiểm tra ô xác nhận mật khẩu | C36: 1. Mở màn hình đổi mật khẩu 2. Quan sát ô nhập xác nhận mật khẩu mới | D36: OTP đúng | E36: Có placehoder, text bị ẩn dạng *** | F36: Ô xác nhận mật khẩu mới hiển thị đúng dạng ẩn để bảo mật thông tin | G36: passed | H36: 46114
A37: GUI_FP_11 | B37: Kiểm tra icon ẩn hiển mật khẩu | C37: 1. Mở màn hình đổi mật khẩu 2. Click icon mắt | D37: Có dữ liệu | E37: Toggle hiển thị/ ẩn | F37: Icon mắt hoạt động chính xác, cho phép người dùng xem hoặc ẩn mật khẩu | G37: passed | H37: 46114
A38: GUI_FP_12 | B38: Kiểm tra button “Đặt lại” | C38: 1. Mở màn hình đổi mật khẩu 2. Quan sát button | D38: Trang load | E38: Button màu xanh, enable | F38: Button "Đặt lại" hiển thị đúng màu thương hiệu và có thể nhấn được | G38: passed | H38: 46114
... A42: GUI_FP_16 | B42: Kiểm tra layout tổng thể | C42: 1. Mở màn hình 2. Thay đổi kích thước màn hình | D42: Trang load | E42: Các thành phần căn đều, không vỡ layout | F42: Layout tổng thể trang Quên mật khẩu cân đối, co giãn tốt theo kích thước màn hình | G42: passed | H42: 46114
A43: FUNCTION_SHOW Trang quên mật khẩu
A44: TC_FP_17 | B44: Xác nhận gửi email thành công khi nhập email hợp lệ | C44: 1. Nhập email đã đăng ký 2. Click "Gửi" | D44: Email tồn tại trong hệ thống | E44: Hệ thống gửi mã OTP về email | F44: Hệ thống gửi email chứa mã OTP thành công về địa chỉ đã đăng ký | G44: passed | H44: 46114
A45: TC_FP_18 | B45: Hiển thị lỗi khi bỏ trống trường email | C45: 1. Không nhập email 2. Click "Gửi" | D45: N/A | E45: Hiển thị thông báo "Vui lòng điền vào mục này" | F45: Xuất hiện thông báo "Vui lòng điền vào mục này" khi nhấn Gửi mà để trống email | G45: passed | H45: 46114
A46: TC_FP_19 | B46: Hiển thị lỗi khi nhập email không có user | C46: 1. Nhập email thiếu user 2. Click "Gửi" | D46: N/A | E46: Hiển thị thông báo "Lỗi định dạng" | F46: Hiển thị thông báo "Lỗi định dạng" do thiếu phần định danh người dùng trong email | G46: passed | H46: 46114
A47: TC_FP_20 | B47: Hiển thị lỗi khi nhập email không có @ | C47: 1. Nhập email thiếu @ 2. Click "Gửi" | D47: N/A | E47: Hiển thị thông báo "Lỗi định dạng" | F47: Báo "Lỗi định dạng" chính xác khi người dùng nhập email không có ký tự @ | G47: passed | H47: 46114
A48: TC_FP_21 | B48: Hiển thị lỗi khi nhập email không có domain | C48: 1. Nhập email thiếu domain 2. Click "Gửi" | D48: N/A | E48: Hiển thị thông báo "Lỗi định dạng" | F48: Báo "Lỗi định dạng" khi email thiếu phần tên miền (domain) | G48: passed | H48: 46114
A49: TC_FP_22 | B49: Hiển thị lỗi khi nhập email có ký tự đặc biệt khác | C49: 1. Nhập email chứa ký tự đặt biệt khác (!,#,%...) 2. Click "Gửi" | D49: N/A | E49: Hiển thị thông báo "Lỗi định dạng" | F49: Hệ thống báo lỗi khi phát hiện ký tự đặc biệt không hợp lệ trong email | G49: passed | H49: 46114
A50: TC_FP_23 | B50: Hiển thị lỗi khi nhập email có khoảng trắng | C50: 1. Nhập email có khoảng trắng 2. Click "Gửi" | D50: N/A | E50: Hiển thị thông báo "Lỗi định dạng" | F50: Hiển thị thông báo lỗi định dạng do email chứa khoảng trắng | G50: passed | H50: 46114
A51: TC_FP_24 | B51: Hiển thị lỗi khi nhập email không tồn tại | C51: 1. Nhập email chưa đăng ký 2. Click "Gửi" | D51: N/A | E51: Hiển thị thông báo "Emai không tồn tại" | F51: Thông báo "Email không tồn tại" hiển thị đúng khi nhập email chưa đăng ký | G51: passed | H51: 46114
A52: TC_FP_25 | B52: Hiển thị lỗi khi nhập sai email quá 5 lần | C52: 1. Nhập email sai quá 5 lần 2. Click "Gửi" nhiều lần | D52: N/A | E52: Hệ thống khóa tạm thời | F52: Sau 5 lần nhập sai liên tiếp, hệ thống thông báo khóa chức năng gửi mail tạm thời | G52: passed | H52: 46114
A53: TC_FP_26 | B53: Kiểm tra khi click vào nút gửi nhiều lần liên tục | C53: 1. Nhập email hợp lệ 2. Click "Gửi" liên tục | D53: N/A | E53: Hệ thống chỉ xử lý 1 yêu cầu đầu tiên | F53: Hệ thống xử lý ổn định, chỉ gửi 01 email duy nhất dù người dùng nhấn nút liên tục | G53: passed | H53: 46114
A54: TC_FP_27 | B54: Kiểm tra hiển thị đúng khi nhấn enter để gửi | C54: 1. Nhập email hợp lệ 2. Nhấn Enter | D54: N/A | E54: Hệ thống chấp nhận và gửi mã OTP về email | F54: Lệnh gửi mã OTP được thực thi ngay sau khi người dùng nhấn phím Enter | G54: passed | H54: 46114
A55: TC_FP_28 | B55: Xác nhận xác thực thành công khi nhập đúng mã OTP | C55: 1. Nhập OTP đúng 2. Click "Gửi" | D55: Đã nhận OTP | E55: Hệ thống xác thực thành công, chuyển màn hình sang trang đặt lại mật khẩu | F55: Mã OTP đúng được chấp nhận, hệ thống tự động chuyển sang trang đặt lại mật khẩu | G55: passed | H55: 46114
... A64: TC_FP_37 | B64: Hiển thị lỗi khi nhập mã OTP bằng ký tự chữ hoặc ký tự đặc biệt | C64: 1. Nhập OTP chữ 2. Click "Gửi" | D64: Đã gửi OTP | E64: Hệ thống chặn không cho phép nhập chữ hoặc ký tự đặc biệt | F64: Ô nhập mã OTP chặn hoàn toàn việc nhập ký tự chữ hoặc ký tự đặc biệt | G64: passed | H64: 46114
A65: TC_FP_38 | B65: Hiển thị lỗi khi nhập mã OTP sai quá 5 lần | C65: 1. Nhập OTP sai quá 5 lần 2. Click "Gửi" | D65: Đã gửi OTP | E65: Hệ thống khóa tạm thời | F65: Hệ thống không thực hiện khóa tài khoản/chức năng sau khi nhập sai OTP quá 5 lần | G65: failed | H65: 46114 | I65: passed | J65: 46118
A66: TC_FP_39 | B66: Kiểm tra hiển thị đúng khi nhấn enter để gửi OTP | C66: 1. Nhập OTP 2. Nhấn Enter | D66: Đã gửi OTP | E66: Hệ thống xác thực thành công, chuyển màn hình sang trang đặt lại mật khẩu | F66: Hệ thống thực hiện xác thực và chuyển trang ngay khi nhấn phím Enter | G66: passed | H66: 46114
A67: TC_FP_40 | B67: Xác nhận đổi mật khẩu thành công khi nhập mật khẩu mới hợp lệ | C67: 1. Nhập mật khẩu mới 2. Xác nhận lại mật khẩu mới 3. Click "Đặt lại" | D67: Đã xác thực OTP | E67: Hệ thống cập nhật mật khẩu mới và cho phép đăng nhập vào hệ thống | F67: Mật khẩu được cập nhật thành công, hệ thống thông báo và cho phép đăng nhập lại | G67: passed | H67: 46114
...

Sheet Thống kê hệ thống
A1: Project Name | B1: XÂY DỰNG HỆ THỐNG DISHNET - NỀN TẢNG MẠNG XÃ HỘI KINH DOANH ẨM THỰC
A2: Module Code | B2: Thống kê hệ thống
A3: Người kiểm tra | B3: Trần Thị Mai Yên, Phan Thị Lệ Thi
B4: Hoàn thành | C4: Lỗi | D4: Chưa kiểm tra | E4: Bị chăn | F4: Tổng số trường hợp thử nghiệm
A5: Round 1 | B5: =COUNTIF(G27:G1063,"passed") -> 63 | C5: =COUNTIF(G38:G1063,"failed") -> 5 | D5: =COUNTIF(H38:H1063,"untest") -> 0 | E5: =COUNTIF(G38:G1063,"blocked") -> 0 | F5: =COUNTIF(A23:A1059, "*DB*") -> 68
A6: Round 2 | B6: =COUNTIF(I27:I1064,"passed") -> 5 | C6: =COUNTIF(G38:G1063,"failed") -> 5 | D6: =COUNTIF(G38:G1063,"untest") -> 0 | E6: =COUNTIF(G38:G1063,"blocked") -> 0 | F6: =COUNTIF(A24:A1060, "*DB*") -> 68
A23: Test Case ID | B23: Mô tả | C23: Hành động | D23: Điều kiện tiên quyết | E23: Kết quả mong đợi | F23: Kết quả thực tế | G23: Kết quả | I23: Kết quả | K23: Chú thích
G24: Vòng 1 | I24: Vòng 2
G25: Trạng thái | H25: Ngày kiểm tra | I25: Trạng thái | J25: Ngày kiểm tra
A26: GUI_SHOW Trang thống kê hệ thống
A27: GUI_DB_01 | B27: Kiểm tra hiển thị sidebar | C27: 1. Mở trang dashboard | D27: Đã login | E27: Sidebar hiển thị | F27: Sidebar hiển thị đúng sau khi đăng nhập, không lỗi giao diện | G27: passed | H27: 46114
A28: GUI_DB_02 | B28: Kiểm tra highlight menu hiện tại | C28: 1. Mở trang dashboard 2. Quan sát menu | D28: Trang thống kê | E28: Menu "Thống kê" đổi màu | F28: Menu “Thống kê” được highlight (đổi màu) đúng khi truy cập trang | G28: passed | H28: 46114
A29: GUI_DB_03 | B29: Kiểm tra khi click menu khác | C29: 1. Mở trang dashboard 2. Click item | D29: Trang load | E29: Điều hướng đúng | F29: Click các menu khác điều hướng đúng trang, không bị reload lỗi | G29: passed | H29: 46114
A30: GUI_DB_04 | B30: Kiểm tra bộ lọc thời gian | C30: 1. Mở trang dashboard 2. Quan sát bộ lọc | D30: Trang load | E30: Có: Hôm nay, 7 ngày, 30 ngày, Tùy chọn | F30: Bộ lọc thời gian hiển thị đầy đủ các tùy chọn (Hôm nay, 7 ngày, 30 ngày, Tùy chọn) và hoạt động bình thường | G30: passed | H30: 46114
A31: GUI_DB_05 | B31: Kiểm tra highlight tab | C31: 1. Mở trang dashboard 2. Click tab | D31: Trang load | E31: Tab được chọn highlight | F31: Tab được chọn hiển thị highlight rõ ràng, đúng trạng thái active | G31: passed | H31: 46114
A32: GUI_DB_06 | B32: Kiểm tra dropdown tùy chọn | C32: 1. Mở trang dashboard 2. Click "tùy chọn" | D32: Trang load | E32: Hiển thị date picker | F32: Dropdown “Tùy chọn” mở và hiển thị date picker chính xác | G32: passed | H32: 46114
A33: GUI_DB_07 | B33: Kiểm tra input ngày | C33: 1. Click "Tùy chọn" 2. Chọn ngày | D33: Date picker mở | E33: Hiển thị ngày đúng format | F33: Date picker hoạt động, chọn ngày và hiển thị đúng định dạng | G33: passed | H33: 46114
A34: GUI_DB_08 | B34: Kiểm tra button "Áp dụng" | C34: 1. Mở trang dashboard 2. Quan sát button | D34: Date picker | E34: Có màu xanh, enable | F34: Button “Áp dụng” hiển thị màu xanh, trạng thái enable và click hoạt động | G34: passed | H34: 46114
A35: GUI_DB_09 | B35: Kiểm tra button "Hủy" | C35: 1. Mở trang dashboard 2. Quan sát button | D35: Date picker | E35: Có màu trắng, enable | F35: Button “Hủy” hiển thị màu trắng, trạng thái enable và click hoạt động | G35: passed | H35: 46114
A36: GUI_DB_10 | B36: Kiểm tra hiển thị card | C36: 1. Mở trang dashboard 2. Quan sát card | D36: Trang load | E36: có 4 card thông kê dữ liệu | F36: Hiển thị đầy đủ 4 card thống kê, dữ liệu load thành công | G36: passed | H36: 46114
A37: GUI_DB_11 | B37: Kiểm tra giá trị số | C37: 1. Mở trang dashboard 2. Quan sát | D37: Có data | E37: Hiển thị rõ, dữ liệu không chồng nhau | F37: Giá trị số hiển thị rõ ràng, không bị chồng lấp hoặc sai định dạng | G37: passed | H37: 46114
A38: GUI_DB_12 | B38: Kiểm tra link “Xem tất cả” | C38: 1. Mở trang dashboard 2. Quan sát | D38: Trang load | E38: Điều hường đúng trang | F38: Link “Xem tất cả” điều hướng đúng trang mong đợi | G38: passed | H38: 46114
... A40: GUI_DB_14 | B40: Responsive card | C40: Resize màn hình | D40: Trang load | E40: Không vỡ layout | F40: Giao diện responsive tốt khi resize màn hình, không vỡ layout | G40: passed | H40: 46114
A41: FUNCTION_SHOW Trang thống kê hệ thống
A42: TC_DB_15 | B42: Xác nhận đăng nhập thành công khi truy cập bằng tài khoản admin | C42: 1. Đăng nhập bằng tài khoản admin | D42: Admin đăng nhập hợp lệ | E42: Đăng nhập thành công vào hệ thống, chuyển màn hình đến trang thống kê | F42: Đăng nhập admin thành công, hệ thống chuyển đúng đến trang thống kê | G42: passed | H42: 46114
A43: TC_DB_16 | B43: Xác nhận thành công chặn các truy cập khi vào trực tiếp mà không đăng nhập | C43: 1. Truy cập URL thống kê 2. Không đăng nhập | D43: Chưa đăng nhập | E43: Hệ thống chuyển màn hình về trang đăng nhập | F43: Khi chưa đăng nhập, truy cập URL bị chuyển về trang đăng nhập | G43: passed | H43: 46114
A44: TC_DB_17 | B44: Xác nhận hiển thị đúng các số liệu trong box thống kê về số người dùng, cửa hàng, đơn hàng và doanh thu trong ngày | C44: 1. Đăng nhập bằng tài khoản admin 2. Quan sát trang thống kê | D44: Admin đăng nhập hợp lệ | E44: Hệ thống hiển thị đúng và đủ dữ liệu thống kê | F44: Hiển thị đầy đủ dữ liệu thống kê ( người dùng, cửa hàng, đơn hàng và doanh thu trong ngày) | G44: passed | H44: 46114
A45: TC_DB_18 | B45: Hiển thị lỗi khi người dùng không phải admin truy cập | C45: 1. Đăng nhập user thường 2. Truy cập trang thống kê | D45: User thường | E45: Không có quyền truy cập | F45: User thường không thể truy cập, hệ thống chặn đúng | G45: passed | H45: 46114
A46: TC_DB_19 | B46: Xác nhận hiển thị đúng khi lọc hôm nay | C46: 1. Chọn "Hôm nay" 2. Kiểm tra dữ liệu | D46: Có dữ liệu | E46: Hiển thị dữ liệu ngày hiện tại | F46: Bộ lọc “Hôm nay” hiển thị đúng dữ liệu ngày hiện tại | G46: passed | H46: 46114
A47: TC_DB_20 | B47: Xác nhận hiển thị đúng khi lọc 7 ngày | C47: 1. Chọn "7 ngày" 2. Kiểm tra dữ liệu | D47: Có dữ liệu | E47: Hiển thị dữ liệu 7 ngày gần nhất | F47: Bộ lọc “7 ngày” hiển thị đúng dữ liệu 7 ngày gần nhất | G47: passed | H47: 46114
A48: TC_DB_21 | B48: Xác nhận hiển thị đúng khi lọc 30 ngày | C48: 1. Chọn "30 ngày" 2. Kiểm tra dữ liệu | D48: Có dữ liệu | E48: Hiển thị dữ liệu 30 ngày gần nhất | F48: Bộ lọc “30 ngày” hiển thị đúng dữ liệu 30 ngày gần nhất | G48: passed | H48: 46114
A49: TC_DB_22 | B49: Xác nhận hiển thị đúng khi lọc tùy chọn | C49: 1. Chọn từ ngày 2. Chọn đến ngày 3. Áp dụng | D49: N/A | E49: Hiển thị đúng dữ liệu khoảng ngày đã chọn | F49: Bộ lọc tùy chọn hiển thị đúng dữ liệu theo khoảng ngày đã chọn | G49: passed | H49: 46114
A50: TC_DB_23 | B50: Hiển thị lỗi khi chọn ngày bắt đầu > ngày hiện tại | C50: 1. Chọn ngày bắt đầu > hôm nay 2. Áp dụng | D50: N/A | E50: Hệ thống chặn không cho phép chọn | F50: Hệ thống chặn đúng, không cho phép chọn ngày bắt đầu > ngày hiện tạ | G50: passed | H50: 46114
A51: TC_DB_24 | B51: Hiển thị lỗi khi ngày kết thúc > hiện tại | C51: 1. Chọn ngày kết thúc tương lai 2. Áp dụng | D51: N/A | E51: Hệ thống chặn không cho phép chọn | F51: Hệ thống chặn đúng, không cho phép chọn ngày kết thúc > ngày hiện tạ | G51: passed | H51: 46114
A52: TC_DB_25 | B52: Hiển thị lỗi khi ngày bắt đầu > ngày kết thúc | C52: 1. Chọn ngày bắt đầu sau ngày kết thúc 2. Áp dụng | D52: N/A | E52: Hệ thống chặn không cho phép chọn | F52: Hệ thống chặn đúng, không cho phép chọn ngày bắt đầu > ngày kết thúc | G52: passed | H52: 46114
A53: TC_DB_26 | B53: Hiển thị lỗi khi không chọn ngày | C53: 1. Không chọn ngày 2. Áp dụng | D53: N/A | E53: Hệ thống áp dụng lựa chọn | F53: Không chọn ngày nhưng vẫn áp dụng, hệ thống xử lý không lỗi code | G53: passed | H53: 46114
... A59: TC_DB_32 | B59: Xác nhận hiển thị đúng % tăng giảm của tổng đơn hàng | C59: 1. Vào dashboard 2, Kiểm tra % tăng giảm đơn hàng | D59: Có dữ liệu | E59: Hiển thị đúng dữ liệu thống kê | F59: % tăng/giảm đơn hàng hiển thị chính xác | G59: passed | H59: 46114
A60: TC_DB_33 | B60: Xác nhận hiển thị đúng biểu đồ tăng giảm số lượng đơn hàng theo ngày | C60: 1. Vào dashboard 2. Quan sát biểu đồ | D60: Có dữ liệu | E60: Hiển thị đúng số đơn từng ngày | F60: Biểu đồ số đơn hàng theo ngày hiển thị không đúng dữ liệu database | G60: failed | H60: 46114 | I60: passed | J60: 46118
A61: TC_DB_34 | B61: Xác nhận trục X hiển thị đúng số ngày | C61: 1. Vào dashboard 2. Quan sát trục ngang biểu đồ | D61: N/A | E61: Hiển thị đúng các ngày gàn nhất | F61: Trục X hiển thị đúng các ngày gần nhất | G61: passed | H61: 46114
A62: TC_DB_35 | B62: Xác nhận trục Y hiển thị đúng số đơn hàng | C62: 1. Vào dashboard 2. Quan sát trục dọc biểu đồ | D62: N/A | E62: Hiển thị đúng theo số đơn hàng | F62: Trục Y hiển thị đúng theo số đơn hàng | G62: passed | H62: 46114
...

Sheet Quản lý đơn hàng hệ thống
A1: Project Name | B1: XÂY DỰNG HỆ THỐNG DISHNET - NỀN TẢNG MẠNG XÃ HỘI KINH DOANH ẨM THỰC
A2: Module Code | B2: Xem đánh giá món ăn
A3: Người kiểm tra | B3: Lê Văn Cường
B4: Hoàn thành | C4: Lỗi | D4: Chưa kiểm tra | E4: Bị chăn | F4: Tổng số trường hợp thử nghiệm
A5: Round 1 | B5: =COUNTIF(G27:G1057,"passed") -> 62 | C5: =COUNTIF(G27:G1057,"failed") -> 5 | D5: =COUNTIF(H27:H1057,"untest") -> 0 | E5: =COUNTIF(G27:G1057,"blocked") -> 0 | F5: =COUNTIF(A23:A1053, "*ORD*") -> 67
A6: Round 2 | B6: =COUNTIF(I27:I1058,"passed") -> 5 | C6: =COUNTIF(I27:I1057,"failed") -> 0 | D6: =COUNTIF(G27:G1057,"untest") -> 0 | E6: =COUNTIF(G27:G1057,"blocked") -> 0 | F6: =COUNTIF(A24:A1054, "*ORD*") -> 67
A23: Test Case ID | B23: Mô tả | C23: Hành động | D23: Điều kiện tiên quyết | E23: Kết quả mong đợi | F23: Kết quả thực tế | G23: Kết quả | I23: Kết quả | K23: Chú thích
G24: Vòng 1 | I24: Vòng 2
G25: Trạng thái | H25: Ngày kiểm tra | I25: Trạng thái | J25: Ngày kiểm tra
A26: GUI_SHOW Trang quản lý đơn hàng hệ thống
A27: GUI_ORD_01 | B27: Kiểm tra hiển thị sidebar | C27: 1. Mở trang quản lý đơn hàng hệ thống | D27: Đã login | E27: Sidebar hiển thị | F27: Sidebar hiển thị đầy đủ sau khi đăng nhập | G27: passed | H27: 46114
A28: GUI_ORD_02 | B28: Kiểm tra highlight menu hiện tại | C28: 1. Mở trang quản lý đơn hàng hệ thống 2. Quan sát menu | D28: Trang thống kê | E28: Menu "Thống kê" đổi màu | F28: Menu “Thống kê” được highlight đúng khi đang ở trang tương ứng | G28: passed | H28: 46114
A29: GUI_ORD_03 | B29: Kiểm tra khi click menu khác | C29: 1. Mở trang quản lý đơn hàng hệ thống 2. Click item | D29: Trang load | E29: Điều hướng đúng | F29: Khi click menu khác, hệ thống điều hướng đúng trang | G29: passed | H29: 46114
A30: GUI_ORD_04 | B30: Kiểm tra bộ lọc thời gian | C30: 1. Mở trang quản lý đơn hàng hệ thống 2. Quan sát bộ lọc | D30: Trang load | E30: Có: Hôm nay, 7 ngày, 30 ngày, Tùy chọn | F30: Bộ lọc thời gian hiển thị đầy đủ các tùy chọn (Hôm nay, 7 ngày, 30 ngày, Tùy chọn) | G30: passed | H30: 46114
A31: GUI_ORD_05 | B31: Kiểm tra highlight tab | C31: 1. Mở trang quản lý đơn hàng hệ thống 2. Click tab | D31: Trang load | E31: Tab được chọn highlight | F31: Tab được chọn hiển thị highlight đúng | G31: passed | H31: 46114
A32: GUI_ORD_06 | B32: Kiểm tra dropdown tùy chọn | C32: 1. Mở trang quản lý đơn hàng hệ thống 2. Click "tùy chọn" | D32: Trang load | E32: Hiển thị date picker | F32: Khi chọn “Tùy chọn”, hệ thống hiển thị date picker | G32: passed | H32: 46114
A33: GUI_ORD_07 | B33: Kiểm tra input ngày | C33: 1. Click "Tùy chọn" 2. Chọn ngày | D33: Date picker mở | E33: Hiển thị ngày đúng format | F33: Date picker hiển thị ngày đúng định dạng | G33: passed | H33: 46114
A34: GUI_ORD_08 | B34: Kiểm tra button "Áp dụng" | C34: 1. Mở trang quản lý đơn hàng hệ thống 2. Quan sát button | D34: Date picker | E34: Có màu xanh, enable | F34: Button “Áp dụng” hiển thị màu xanh, trạng thái enable | G34: passed | H34: 46114
A35: GUI_ORD_09 | B35: Kiểm tra button "Hủy" | C35: 1. Mở trang quản lý đơn hàng hệ thống 2. Quan sát button | D35: Date picker | E35: Có màu trắng, enable | F35: Button “Hủy” hiển thị đúng giao diện, trạng thái enable | G35: passed | H35: 46114
A36: GUI_ORD_10 | B36: kiểm tra textbox search bar | C36: 1. Mở trang quản lý đơn hàng hệ thống 2. Quan sát textbox | D36: Trang load | E36: Hiển thị textbox, cho phép nhập | F36: Textbox search hiển thị đúng và cho phép nhập dữ liệu | G36: passed | H36: 46114
A37: GUI_ORD_11 | B37: Kiểm tra dropdown cửa hàng, trạng thái | C37: 1. Mở trang quản lý đơn hàng hệ thống 2. Click item | D37: Trang load | E37: Hiển thị danh sách | F37: Dropdown cửa hàng/trạng thái hiển thị danh sách đầy đủ | G37: passed | H37: 46114
A38: GUI_ORD_12 | B38: Kiểm tra khi click vào button xem | C38: 1. Mở trang quản lý đơn hàng hệ thống 2. Click "Xem" | D38: Trang load | E38: Điều hướng đúng | F38: Khi click “Xem”, hệ thống điều hướng đúng | G38: passed | H38: 46114
... A40: GUI_ORD_14 | B40: Kiểm tra responsive | C40: 1. Mở màn hình 2. Thay đổi kích thước màn hình | D40: Trang load | E40: Không vỡ layout | F40: Giao diện responsive tốt, không bị vỡ layout khi thay đổi kích thước màn hình | G40: passed | H40: 46114
A41: FUNCTION_SHOW Trang quản lý đơn hàng hệ thống
A42: TC_ORD_15 | B42: Xác nhận đăng nhập thành công khi truy cập bằng tài khoản admin | C42: 1. Đăng nhập tài khoản admin | D42: Admin đăng nhập hợp lệ | E42: Đăng nhập thành công vào hệ thống, chuyển màn hình đến trang thống kê | F42: Admin đăng nhập thành công và được chuyển đến màn hình thống kê | G42: passed | H42: 46114
A43: TC_ORD_16 | B43: Xác nhận thành công chặn các truy cập khi vào trực tiếp mà không đăng nhập | C43: 1. Truy cập URL quản lý đơn hàng 2. Không đăng nhập | D43: Chưa đăng nhập | E43: Hệ thống chuyển màn hình về trang đăng nhập | F43: Khi chưa đăng nhập truy cập URL, hệ thống chuyển về trang đăng nhập | G43: passed | H43: 46114
A44: TC_ORD_17 | B44: Hiển thị lỗi khi người dùng không phải admin truy cập | C44: 1. Đăng nhập user thường 2. Truy cập trang | D44: User thường | E44: Không cho phép truy cập | F44: User thường không thể truy cập trang admin (bị chặn đúng) | G44: passed | H44: 46114
A45: TC_ORD_18 | B45: Xác nhận hiển thị danh sách đơn hàng khi admin truy cập thành công vào trang quản lý đơn hàng hệ thống | C45: 1. Đăng nhập tài khoản admin 2. Truy cập trang quản lý đơn hàng | D45: Admin đã đăng nhập | E45: Hiển thị danh sách đơn hàng của người dùng | F45: Admin đăng nhập hợp lệ có thể truy cập và xem danh sách đơn hàng | G45: passed | H45: 46114
A46: TC_ORD_19 | B46: Xác nhận hiển thị đúng khi lọc hôm nay | C46: 1. Chọn "Hôm nay" 2. Kiểm tra dữ liệu | D46: Có dữ liệu | E46: Hiển thị dữ liệu ngày hiện tại | F46: Bộ lọc “Hôm nay” hiển thị đúng dữ liệu ngày hiện tại | G46: passed | H46: 46114
A47: TC_ORD_20 | B47: Xác nhận hiển thị đúng khi lọc 7 ngày | C47: 1. Chọn "7 ngày" 2. Kiểm tra dữ liệu | D47: Có dữ liệu | E47: Hiển thị dữ liệu 7 ngày gần nhất | F47: Bộ lọc “7 ngày” hiển thị đúng dữ liệu 7 ngày gần nhất | G47: passed | H47: 46114
A48: TC_ORD_21 | B48: Xác nhận hiển thị đúng khi lọc 30 ngày | C48: 1. Chọn "30 ngày" 2. Kiểm tra dữ liệu | D48: Có dữ liệu | E48: Hiển thị dữ liệu 30 ngày gần nhất | F48: Bộ lọc “30 ngày” hiển thị đúng dữ liệu 30 ngày gần nhất | G48: passed | H48: 46114
A49: TC_ORD_22 | B49: Xác nhận hiển thị đúng khi lọc tùy chọn | C49: 1. Chọn từ ngày 2. Chọn đến ngày 3. Áp dụng | D49: N/A | E49: Hiển thị đúng dữ liệu khoảng ngày đã chọn | F49: Bộ lọc tùy chọn hiển thị đúng dữ liệu theo khoảng ngày đã chọn | G49: passed | H49: 46114
A50: TC_ORD_23 | B50: Hiển thị lỗi khi chọn ngày bắt đầu > ngày hiện tại | C50: 1. Chọn ngày bắt đầu > hôm nay 2. Áp dụng | D50: N/A | E50: Hệ thống chặn không cho phép chọn | F50: Khi chọn ngày bắt đầu > hôm nay, hệ thống chặn và không cho áp dụng | G50: passed | H50: 46114
A51: TC_ORD_24 | B51: Hiển thị lỗi khi ngày kết thúc > hiện tại | C51: 1. Chọn ngày kết thúc tương lai 2. Áp dụng | D51: N/A | E51: Hệ thống chặn không cho phép chọn | F51: Khi chọn ngày kết thúc trong tương lai, hệ thống chặn không cho chọn | G51: passed | H51: 46114
A52: TC_ORD_25 | B52: Hiển thị lỗi khi ngày bắt đầu > ngày kết thúc | C52: 1. Chọn ngày bắt đầu sau ngày kết thúc 2. Áp dụng | D52: N/A | E52: Hệ thống chặn không cho phép chọn | F52: Khi ngày bắt đầu > ngày kết thúc, hệ thống hiển thị lỗi và không cho áp dụng | G52: passed | H52: 46114
A53: TC_ORD_26 | B53: Hiển thị lỗi khi không chọn ngày | C53: 1. Không chọn ngày 2. Áp dụng | D53: N/A | E53: Hệ thống áp dụng lựa chọn | F53: Khi không chọn ngày mà vẫn áp dụng, hệ thống hiển thị thông báo yêu cầu chọn ngày | G53: passed | H53: 46114
... A70: TC_ORD_43 | B70: Xác nhận hiển thị đúng trạng thái của đơn hàng | C70: 1. Quan sát trạng thái | D70: N/A | E70: Hiển thị đúng trạng thái đang thực hiện | F70: Trạng thái đơn hàng hiển thị đúng với trạng thái thực tế | G70: passed | H70: 46114
A71: TC_ORD_44 | B71: Xác nhận hiển thị đúng thời gian | C71: 1. Quan sát timestamp | D71: N/A | E71: Format dd/mm/yyyy hh:mm | F71: Thời gian chỉ hiển thị dd/mm/yy, không đúng định dạng dd/mm/yyyy hh:mm | G71: failed | H71: 46114 | I71: passed | J71: 46118
A72: TC_ORD_45 | B72: Xác nhận hiển thị đúng nhấn phân trang | C72: 1. Click trang tiếp theo | D72: Có nhiều dữ liệu | E72: Hiển thị dữ liệu trang tiếp theo | F72: Click trang tiếp theo, dữ liệu được hiển thị đúng | G72: passed | H72: 46114
A73: TC_ORD_46 | B73: Xác nhận hệ thống hiển thị đúng chi tiết đơn hàng khi nhấn vào nút "Xem" | C73: 1. Click "Xem" | D73: Có dữ liệu | E73: Hiển thị chi tiết đơn hàng | F73: Click “Xem”, hệ thống hiển thị đầy đủ chi tiết đơn hàng | G73: passed | H73: 46114
...

Sheet Kiểm duyệt yêu cầu hệ thống
A1: Project Name | B1: XÂY DỰNG HỆ THỐNG DISHNET - NỀN TẢNG MẠNG XÃ HỘI KINH DOANH ẨM THỰC
A2: Module Code | B2: Kiểm duyệt yêu cầu hệ thống
A3: Người kiểm tra | B3: Trần Thị Mai Yên
B4: Hoàn thành | C4: Lỗi | D4: Chưa kiểm tra | E4: Bị chăn | F4: Tổng số trường hợp thử nghiệm
A5: Round 1 | B5: =COUNTIF(G25:G972,"passed") -> 23 | C5: =COUNTIF(G25:G972,"failed") -> 19 | D5: =COUNTIF(H25:I972,"untest") -> 0 | E5: =COUNTIF(G25:G972,"blocked") -> 0 | F5: =COUNTIF(A22:A968, "*REQ*") -> 42
A6: Round 2 | B6: =COUNTIF(I25:I973,"passed") -> 19 | C6: =COUNTIF(I25:I972,"failed") -> 0 | D6: =COUNTIF(G25:G972,"untest") -> 0 | E6: =COUNTIF(G25:G972,"blocked") -> 0 | F6: =COUNTIF(A23:A969, "*REQ*") -> 42
A21: Test Case ID | B21: Mô tả | C21: Hành động | D21: Điều kiện tiên quyết | E21: Kết quả mong đợi | F21: Kết quả thực tế | G21: Kết quả | I21: Kết quả | K21: Chú thích
G22: Vòng 1 | I22: Vòng 2
G23: Trạng thái | H23: Ngày kiểm tra | I23: Trạng thái | J23: Ngày kiểm tra
A24: GUI
A25: GUI_REQ_01 | B25: Xác minh hệ thống hiển thị danh sách yêu cầu khi Admin truy cập trang. | C25: 1. Đăng nhập tài khoản Admin. 2. Truy cập menu "Kiểm duyệt". | D25: Tài khoản Admin hợp lệ. | E25: Chuyển đến trang Kiểm duyệt và hiển thị danh sách. | F25: Trang tải danh sách yêu cầu nhanh chóng trên nền trắng bo góc. | G25: passed | H25: 46114
A26: GUI_REQ_02 | B26: Xác minh bảng hiển thị đúng các cột: STT, Tên người dùng, Email, Loại yêu cầu, Trạng thái, Thời gian gửi. | C26: 1. Quan sát hàng tiêu đề của bảng dữ liệu. | D26: Đã truy cập vào menu "Kiểm duyệt". | E26: Hiển thị đủ 6 cột thông tin như thiết kế. | F26: Bảng hiển thị chính xác 6 cột thông tin với tiêu đề in đậm. | G26: passed | H26: 46114
A27: GUI_REQ_03 | B27: Xác minh nút "Xem" hiển thị tương ứng tại mỗi dòng yêu cầu. | C27: 1. Quan sát cột cuối cùng của bảng. | D27: Bảng có ít nhất 1 bản ghi dữ liệu yêu cầu. | E27: Mỗi dòng đều có nút "Xem" màu xanh. | F27: Nút "Xem" nền xanh dương hiển thị đồng nhất ở cuối mỗi hàng. | G27: passed | H27: 46114
A28: GUI_REQ_04 | B28: Xác minh màu sắc trạng thái hiển thị đúng quy định (Xanh/Cam/Đỏ). | C28: 1. Quan sát cột "Trạng thái". | D28: Danh sách có các yêu cầu ở các trạng thái khác nhau. | E28: Màu sắc các nhãn trạng thái hiển thị đúng quy định. | F28: Các nhãn Đã duyệt (Xanh), Chờ duyệt (Cam), Từ chối (Đỏ) hiển thị đúng màu. | G28: passed | H28: 46114
A29: GUI_REQ_05 | B29: Xác minh hiển thị bộ lọc thời gian và thanh tìm kiếm phía trên bảng. | C29: 1. Quan sát khu vực phía trên bảng danh sách. | D29: Trang đã tải xong hoàn toàn các thành phần. | E29: Các bộ lọc và thanh tìm kiếm hiển thị đầy đủ. | F29: Hiển thị đủ 4 nút lọc nhanh, ô tìm kiếm và 2 dropdown lọc Loại/Trạng thái. | G29: passed | H29: 46114
A30: GUI_REQ_06 | B30: Xác minh định dạng và màu sắc thời gian gửi yêu cầu. | C30: 1. Quan sát cột "Thời gian gửi yêu cầu". | D30: Dữ liệu yêu cầu có thông tin thời gian. | E30: Hiển thị đúng định dạng Ngày/Tháng/Năm, Giờ:Phút. | F30: Thời gian hiển thị rõ ràng (màu xanh dương), có kèm định dạng SA/CH (AM/PM). | G30: passed | H30: 46114
A31: GUI_REQ_07 | B31: Xác minh hiển thị thanh điều hướng phân trang ở cuối bảng. | C31: 1. Cuộn xuống phía dưới cùng của bảng dữ liệu. | D31: Tổng số bản ghi lớn hơn số lượng hiển thị trên 1 trang. | E31: Hiển thị các nút chuyển trang và số trang hiện tại. | F31: Nút số "1" hiển thị nổi bật với nền xanh lá cây và bo tròn. | G31: passed | H31: 46114
A32: GUI_REQ_08 | B32: Xác minh làm nổi bật menu "Kiểm duyệt" ở thanh sidebar. | C32: 1. Quan sát thanh menu bên trái màn hình. | D32: Đang ở trang Kiểm duyệt yêu cầu. | E32: Mục "Kiểm duyệt" được highlight để nhận diện. | F32: Menu "Kiểm duyệt" có nền xanh lá, giúp nhận diện vị trí trang hiện tại. | G32: passed | H32: 46114
A33: FUNCTION
A34: TC_REQ_09 | B34: Xác minh rằng chỉ hiển thị các yêu cầu gửi trong ngày hiện tại khi click vào button "Hôm nay" đối với điều kiện có yêu cầu trong ngày. | C34: 1. Click vào button "Hôm nay". | D34: Có yêu cầu trong ngày | E34: Chỉ hiển thị các yêu cầu gửi trong ngày hiện tại. | F34: Hiển thị đúng dữ liệu trong ngày. | G34: passed | H34: 46114
A35: TC_REQ_10 | B35: Xác minh rằng hiển thị danh sách yêu cầu trong vòng 7 ngày qua khi click vào button "7 ngày" đối với điều kiện có yêu cầu trong 7 ngày. | C35: 1. Click vào button "7 ngày". | D35: Có yêu cầu trong 7 ngày | E35: Hiển thị danh sách yêu cầu trong vòng 7 ngày qua. | F35: Hiển thị đúng dữ liệu 7 ngày qua. | G35: passed | H35: 46114
A36: TC_REQ_11 | B36: Xác minh rằng hiển thị danh sách yêu cầu trong vòng 30 ngày qua khi click vào button "30 ngày" đối với điều kiện có yêu cầu trong 30 ngày. | C36: 1. Click vào button "30 ngày". | D36: Có yêu cầu trong 30 ngày | E36: Hiển thị danh sách yêu cầu trong vòng 30 ngày qua. | F36: Hiển thị đúng dữ liệu 30 ngày qua. | G36: passed | H36: 46114
A37: TC_REQ_12 | B37: Xác minh rằng hiển thị đúng các yêu cầu thuộc khoảng thời gian đó khi chọn ngày bắt đầu và ngày kết thúc đối với điều kiện có dữ liệu trong khoảng chọn. | C37: 1. Chọn "Tùy chọn". 2. Chọn ngày bắt đầu và ngày kết thúc. | D37: Có dữ liệu trong khoảng chọn | E37: Hiển thị đúng các yêu cầu thuộc khoảng thời gian đó. | F37: Dữ liệu hiển thị bị lệch 1 ngày so với lựa chọn (lỗi múi giờ/timezone). | G37: passed | H37: 46114
A38: TC_REQ_13 | B38: Xác minh rằng hệ thống hiển thị thông báo lỗi ngày không hợp lệ khi nhấn Apply đối với điều kiện chọn ngày bắt đầu > ngày kết thúc. | C38: 1. Chọn ngày bắt đầu > ngày kết thúc. 2. Nhấn Apply. | D38: N/A | E38: Hệ thống hiển thị thông báo lỗi ngày không hợp lệ. | F38: Hệ thống không báo lỗi, vẫn thực hiện query và trả về danh sách rỗng. | G38: failed | H38: 46114 | I38: passed | J38: 46118
A39: TC_REQ_14 | B39: Xác minh rằng các ngày trong tương lai bị disabled (ẩn/không cho chọn) khi click vào các ngày sau ngày hiện tại | C39: 1. Mở lịch chọn ngày. 2. Click vào các ngày sau ngày hiện tại. | D39: N/A | E39: Các ngày trong tương lai bị disabled (ẩn/không cho chọn). | F39: Người dùng vẫn chọn được ngày trong tương lai. | G39: failed | H39: 46114 | I39: passed | J39: 46118
A40: TC_REQ_15 | B40: Xác minh rằng hiển thị dữ liệu của đúng ngày đã chọn khi chọn ngày bắt đầu và kết thúc trùng nhau đối với điều kiện có yêu cầu trong ngày đó. | C40: 1. Chọn ngày bắt đầu và kết thúc trùng nhau. | D40: Có yêu cầu trong ngày đó | E40: Hiển thị dữ liệu của đúng ngày đã chọn. | F40: Hiển thị đúng dữ liệu của ngày đó. | G40: passed | H40: 46114
A41: TC_REQ_16 | B41: Xác minh rằng hiển thị các yêu cầu của người dùng đó khi nhập tên vào ô tìm kiếm và nhấn Enter đối với điều kiện tên tồn tại trong danh sách. | C41: 1. Nhập tên vào ô tìm kiếm. 2. Nhấn Enter. | D41: Tên tồn tại trong danh sách | E41: Hiển thị các yêu cầu của người dùng đó. | F41: Không tìm thấy kết quả nếu nhập tên có dấu (lỗi Unicodde). | G41: failed | H41: 46114 | I41: passed | J41: 46118
A42: TC_REQ_17 | B42: Xác minh rằng hệ thống hiển thị tổng doanh thu khớp với danh sách khi Admin lọc theo thời gian đối với điều kiện có dữ liệu doanh thu. | C42: 1. Thực hiện lọc dữ liệu theo thời gian. 2. Quan sát dòng tổng cộng. | D42: Có dữ liệu doanh thu | E42: Hệ thống hiển thị tổng doanh thu khớp với danh sách. | F42: Tổng doanh thu bị sai lệch 1đ do lỗi làm tròn số thập phân. | G42: failed | H42: 46114 | I42: passed | J42: 46118
A43: TC_REQ_18 | B43: Xác minh rằng danh sách ở trang mới vẫn giữ nguyên bộ lọc ban đầu khi nhấn chuyển trang đối với điều kiện danh sách có nhiều trang. | C43: 1. Thực hiện bộ lọc bất kỳ. 2. Nhấn chuyển sang trang 2. | D43: Danh sách có nhiều trang | E43: Danh sách ở trang mới vẫn giữ nguyên bộ lọc ban đầu. | F43: Hệ thống tự động reset bộ lọc về mặc định khi chuyển trang. | G43: failed | H43: 46114 | I43: passed | J43: 46118
A44: TC_REQ_19 | B44: Xác minh rằng hệ thống hiển thị thông báo lỗi "Số dư không đủ" khi Admin nhấn phê duyệt đối với điều kiện tài khoản Merchant không đủ tiền. | C44: 1. Nhấn nút "Phê duyệt". | D44: Tài khoản Merchant không đủ tiền | E44: Hệ thống hiển thị thông báo lỗi "Số dư không đủ". | F44: Hệ thống vẫn cho phê duyệt dẫn đến số dư bị âm. | G44: failed | H44: 46114 | I44: passed | J44: 46118
A45: TC_REQ_20 | B45: Xác minh rằng hệ thống mở modal hiển thị đầy đủ thông tin chi tiết khi nhấn nút "Xem" | C45: 1. Nhấn nút "Xem". | D45: N/A | E45: Hệ thống mở modal hiển thị đầy đủ thông tin chi tiết. | F45: Hiển thị đầy đủ thông tin chi tiết. | G45: passed | H45: 46114 | J45: 46118
A46: TC_REQ_21 | B46: Xác minh rằng hệ thống ghi nhận đúng lịch sử người duyệt và thời gian thực hiện khi nhấn Phê duyệt. | C46: 1. Nhấn Phê duyệt. 2. Kiểm tra log hệ thống. | D46: N/A | E46: Ghi nhận đúng lịch sử người duyệt và thời gian thực hiện. | F46: Ghi nhận đúng thông tin. | G46: passed | H46: 46114
A47: TC_REQ_22 | B47: Xác minh rằng hệ thống hiển thị thông báo "Yêu cầu đã được xử lý bởi người khác" khi hai Admin cùng duyệt một yêu cầu đối với điều kiện yêu cầu đang mở bởi 2 người. | C47: 1. Hai Admin cùng mở 1 yêu cầu. 2. Admin 1 duyệt trước. 3. Admin 2 nhấn duyệt sau. | D47: Yêu cầu đang mở bởi 2 người | E47: Hệ thống hiển thị thông báo "Yêu cầu đã được xử lý bởi người khác". | F47: Admin 2 vẫn nhấn duyệt được và hệ thống báo thành công (Race condition). | G47: failed | H47: 46114 | I47: passed | J47: 46118
A48: TC_REQ_23 | B48: Xác minh rằng danh sách được sắp xếp theo thời gian mới nhất lên đầu khi load lại trang . | C48: 1. Nhấn F5 làm mới trang. | D48: N/A | E48: Danh sách được sắp xếp theo thời gian mới nhất lên đầu. | F48: Dữ liệu sắp xếp đúng thứ tự. | G48: passed | H48: 46114
A49: TC_REQ_24 | B49: Xác minh rằng hệ thống gửi email thông báo kết quả cho người dùng khi Admin hoàn tất xử lý . | C49: 1. Nhấn Phê duyệt hoặc Từ chối. | D49: N/A | E49: Hệ thống gửi email thông báo kết quả cho người dùng. | F49: Người dùng không nhận được email thông báo. | G49: failed | H49: 46114 | I49: passed | J49: 46118
A50: TC_REQ_25 | B50: Xác minh rằng hệ thống giải phóng bộ nhớ và đóng modal khi nhấn nút "Đóng" hoặc nhấn ra ngoài modal đối với điều kiện modal đang mở. | C50: 1. Nhấn nút "Đóng" trên modal. | D50: Modal đang mở | E50: Hệ thống giải phóng bộ nhớ và đóng modal. | F50: Modal đóng đúng quy định. | G50: passed | H50: 46114
A51: TC_REQ_26 | B51: Xác minh rằng hệ thống không cho phép để trống trường "Lý do" khi nhấn nút "Từ chối" đối với điều kiện N/A. | C51: 1. Nhấn "Từ chối". 2. Để trống ô lý do. 3. Nhấn Xác nhận. | D51: N/A | E51: Hệ thống yêu cầu nhập lý do từ chối. | F51: Hệ thống vẫn cho phép từ chối mà không cần nhập lý do. | G51: failed | H51: 46114 | I51: passed | J51: 46118
A52: TC_REQ_27 | B52: Xác minh rằng trạng thái mặc định là "Chờ duyệt" khi người dùng gửi yêu cầu đối với điều kiện N/A. | C52: 1. Thực hiện gửi một yêu cầu. | D52: N/A | E52: Trạng thái mặc định của yêu cầu là "Chờ duyệt". | F52: Hiển thị đúng trạng thái. | G52: passed | H52: 46114
A53: TC_REQ_28 | B53: Xác minh rằng không cho gửi thêm yêu cầu cùng loại khi người dùng đã có yêu cầu cùng loại đang "Chờ duyệt" đối với điều kiện có yêu cầu đang chờ duyệt. | C53: 1. Gửi thêm yêu cầu cùng loại. | D53: Có yêu cầu cùng loại đang "Chờ duyệt" | E53: Hệ thống không cho gửi thêm yêu cầu. | F53: Vẫn cho gửi trùng lặp yêu cầu. | G53: failed | H53: 46114 | I53: passed | J53: 46118
A54: TC_REQ_29 | B54: Xác minh rằng không cho gửi lại yêu cầu cùng loại khi người dùng đã có yêu cầu "Đã duyệt" đối với điều kiện có yêu cầu đã được duyệt. | C54: 1. Thao tác gửi lại yêu cầu cùng loại. | D54: Có yêu cầu "Đã duyệt" | E54: Hệ thống không cho phép gửi lại. | F54: Chặn gửi lại chính xác. | G54: passed | H54: 46114
...

Sheet Quản lý tài khoản
A1: Project Name | B1: XÂY DỰNG HỆ THỐNG DISHNET - NỀN TẢNG MẠNG XÃ HỘI KINH DOANH ẨM THỰC
A2: Module Code | B2: Quản lý tài khoản
A3: Người kiểm tra | B3: Trần Thị Mai Yên
B4: Hoàn thành | C4: Lỗi | D4: Chưa kiểm tra | E4: Bị chăn | F4: Tổng số trường hợp thử nghiệm
A5: Round 1 | B5: =COUNTIF(G27:G929,"passed") -> 54 | C5: =COUNTIF(G27:G929,"failed") -> 1 | D5: =COUNTIF(G27:G929,"untest") -> 0 | E5: =COUNTIF(G27:G929,"blocked") -> 0 | F5: =COUNTIF(A23:A925, "*ACC*") -> 55
A6: Round 2 | B6: =COUNTIF(I27:I930,"passed") -> 1 | C6: =COUNTIF(G27:G929,"failed") -> 1 | D6: =COUNTIF(G27:G929,"untest") -> 0 | E6: =COUNTIF(G27:G929,"blocked") -> 0 | F6: =COUNTIF(A24:A926, "*ACC*") -> 55
A23: Test Case ID | B23: Mô tả | C23: Hành động | D23: Điều kiện tiên quyết | E23: Kết quả mong đợi | F23: Kết quả thực tế | G23: Kết quả | I23: Kết quả | K23: Chú thích
G24: Vòng 1 | I24: Vòng 2
G25: Trạng thái | H25: Ngày kiểm tra | I25: Trạng thái | J25: Ngày kiểm tra
A26: GUI
A27: GUI_ACC_01 | B27: Xác minh hiển thị danh sách các thẻ (card) khuyến mãi. | C27: 1. Truy cập menu "Quản lý khuyến mãi". | D27: Admin đã đăng nhập hệ thống. | E27: Các mã khuyến mãi hiển thị dưới dạng thẻ lưới (grid). | F27: Danh sách khuyến mãi hiển thị trực quan theo từng ô hình chữ nhật bo góc. | G27: passed | H27: 46114
A28: GUI_ACC_02 | B28: Xác minh hiển thị nút "Thêm khuyến mãi". | C28: 1. Quan sát góc trên bên phải màn hình. | D28: Đang ở trang Quản lý khuyến mãi. | E28: Hiển thị nút "Thêm khuyến mãi" màu xanh lá. | F28: Nút "Thêm khuyến mãi" kèm icon dấu cộng hiển thị rõ ràng tại vị trí góc phải. | G28: passed | H28: 46114
A29: GUI_ACC_03 | B29: Xác minh hiển thị bộ lọc và thanh tìm kiếm. | C29: 1. Quan sát khu vực điều hướng phía trên danh sách. | D29: Trang đã tải xong giao diện. | E29: Hiển thị ô tìm kiếm, dropdown trạng thái, loại và sắp xếp. | F29: Có đầy đủ 4 công cụ lọc: Tìm kiếm, Trạng thái mã, Loại khuyến mãi và Sắp xếp. | G29: passed | H29: 46114
